Workbook
Name Fronteras: 'Rangos'!$H$5:$H$11
Name Productores: 'Rangos'!$J$5:$J$39
Name Status: 'Rangos'!$B$5:$B$14
Name Transporte: 'Rangos'!$D$5:$D$44

Sheet Cargas
B2: PROGRAMA DE CARGAS EN BRASIL
A4: Carga Sem.# | B4: Status | C4: Factura Export. | D4: Productor | E4: Fecha de Carga | F4: Carpeta Import. | G4: AFIDI | H4: Transportista | I4: Fecha Frontera | J4: Frontera | K4: Insp. MGAP | L4: Fecha Descarga | M4: TT | N4: Cajas MIC | O4: Código de viaje | P4: Cajas Desc | Q4: MIC | R4: PLACAS T | S4: PLACAS R | T4: Observaciones
A5: 14 | B5: Cancelado | C5: xx | D5: Papa | F5: =VLOOKUP($C5,CARPETAS!$C$5:$L$2388,2,FALSE) -> BRB | G5: =VLOOKUP($C5,CARPETAS!$C$5:$L$2388,9,FALSE) -> xx | H5: =VLOOKUP($C5,CARPETAS!$C$5:$L$2388,5,FALSE) -> xx | I5: =E5+2 -> 2 | J5: =VLOOKUP($C5,CARPETAS!$C$5:$L$2388,4,FALSE) -> xx | L5: =I5+1 -> 3 | M5: =IF(E5<>"",L5-E5,"-") -> - | N5: 1000
A6: 2 | B6: Cancelado | C6: XX | D6: Claudia | E6: 43112 | F6: =VLOOKUP($C6,CARPETAS!$C$5:$L$2388,2,FALSE) -> BRB | G6: =VLOOKUP($C6,CARPETAS!$C$5:$L$2388,9,FALSE) -> xx | H6: =VLOOKUP($C6,CARPETAS!$C$5:$L$2388,5,FALSE) -> xx | I6: =E6+2 -> 43114 | J6: =VLOOKUP($C6,CARPETAS!$C$5:$L$2388,4,FALSE) -> xx | L6: =I6+1 -> 43115 | M6: =IF(E6<>"",L6-E6,"-") -> 3 | N6: 936
A7: 7 | B7: Cancelado | C7: xx | D7: Claudia | E7: 43143 | F7: =VLOOKUP($C7,CARPETAS!$C$5:$L$2388,2,FALSE) -> BRB | G7: =VLOOKUP($C7,CARPETAS!$C$5:$L$2388,9,FALSE) -> xx | H7: =VLOOKUP($C7,CARPETAS!$C$5:$L$2388,5,FALSE) -> xx | I7: =E7+2 -> 43145 | J7: =VLOOKUP($C7,CARPETAS!$C$5:$L$2388,4,FALSE) -> xx | L7: =I7+1 -> 43146 | M7: =IF(E7<>"",L7-E7,"-") -> 3 | N7: 936
A8: 7 | B8: Cancelado | C8: xx | D8: Jaime | E8: 43147 | F8: =VLOOKUP($C8,CARPETAS!$C$5:$L$2388,2,FALSE) -> BRB | G8: =VLOOKUP($C8,CARPETAS!$C$5:$L$2388,9,FALSE) -> xx | H8: =VLOOKUP($C8,CARPETAS!$C$5:$L$2388,5,FALSE) -> xx | I8: =E8+2 -> 43149 | J8: =VLOOKUP($C8,CARPETAS!$C$5:$L$2388,4,FALSE) -> xx | L8: =I8+1 -> 43150 | M8: =IF(E8<>"",L8-E8,"-") -> 3 | N8: 936
A9: 7 | B9: Cancelado | C9: xx | D9: Sidnei | E9: 43147 | F9: =VLOOKUP($C9,CARPETAS!$C$5:$L$2388,2,FALSE) -> BRB | G9: =VLOOKUP($C9,CARPETAS!$C$5:$L$2388,9,FALSE) -> xx | H9: =VLOOKUP($C9,CARPETAS!$C$5:$L$2388,5,FALSE) -> xx | I9: =E9+2 -> 43149 | J9: =VLOOKUP($C9,CARPETAS!$C$5:$L$2388,4,FALSE) -> xx | L9: =I9+1 -> 43150 | M9: =IF(E9<>"",L9-E9,"-") -> 3 | N9: 936
A10: 7 | B10: Cancelado | C10: xx | D10: Sidnei | E10: 43147 | F10: =VLOOKUP($C10,CARPETAS!$C$5:$L$2388,2,FALSE) -> BRB | G10: =VLOOKUP($C10,CARPETAS!$C$5:$L$2388,9,FALSE) -> xx | H10: =VLOOKUP($C10,CARPETAS!$C$5:$L$2388,5,FALSE) -> xx | I10: =E10+2 -> 43149 | J10: =VLOOKUP($C10,CARPETAS!$C$5:$L$2388,4,FALSE) -> xx | L10: =I10+1 -> 43150 | M10: =IF(E10<>"",L10-E10,"-") -> 3 | N10: 936
A11: 7 | B11: Cancelado | C11: xx | D11: Ulgo | E11: 43147 | F11: =VLOOKUP($C11,CARPETAS!$C$5:$L$2388,2,FALSE) -> BRB | G11: =VLOOKUP($C11,CARPETAS!$C$5:$L$2388,9,FALSE) -> xx | H11: =VLOOKUP($C11,CARPETAS!$C$5:$L$2388,5,FALSE) -> xx | I11: =E11+2 -> 43149 | J11: =VLOOKUP($C11,CARPETAS!$C$5:$L$2388,4,FALSE) -> xx | L11: =I11+1 -> 43150 | M11: =IF(E11<>"",L11-E11,"-") -> 3 | N11: 936
A12: 7 | B12: Cancelado | C12: xx | D12: Claudia | E12: 43147 | F12: =VLOOKUP($C12,CARPETAS!$C$5:$L$2388,2,FALSE) -> BRB | G12: =VLOOKUP($C12,CARPETAS!$C$5:$L$2388,9,FALSE) -> xx | H12: =VLOOKUP($C12,CARPETAS!$C$5:$L$2388,5,FALSE) -> xx | I12: =E12+2 -> 43149 | J12: =VLOOKUP($C12,CARPETAS!$C$5:$L$2388,4,FALSE) -> xx | L12: =I12+1 -> 43150 | M12: =IF(E12<>"",L12-E12,"-") -> 3 | N12: 936
A13: 9 | B13: Cancelado | C13: xx | D13: Sidnei | E13: 43161 | F13: =VLOOKUP($C13,CARPETAS!$C$5:$L$2388,2,FALSE) -> BRB | G13: =VLOOKUP($C13,CARPETAS!$C$5:$L$2388,9,FALSE) -> xx | H13: =VLOOKUP($C13,CARPETAS!$C$5:$L$2388,5,FALSE) -> xx | I13: =E13+2 -> 43163 | J13: =VLOOKUP($C13,CARPETAS!$C$5:$L$2388,4,FALSE) -> xx | L13: =I13+1 -> 43164 | M13: =IF(E13<>"",L13-E13,"-") -> 3 | N13: 936
A14: 11 | B14: Cancelado | C14: XX | D14: Jaime | E14: 43175 | F14: =VLOOKUP($C14,CARPETAS!$C$5:$L$2388,2,FALSE) -> BRB | G14: =VLOOKUP($C14,CARPETAS!$C$5:$L$2388,9,FALSE) -> xx | H14: =VLOOKUP($C14,CARPETAS!$C$5:$L$2388,5,FALSE) -> xx | I14: 43174 | J14: =VLOOKUP($C14,CARPETAS!$C$5:$L$2388,4,FALSE) -> xx | L14: =I14+1 -> 43175 | M14: =IF(E14<>"",L14-E14,"-") -> 0 | N14: 936
A15: 11 | B15: Cancelado | C15: xx | D15: Ulgo | E15: 43175 | F15: =VLOOKUP($C15,CARPETAS!$C$5:$L$2388,2,FALSE) -> BRB | G15: =VLOOKUP($C15,CARPETAS!$C$5:$L$2388,9,FALSE) -> xx | H15: =VLOOKUP($C15,CARPETAS!$C$5:$L$2388,5,FALSE) -> xx | I15: 43174 | J15: =VLOOKUP($C15,CARPETAS!$C$5:$L$2388,4,FALSE) -> xx | L15: =I15+1 -> 43175 | M15: =IF(E15<>"",L15-E15,"-") -> 0 | N15: 936
A16: 13 | B16: Destruida | C16: 308/2018 | D16: Corupá | E16: 43185 | F16: =VLOOKUP($C16,CARPETAS!$C$5:$L$2388,2,FALSE) -> #N/A | G16: =VLOOKUP($C16,CARPETAS!$C$5:$L$2388,9,FALSE) -> #N/A | H16: =VLOOKUP($C16,CARPETAS!$C$5:$L$2388,5,FALSE) -> #N/A | I16: =E16+2 -> 43187 | J16: =VLOOKUP($C16,CARPETAS!$C$5:$L$2388,4,FALSE) -> #N/A | L16: =I16+1+4 -> 43192 | M16: =IF(E16<>"",L16-E16,"-") -> 7 | N16: 936 | Q16: 2935 | R16: MKB 0869 | S16: MGK 7801 | T16: P.C.DESCARGA MIERCOLES EN R. DE COREA 02/04/18 /*//TZ: caminhão se encontrava com temperatura de -6º NEGATIVOS, mirar a fruta,
A17: 13 | B17: Cancelado | C17: xx | D17: Claudia | E17: 43186 | F17: =VLOOKUP($C17,CARPETAS!$C$5:$L$2388,2,FALSE) -> BRB | G17: =VLOOKUP($C17,CARPETAS!$C$5:$L$2388,9,FALSE) -> xx | H17: =VLOOKUP($C17,CARPETAS!$C$5:$L$2388,5,FALSE) -> xx | I17: =E17+2 -> 43188 | J17: =VLOOKUP($C17,CARPETAS!$C$5:$L$2388,4,FALSE) -> xx | L17: =I17+1 -> 43189 | M17: =IF(E17<>"",L17-E17,"-") -> 3 | N17: 936
A18: 21 | B18: Cancelado | C18: xx | D18: Claudia | E18: 43245 | F18: =VLOOKUP($C18,CARPETAS!$C$5:$L$2388,2,FALSE) -> BRB | G18: =VLOOKUP($C18,CARPETAS!$C$5:$L$2388,9,FALSE) -> xx | H18: =VLOOKUP($C18,CARPETAS!$C$5:$L$2388,5,FALSE) -> xx | I18: =E18+2 -> 43247 | J18: =VLOOKUP($C18,CARPETAS!$C$5:$L$2388,4,FALSE) -> xx | L18: =I18+1 -> 43248 | M18: =IF(E18<>"",L18-E18,"-") -> 3 | N18: 936
A19: 21 | B19: Cancelado | C19: xx | D19: Jaime | E19: 43245 | F19: =VLOOKUP($C19,CARPETAS!$C$5:$L$2388,2,FALSE) -> BRB | G19: =VLOOKUP($C19,CARPETAS!$C$5:$L$2388,9,FALSE) -> xx | H19: =VLOOKUP($C19,CARPETAS!$C$5:$L$2388,5,FALSE) -> xx | I19: =E19+2 -> 43247 | J19: =VLOOKUP($C19,CARPETAS!$C$5:$L$2388,4,FALSE) -> xx | L19: =I19+1 -> 43248 | M19: =IF(E19<>"",L19-E19,"-") -> 3 | N19: 936
A20: 22 | B20: Cancelado | C20: xx | D20: Claudia | E20: 43248 | F20: =VLOOKUP($C20,CARPETAS!$C$5:$L$2388,2,FALSE) -> BRB | G20: =VLOOKUP($C20,CARPETAS!$C$5:$L$2388,9,FALSE) -> xx | H20: =VLOOKUP($C20,CARPETAS!$C$5:$L$2388,5,FALSE) -> xx | I20: =E20+2 -> 43250 | J20: =VLOOKUP($C20,CARPETAS!$C$5:$L$2388,4,FALSE) -> xx | L20: =I20+1 -> 43251 | M20: =IF(E20<>"",L20-E20,"-") -> 3 | N20: 936
A21: 22 | B21: Cancelado | C21: xx | D21: Claudia | E21: 43248 | F21: =VLOOKUP($C21,CARPETAS!$C$5:$L$2388,2,FALSE) -> BRB | G21: =VLOOKUP($C21,CARPETAS!$C$5:$L$2388,9,FALSE) -> xx | H21: =VLOOKUP($C21,CARPETAS!$C$5:$L$2388,5,FALSE) -> xx | I21: =E21+2 -> 43250 | J21: =VLOOKUP($C21,CARPETAS!$C$5:$L$2388,4,FALSE) -> xx | L21: =I21+1 -> 43251 | M21: =IF(E21<>"",L21-E21,"-") -> 3 | N21: 936
A22: 22 | B22: Cancelado | C22: xx | D22: Jaime | E22: 43248 | F22: =VLOOKUP($C22,CARPETAS!$C$5:$L$2388,2,FALSE) -> BRB | G22: =VLOOKUP($C22,CARPETAS!$C$5:$L$2388,9,FALSE) -> xx | H22: =VLOOKUP($C22,CARPETAS!$C$5:$L$2388,5,FALSE) -> xx | I22: =E22+2 -> 43250 | J22: =VLOOKUP($C22,CARPETAS!$C$5:$L$2388,4,FALSE) -> xx | L22: =I22+1 -> 43251 | M22: =IF(E22<>"",L22-E22,"-") -> 3 | N22: 936
A23: 22 | B23: Cancelado | C23: xx | D23: Gilson | E23: 43248 | F23: =VLOOKUP($C23,CARPETAS!$C$5:$L$2388,2,FALSE) -> BRB | G23: =VLOOKUP($C23,CARPETAS!$C$5:$L$2388,9,FALSE) -> xx | H23: =VLOOKUP($C23,CARPETAS!$C$5:$L$2388,5,FALSE) -> xx | I23: =E23+2 -> 43250 | J23: =VLOOKUP($C23,CARPETAS!$C$5:$L$2388,4,FALSE) -> xx | L23: =I23+1 -> 43251 | M23: =IF(E23<>"",L23-E23,"-") -> 3 | N23: 936
A24: 22 | B24: Cancelado | C24: xx | D24: Corupá | E24: 43248 | F24: =VLOOKUP($C24,CARPETAS!$C$5:$L$2388,2,FALSE) -> BRB | G24: =VLOOKUP($C24,CARPETAS!$C$5:$L$2388,9,FALSE) -> xx | H24: =VLOOKUP($C24,CARPETAS!$C$5:$L$2388,5,FALSE) -> xx | I24: =E24+2 -> 43250 | J24: =VLOOKUP($C24,CARPETAS!$C$5:$L$2388,4,FALSE) -> xx | L24: =I24+1 -> 43251 | M24: =IF(E24<>"",L24-E24,"-") -> 3 | N24: 936
A25: 22 | B25: Cancelado | C25: xx | D25: Sidnei | E25: 43248 | F25: =VLOOKUP($C25,CARPETAS!$C$5:$L$2388,2,FALSE) -> BRB | G25: =VLOOKUP($C25,CARPETAS!$C$5:$L$2388,9,FALSE) -> xx | H25: =VLOOKUP($C25,CARPETAS!$C$5:$L$2388,5,FALSE) -> xx | I25: =E25+2 -> 43250 | J25: =VLOOKUP($C25,CARPETAS!$C$5:$L$2388,4,FALSE) -> xx | L25: =I25+1 -> 43251 | M25: =IF(E25<>"",L25-E25,"-") -> 3 | N25: 936
A26: 22 | B26: Cancelado | C26: xx | D26: Claudia | E26: 43252 | F26: =VLOOKUP($C26,CARPETAS!$C$5:$L$2388,2,FALSE) -> BRB | G26: =VLOOKUP($C26,CARPETAS!$C$5:$L$2388,9,FALSE) -> xx | H26: =VLOOKUP($C26,CARPETAS!$C$5:$L$2388,5,FALSE) -> xx | I26: =E26+2 -> 43254 | J26: =VLOOKUP($C26,CARPETAS!$C$5:$L$2388,4,FALSE) -> xx | L26: =I26+1 -> 43255 | M26: =IF(E26<>"",L26-E26,"-") -> 3 | N26: 936
A27: 22 | B27: Cancelado | C27: xx | D27: Claudia | E27: 43252 | F27: =VLOOKUP($C27,CARPETAS!$C$5:$L$2388,2,FALSE) -> BRB | G27: =VLOOKUP($C27,CARPETAS!$C$5:$L$2388,9,FALSE) -> xx | H27: =VLOOKUP($C27,CARPETAS!$C$5:$L$2388,5,FALSE) -> xx | I27: =E27+2 -> 43254 | J27: =VLOOKUP($C27,CARPETAS!$C$5:$L$2388,4,FALSE) -> xx | L27: =I27+1 -> 43255 | M27: =IF(E27<>"",L27-E27,"-") -> 3 | N27: 936
A28: 22 | B28: Cancelado | C28: xx | D28: Jaime | E28: 43252 | F28: =VLOOKUP($C28,CARPETAS!$C$5:$L$2388,2,FALSE) -> BRB | G28: =VLOOKUP($C28,CARPETAS!$C$5:$L$2388,9,FALSE) -> xx | H28: =VLOOKUP($C28,CARPETAS!$C$5:$L$2388,5,FALSE) -> xx | I28: =E28+2 -> 43254 | J28: =VLOOKUP($C28,CARPETAS!$C$5:$L$2388,4,FALSE) -> xx | L28: =I28+1 -> 43255 | M28: =IF(E28<>"",L28-E28,"-") -> 3 | N28: 936
... A34: 26 | B34: Cancelado | C34: xx | D34: Corupá | E34: 43278 | F34: =VLOOKUP($C34,CARPETAS!$C$5:$L$2388,2,FALSE) -> BRB | G34: =VLOOKUP($C34,CARPETAS!$C$5:$L$2388,9,FALSE) -> xx | H34: =VLOOKUP($C34,CARPETAS!$C$5:$L$2388,5,FALSE) -> xx | I34: =E34+2 -> 43280 | J34: =VLOOKUP($C34,CARPETAS!$C$5:$L$2388,4,FALSE) -> xx | L34: =I34+1 -> 43281 | M34: =IF(E34<>"",L34-E34,"-") -> 3 | N34: 936
A35: 36 | B35: Cancelado | C35: xx | D35: Sidnei | E35: 43349 | F35: =VLOOKUP($C35,CARPETAS!$C$5:$L$2388,2,FALSE) -> BRB | G35: =VLOOKUP($C35,CARPETAS!$C$5:$L$2388,9,FALSE) -> xx | H35: =VLOOKUP($C35,CARPETAS!$C$5:$L$2388,5,FALSE) -> xx | I35: 43322 | J35: =VLOOKUP($C35,CARPETAS!$C$5:$L$2388,4,FALSE) -> xx | L35: =I35+1 -> 43323 | M35: =IF(E35<>"",L35-E35,"-") -> -26 | N35: 936
A36: 42 | B36: Cancelado | C36: xx | D36: Nordeste | E36: 43391 | F36: =VLOOKUP($C36,CARPETAS!$C$5:$L$2388,2,FALSE) -> BRB | G36: =VLOOKUP($C36,CARPETAS!$C$5:$L$2388,9,FALSE) -> xx | H36: =VLOOKUP($C36,CARPETAS!$C$5:$L$2388,5,FALSE) -> xx | I36: =E36+3 -> 43394 | J36: =VLOOKUP($C36,CARPETAS!$C$5:$L$2388,4,FALSE) -> xx | L36: =I36+1 -> 43395 | M36: =IF(E36<>"",L36-E36,"-") -> 4 | N36: 936 | O36: N/A
A37: 43 | B37: Cancelado | C37: xx | D37: Nordeste | E37: 43395 | F37: =VLOOKUP($C37,CARPETAS!$C$5:$L$2388,2,FALSE) -> BRB | G37: =VLOOKUP($C37,CARPETAS!$C$5:$L$2388,9,FALSE) -> xx | H37: =VLOOKUP($C37,CARPETAS!$C$5:$L$2388,5,FALSE) -> xx | I37: =E37+3 -> 43398 | J37: =VLOOKUP($C37,CARPETAS!$C$5:$L$2388,4,FALSE) -> xx | L37: =I37+1 -> 43399 | M37: =IF(E37<>"",L37-E37,"-") -> 4 | N37: 936
A38: 43 | B38: Cancelado | C38: xx | D38: Nordeste | E38: 43395 | F38: =VLOOKUP($C38,CARPETAS!$C$5:$L$2388,2,FALSE) -> BRB | G38: =VLOOKUP($C38,CARPETAS!$C$5:$L$2388,9,FALSE) -> xx | H38: =VLOOKUP($C38,CARPETAS!$C$5:$L$2388,5,FALSE) -> xx | I38: =E38+3 -> 43398 | J38: =VLOOKUP($C38,CARPETAS!$C$5:$L$2388,4,FALSE) -> xx | L38: =I38+1 -> 43399 | M38: =IF(E38<>"",L38-E38,"-") -> 4 | N38: 936
A39: 47 | B39: Cancelado | C39: xx | D39: Valdemar | E39: 43425 | F39: =VLOOKUP($C39,CARPETAS!$C$5:$L$2388,2,FALSE) -> BRB | G39: =VLOOKUP($C39,CARPETAS!$C$5:$L$2388,9,FALSE) -> xx | H39: =VLOOKUP($C39,CARPETAS!$C$5:$L$2388,5,FALSE) -> xx | I39: =E39+2 -> 43427 | J39: =VLOOKUP($C39,CARPETAS!$C$5:$L$2388,4,FALSE) -> xx | L39: =I39+1 -> 43428 | M39: =IF(E39<>"",L39-E39,"-") -> 3 | N39: 936
A40: 47 | B40: Cancelado | C40: xx | D40: Valdemar | E40: 43426 | F40: =VLOOKUP($C40,CARPETAS!$C$5:$L$2388,2,FALSE) -> BRB | G40: =VLOOKUP($C40,CARPETAS!$C$5:$L$2388,9,FALSE) -> xx | H40: =VLOOKUP($C40,CARPETAS!$C$5:$L$2388,5,FALSE) -> xx | I40: =E40+2 -> 43428 | J40: =VLOOKUP($C40,CARPETAS!$C$5:$L$2388,4,FALSE) -> xx | L40: =I40+1 -> 43429 | M40: =IF(E40<>"",L40-E40,"-") -> 3 | N40: 936
A41: 48 | B41: Cancelado | C41: xx | D41: Nordeste | E41: 43430 | F41: =VLOOKUP($C41,CARPETAS!$C$5:$L$2388,2,FALSE) -> BRB | G41: =VLOOKUP($C41,CARPETAS!$C$5:$L$2388,9,FALSE) -> xx | H41: =VLOOKUP($C41,CARPETAS!$C$5:$L$2388,5,FALSE) -> xx | I41: =E41+2 -> 43432 | J41: =VLOOKUP($C41,CARPETAS!$C$5:$L$2388,4,FALSE) -> xx | L41: =I41+1 -> 43433 | M41: =IF(E41<>"",L41-E41,"-") -> 3 | N41: 936
A42: 1 | B42: Descargado | C42: 403/2018 | D42: Gilson | E42: 43468 | F42: =VLOOKUP($C42,CARPETAS!$C$5:$L$2388,2,FALSE) -> #N/A | G42: =VLOOKUP($C42,CARPETAS!$C$5:$L$2388,9,FALSE) -> #N/A | H42: =VLOOKUP($C42,CARPETAS!$C$5:$L$2388,5,FALSE) -> #N/A | I42: 43469 | J42: =VLOOKUP($C42,CARPETAS!$C$5:$L$2388,4,FALSE) -> #N/A | L42: =I42+1 -> 43470 | M42: =IF(E42<>"",L42-E42,"-") -> 2 | N42: 900 | O42: GT 001 | P42: 902 | Q42: 536 | R42: QIW 6450 | S42: QHT8275 | T42: P.C. DESCARGO EN R. NATURAL 05/01/19 ///R.D 05/01 - DESCARGA EN REP DE COREA.
A43: 1 | B43: Descargado | C43: 405/2019 | D43: Valdemar | E43: 43468 | F43: =VLOOKUP($C43,CARPETAS!$C$5:$L$2388,2,FALSE) -> BRB001 | G43: =VLOOKUP($C43,CARPETAS!$C$5:$L$2388,9,FALSE) -> 134.03.89 | H43: =VLOOKUP($C43,CARPETAS!$C$5:$L$2388,5,FALSE) -> Transzanini | I43: 43469 | J43: =VLOOKUP($C43,CARPETAS!$C$5:$L$2388,4,FALSE) -> Rivera | L43: =I43+4 -> 43473 | M43: =IF(E43<>"",L43-E43,"-") -> 5 | N43: 900 | O43: VH 004 | P43: 900 | Q43: 537 | R43: FJX 1877 | S43: EOE 2359 | T43: R.D 09/01 - DESCARGO EN MERCADO MODELO. /// R.D 08/01 - QUEDA PARA DESCARAR EL DIA 09/01
A44: 1 | B44: Descargado | C44: 404/2018 | D44: Corupá | E44: 43468 | F44: =VLOOKUP($C44,CARPETAS!$C$5:$L$2388,2,FALSE) -> #N/A | G44: =VLOOKUP($C44,CARPETAS!$C$5:$L$2388,9,FALSE) -> #N/A | H44: =VLOOKUP($C44,CARPETAS!$C$5:$L$2388,5,FALSE) -> #N/A | I44: 43472 | J44: =VLOOKUP($C44,CARPETAS!$C$5:$L$2388,4,FALSE) -> #N/A | L44: =I44+1 -> 43473 | M44: =IF(E44<>"",L44-E44,"-") -> 5 | N44: 900 | O44: CP 002 | P44: 901 | Q44: 3371 | R44: MLP 4888 | S44: MKT 2555 | T44: P.C. DESCARGO EN LARRAVIDE 08/01/19 ///R.D 08/01 - DESCARGA EN LARRAVIDE /// TZ 07/01 - DESCARGA 08/1
A45: 1 | B45: Descargado | C45: 404/2018 | D45: Claudia | E45: 43468 | F45: =VLOOKUP($C45,CARPETAS!$C$5:$L$2388,2,FALSE) -> #N/A | G45: =VLOOKUP($C45,CARPETAS!$C$5:$L$2388,9,FALSE) -> #N/A | H45: =VLOOKUP($C45,CARPETAS!$C$5:$L$2388,5,FALSE) -> #N/A | I45: 43472 | J45: =VLOOKUP($C45,CARPETAS!$C$5:$L$2388,4,FALSE) -> #N/A | L45: =I45+1 -> 43473 | M45: =IF(E45<>"",L45-E45,"-") -> 5 | N45: 900 | O45: CH 003 | P45: 901 | Q45: 3374 | R45: MGK 2404 | S45: MIB 3710 | T45: R.D 08/01 - DESCARGA EN MERCADO MODELO /// TZ 07/01 - DESCARGA 08/1
A46: 1 | B46: Descargado | C46: 405/2019 | D46: Claudia | E46: 43469 | F46: =VLOOKUP($C46,CARPETAS!$C$5:$L$2388,2,FALSE) -> BRB001 | G46: =VLOOKUP($C46,CARPETAS!$C$5:$L$2388,9,FALSE) -> 134.03.89 | H46: =VLOOKUP($C46,CARPETAS!$C$5:$L$2388,5,FALSE) -> Transzanini | I46: 43472 | J46: =VLOOKUP($C46,CARPETAS!$C$5:$L$2388,4,FALSE) -> Rivera | L46: =I46+1 -> 43473 | M46: =IF(E46<>"",L46-E46,"-") -> 4 | N46: 900 | O46: CH 004 | P46: 901 | Q46: 539 | R46: EOE 2475 | S46: MJY 7644 | T46: R.D 08/01 - DESCARGA EN MERCADO MODELO /// TZ 07/01 - DESCARGA 08/1
A47: 2 | B47: Descargado | C47: 405/2019 | D47: Valdemar | E47: 43471 | F47: =VLOOKUP($C47,CARPETAS!$C$5:$L$2388,2,FALSE) -> BRB001 | G47: =VLOOKUP($C47,CARPETAS!$C$5:$L$2388,9,FALSE) -> 134.03.89 | H47: =VLOOKUP($C47,CARPETAS!$C$5:$L$2388,5,FALSE) -> Transzanini | I47: 43472 | J47: =VLOOKUP($C47,CARPETAS!$C$5:$L$2388,4,FALSE) -> Rivera | L47: =I47+1 -> 43473 | M47: =IF(E47<>"",L47-E47,"-") -> 2 | N47: 900 | O47: VH 005 | P47: 900 | Q47: 538 | R47: QJQ 3510 | S47: MLX 3048 | T47: P.C. DESCARGO EN LARRAVIDE 08/01/19 ////R.D 08/01 - DESCARGA EN LARRAVIDE /// TZ 07/01 - DESCARGA 08/1
...

Sheet Carpetas
B2: CARPETAS DE IMPORTACIÓN - CONTROL DE CARGAS y SALDOS
B4: Fecha | C4: Fatura | D4: Carpeta | E4: Export | F4: Frontera | G4: Transp. | H4: Qtde | I4: Cargado | J4: Saldo | K4: Afidi | L4: DUA
B5: 43838 | C5: 006/2020 | D5: BRB004 | E5: Etimex | F5: Rio Branco | G5: Silvio | H5: 4680 | I5: =SUMIF(Cargas!$C$5:$C$1652,C5,Cargas!$N$5:$N$1652) -> 4680 | J5: =IF(ABS(H5-I5)<20,0,H5-I5) -> 0 | K5: 136.37.80 | L5: 6527
B6: 43845 | C6: 008/2020 | D6: BRB007 | E6: Etimex | F6: Rio Branco | G6: Silvio | H6: 4680 | I6: =SUMIF(Cargas!$C$5:$C$1652,C6,Cargas!$N$5:$N$1652) -> 4680 | J6: =IF(ABS(H6-I6)<20,0,H6-I6) -> 0 | K6: 136.42.77 | L6: 11510
B7: 43859 | C7: 013/2020 | D7: BRB011 | E7: Etimex | F7: Rio Branco | G7: Silvio | H7: 5616 | I7: =SUMIF(Cargas!$C$5:$C$1652,C7,Cargas!$N$5:$N$1652) -> 5616 | J7: =IF(ABS(H7-I7)<20,0,H7-I7) -> 0 | K7: 136.51.05 | L7: 22600
B8: 43467 | C8: 405/2019 | D8: BRB001 | E8: Joana | F8: Rivera | G8: Transzanini | H8: 6300 | I8: =SUMIF(Cargas!$C$5:$C$1652,C8,Cargas!$N$5:$N$1652) -> 6300 | J8: =IF(ABS(H8-I8)<20,0,H8-I8) -> 0 | K8: 134.03.89 | L8: 1843
B9: 43497 | C9: 406/2019 | D9: BRB002 | E9: Joana | F9: Rivera | G9: Silvio | H9: 7200 | I9: =SUMIF(Cargas!$C$5:$C$1652,C9,Cargas!$N$5:$N$1652) -> 7200 | J9: =IF(ABS(H9-I9)<20,0,H9-I9) -> 0 | K9: 134.03.90 | L9: 3609
B10: 43472 | C10: 407/2019 | D10: BRB003 | E10: Joana | F10: Rivera | G10: Cmcn | H10: 1800 | I10: =SUMIF(Cargas!$C$5:$C$1652,C10,Cargas!$N$5:$N$1652) -> 1800 | J10: =IF(ABS(H10-I10)<20,0,H10-I10) -> 0 | K10: 134.06.39 | L10: 6078
B11: 43475 | C11: 408/2019 | D11: BRB004 | E11: Joana | F11: Rivera | G11: Silvio | H11: 5400 | I11: =SUMIF(Cargas!$C$5:$C$1652,C11,Cargas!$N$5:$N$1652) -> 5400 | J11: =IF(ABS(H11-I11)<20,0,H11-I11) -> 0 | K11: 134.08.44 | L11: 7741
B12: 43475 | C12: 409/2019 | D12: BRB005 | E12: Joana | F12: Rivera | G12: Transzanini | H12: 5400 | I12: =SUMIF(Cargas!$C$5:$C$1652,C12,Cargas!$N$5:$N$1652) -> 5400 | J12: =IF(ABS(H12-I12)<20,0,H12-I12) -> 0 | K12: 134.08.43 | L12: 110005
B13: 43480 | C13: 410/2019 | D13: BRB006 | E13: Joana | F13: Rivera | G13: Silvio | H13: 7200 | I13: =SUMIF(Cargas!$C$5:$C$1652,C13,Cargas!$N$5:$N$1652) -> 7200 | J13: =IF(ABS(H13-I13)<20,0,H13-I13) -> 0 | K13: 134.10.38 | L13: 10395
B14: 43488 | C14: 411/2019 | D14: BRB007 | E14: Joana | F14: Rivera | G14: Zanini | H14: 3744 | I14: =SUMIF(Cargas!$C$5:$C$1652,C14,Cargas!$N$5:$N$1652) -> 3744 | J14: =IF(ABS(H14-I14)<20,0,H14-I14) -> 0 | K14: 134.16.99 | L14: 15329
B15: 43493 | C15: 412/2019 | D15: BRB008 | E15: Joana | F15: Rivera | G15: Silvio | H15: 3744 | I15: =SUMIF(Cargas!$C$5:$C$1652,C15,Cargas!$N$5:$N$1652) -> 3744 | J15: =IF(ABS(H15-I15)<20,0,H15-I15) -> 0 | K15: 134.18.85 | L15: 18261
B16: 43493 | C16: 413/2019 | D16: BRB009 | E16: Joana | F16: Rivera | G16: CMCN | H16: 1872 | I16: =SUMIF(Cargas!$C$5:$C$1652,C16,Cargas!$N$5:$N$1652) -> 1872 | J16: =IF(ABS(H16-I16)<20,0,H16-I16) -> 0 | K16: 134.18.86 | L16: 18226
... B104: 43781 | C104: 490/2019 | D104: BRE002 | E104: Joana | F104: Rivera | G104: Silvio | H104: 1250 | I104: =SUMIF(Cargas!$C$5:$C$1652,C104,Cargas!$N$5:$N$1652) -> 1250 | J104: =IF(ABS(H104-I104)<20,0,H104-I104) -> 0 | K104: 135.92.62 | L104: 202355
B105: 43904 | C105: 049/20 | D105: BRP007 | E105: Etimex | F105: Rio Branco | G105: Silvio | H105: 1000 | I105: =SUMIF(Cargas!$C$5:$C$1652,C105,Cargas!$N$5:$N$1652) -> 1000 | J105: =IF(ABS(H105-I105)<20,0,H105-I105) -> 0 | K105: 136.62.83 | L105: xx
B106: 43903 | C106: 050/20 | D106: BRB021 | E106: Etimex | F106: Rio Branco | G106: Silvio | H106: 7488 | I106: =SUMIF(Cargas!$C$5:$C$1652,C106,Cargas!$N$5:$N$1652) -> 7488 | J106: =IF(ABS(H106-I106)<20,0,H106-I106) -> 0 | K106: 1367846 | L106: 42973
B107: 43907 | C107: 055/20 | D107: BRB022 | E107: Etimex | F107: Rio Branco | G107: Silvio | H107: 7488 | I107: =SUMIF(Cargas!$C$5:$C$1652,C107,Cargas!$N$5:$N$1652) -> 7488 | J107: =IF(ABS(H107-I107)<20,0,H107-I107) -> 0 | K107: 136.80.95 | L107: 46164
B108: 43907 | C108: 056/20 | D108: BRB023 | E108: Etimex | F108: Rio Branco | G108: Zanini | H108: 3744 | I108: =SUMIF(Cargas!$C$5:$C$1652,C108,Cargas!$N$5:$N$1652) -> 3744 | J108: =IF(ABS(H108-I108)<20,0,H108-I108) -> 0 | K108: 136.80.96 | L108: 45581
B109: 43914 | C109: 060/20 | D109: BRP008 | E109: Etimex | F109: Rio Branco | G109: Silvio | H109: 1000 | I109: =SUMIF(Cargas!$C$5:$C$1652,C109,Cargas!$N$5:$N$1652) -> 1000 | J109: =IF(ABS(H109-I109)<20,0,H109-I109) -> 0 | K109: 136.62.83 | L109: xx
B110: 43915 | C110: 063/20 | D110: BRP009 | E110: Etimex | F110: Rio Branco | G110: Silvio | H110: 1000 | I110: =SUMIF(Cargas!$C$5:$C$1652,C110,Cargas!$N$5:$N$1652) -> 1000 | J110: =IF(ABS(H110-I110)<20,0,H110-I110) -> 0 | K110: 136.54.60 | L110: xx
B111: 43915 | C111: 064/20 | D111: BRB024 | E111: Etimex | F111: Rio Branco | G111: Silvio | H111: 7488 | I111: =SUMIF(Cargas!$C$5:$C$1652,C111,Cargas!$N$5:$N$1652) -> 7488 | J111: =IF(ABS(H111-I111)<20,0,H111-I111) -> 0 | K111: 136.85.90 | L111: 48621
B112: 43917 | C112: 065/20 | D112: BRB025 | E112: Etimex | F112: Rio Branco | G112: Zanini | H112: 5616 | I112: =SUMIF(Cargas!$C$5:$C$1652,C112,Cargas!$N$5:$N$1652) -> 5616 | J112: =IF(ABS(H112-I112)<20,0,H112-I112) -> 0 | K112: 136.85.91 | L112: 49751
B113: 43918 | C113: 069/20 | D113: BRP010 | E113: Etimex | F113: Rio Branco | G113: Silvio | H113: 1000 | I113: =SUMIF(Cargas!$C$5:$C$1652,C113,Cargas!$N$5:$N$1652) -> 1000 | J113: =IF(ABS(H113-I113)<20,0,H113-I113) -> 0 | K113: 136.78.87 | L113: 49710
B114: 43920 | C114: 071/20 | D114: BRB027 | E114: Etimex | F114: Rio Branco | G114: Silvio | H114: 7488 | I114: =SUMIF(Cargas!$C$5:$C$1652,C114,Cargas!$N$5:$N$1652) -> 7488 | J114: =IF(ABS(H114-I114)<20,0,H114-I114) -> 0 | K114: 136.87.60 | L114: 50964
B115: 43921 | C115: 072/20 | D115: BRP011 | E115: Etimex | F115: Rio Branco | G115: Silvio | H115: 1000 | I115: =SUMIF(Cargas!$C$5:$C$1652,C115,Cargas!$N$5:$N$1652) -> 1000 | J115: =IF(ABS(H115-I115)<20,0,H115-I115) -> 0 | K115: 136.75.81 | L115: xx
B116: 43922 | C116: 074/20 | D116: BRP012 | E116: Etimex | F116: Rio Branco | G116: Silvio | H116: 1000 | I116: =SUMIF(Cargas!$C$5:$C$1652,C116,Cargas!$N$5:$N$1652) -> 1000 | J116: =IF(ABS(H116-I116)<20,0,H116-I116) -> 0 | K116: 136.78.88 | L116: xx
B117: 43920 | C117: 075/20 | D117: BRB028 | E117: Etimex | F117: Rio Branco | G117: Zanini | H117: 5616 | I117: =SUMIF(Cargas!$C$5:$C$1652,C117,Cargas!$N$5:$N$1652) -> 5616 | J117: =IF(ABS(H117-I117)<20,0,H117-I117) -> 0 | K117: 136.89.74 | L117: 52547
B118: 44048 | C118: 083/ | D118: BRB057 | E118: Agricola Famosa | F118: Rio Branco | G118: Silvio | H118: 1152 | I118: =SUMIF(Cargas!$C$5:$C$1652,C118,Cargas!$N$5:$N$1652) -> 1152 | J118: =IF(ABS(H118-I118)<20,0,H118-I118) -> 0 | K118: 137.80.10 | L118: 121946
B119: 43928 | C119: 086/20 | D119: BRP014 | E119: Etimex | F119: Rio Branco | G119: Silvio | H119: 1000 | I119: =SUMIF(Cargas!$C$5:$C$1652,C119,Cargas!$N$5:$N$1652) -> 1000 | J119: =IF(ABS(H119-I119)<20,0,H119-I119) -> 0 | K119: 136.86.99 | L119: 53668
B120: 43929 | C120: 087/20 | D120: BRB030 | E120: Etimex | F120: Rio Branco | G120: Silvio | H120: 9360 | I120: =SUMIF(Cargas!$C$5:$C$1652,C120,Cargas!$N$5:$N$1652) -> 9360 | J120: =IF(ABS(H120-I120)<20,0,H120-I120) -> 0 | K120: 136.95.65 | L120: 54013
B121: 44048 | C121: 088/ | D121: BRB057 | E121: Agricola Famosa | F121: Rio Branco | G121: Silvio | H121: 1152 | I121: =SUMIF(Cargas!$C$5:$C$1652,C121,Cargas!$N$5:$N$1652) -> 1152 | J121: =IF(ABS(H121-I121)<20,0,H121-I121) -> 0 | K121: 137.80.10 | L121: 121946
B122: 43929 | C122: 088/20 | D122: BRB031 | E122: Etimex | F122: Rio Branco | G122: Zanini | H122: 5616 | I122: =SUMIF(Cargas!$C$5:$C$1652,C122,Cargas!$N$5:$N$1652) -> 5616 | J122: =IF(ABS(H122-I122)<20,0,H122-I122) -> 0 | K122: 136.95.66 | L122: 54930
B123: 43930 | C123: 089/20 | D123: BRP015 | E123: Etimex | F123: Rio Branco | G123: Silvio | H123: 2000 | I123: =SUMIF(Cargas!$C$5:$C$1652,C123,Cargas!$N$5:$N$1652) -> 2000 | J123: =IF(ABS(H123-I123)<20,0,H123-I123) -> 0 | K123: 139.96.27 | L123: 53933
B124: 43937 | C124: 095/20 | D124: BRB029 | E124: Etimex | F124: Rio Branco | G124: ATX | H124: 1872 | I124: =SUMIF(Cargas!$C$5:$C$1652,C124,Cargas!$N$5:$N$1652) -> 1872 | J124: =IF(ABS(H124-I124)<20,0,H124-I124) -> 0 | K124: 136.95.67 | L124: 56917
B125: 43939 | C125: 096/20 | D125: BRP016 | E125: Etimex | F125: Rio Branco | G125: Silvio | H125: 1000 | I125: =SUMIF(Cargas!$C$5:$C$1652,C125,Cargas!$N$5:$N$1652) -> 1000 | J125: =IF(ABS(H125-I125)<20,0,H125-I125) -> 0 | K125: 137.01.81 | L125: 57401
B126: 43941 | C126: 100/20 | D126: BRB032 | E126: Etimex | F126: Rio Branco | G126: Silvio | H126: 5616 | I126: =SUMIF(Cargas!$C$5:$C$1652,C126,Cargas!$N$5:$N$1652) -> 5616 | J126: =IF(ABS(H126-I126)<20,0,H126-I126) -> 0 | K126: 137.02.11 | L126: 59793
B127: 43941 | C127: 101/20 | D127: BRB033 | E127: Etimex | F127: Rio Branco | G127: Zanini | H127: 5616 | I127: =SUMIF(Cargas!$C$5:$C$1652,C127,Cargas!$N$5:$N$1652) -> 5616 | J127: =IF(ABS(H127-I127)<20,0,H127-I127) -> 0 | K127: 137.02.12 | L127: 60087
B128: 44055 | C128: 102 | D128: BRB060 | E128: Agricola Famosa | F128: Rio Branco | G128: Silvio | H128: 1152 | I128: =SUMIF(Cargas!$C$5:$C$1652,C128,Cargas!$N$5:$N$1652) -> 1152 | J128: =IF(ABS(H128-I128)<20,0,H128-I128) -> 0 | K128: 137.86.68 | L128: 127453
... B150: 44041 | C150: 1435/ | D150: PYB004 | E150: Misionero | F150: Salto | G150: Transur | H150: 990 | I150: =SUMIF(Cargas!$C$5:$C$1652,C150,Cargas!$N$5:$N$1652) -> 990 | J150: =IF(ABS(H150-I150)<20,0,H150-I150) -> 0 | K150: 137.80.74 | L150: 119445
...

Sheet Rangos
B2: Listas para validación de datos
B4: Status List | D4: Transporte | E4: Cajas x Viaje | F4: INCOTERMS | H4: Fronteras | J4: Productores | K4: Iniciales
B5: Solicitado | J5: Ulgo | K5: HG
B6: Destruida | D6: CMCN | E6: 936 | F6: DAP | H6: Montevideo | J6: Sergio | K6: SR
B7: Confirmado | D7: Amaro | E7: 1008 | F7: DAP | H7: Salto | J7: Claudia | K7: CH
B8: Cancelado | D8: Balbiani | E8: 1040 | F8: FCA | H8: Chuy | J8: Gilson | K8: GT
B9: Cargado | D9: Cigliuti | E9: 936 | F9: FCA | H9: Río Branco | J9: Jaime | K9: JM
B10: Frontera | D10: Cordenonsi | E10: 936 | F10: DAP | H10: Rivera | J10: Papa | K10: PA
B11: Liberado | D11: El Palomar | E11: 1000 | F11: DAP | H11: xx | J11: Boniato | K11: BO
B12: Arribado | D12: Pradera | E12: 918 | F12: FCA | J12: Sidnei | K12: SR
B13: Puerto | D13: Transzanini | E13: 918 | J13: Benini | K13: BN
B14: Descargado | D14: Gral | E14: 918 | F14: DAP | J14: Valdemar | K14: VH
D15: Aotrans | J15: Valdemar Ita
D16: Sergio Nava | E16: 918 | J16: Varios | K16: VA
D17: Marvel | J17: Nordeste | K17: ND
D18: K2 | E18: 918 | F18: DAP | J18: Corupá | K18: CP
D19: Costa Rica | E19: 918 | F19: DAP | J19: Jhony Viera | K19: JV
D20: Schwanck | E20: 918 | F20: DAP | J20: Muller | K20: MU
J21: Sergio | K21: SG
J22: Vitor | K22: VM
J23: Paraguay | K23: PY
J24: Paraguay EC | K24: PYE
J25: Paraguay OP | K25: PYO
J26: Paraguay MS | K26: PYM
J27: Paraguay GM | K27: GM
D28: Silvio | E28: 918 | F28: DAP | J28: Paraguay DF | K28: DF
D29: Tottal Brasil | E29: 918 | F29: DAP | J29: Paraguay HF | K29: HF
J30: Paraguay SF | K30: SF
D31: Trans America | E31: 918 | F31: DAP | J31: Bolivia Tuli | K31: BT
J32: Cebolla | K32: CE
J33: Abacaxi | K33: AB
J34: AgroBianvirc | K34: BRSP
D35: Transitex | E35: 1008 | F35: DAP | J35: Varios | K35: VA
D36: Ruiz | E36: 1008 | F36: FCA | J36: Cobalchini | K36: CB
D37: Viana | E37: 1008 | F37: FCA | J37: Junkes | K37: JS
D38: Realeza | E38: 918 | F38: FCA | J38: BAHIA | K38: BA
D39: Azzolini | E39: 918 | F39: DAP | J39: xx | K39: xx
D40: VI-MA | E40: 918 | F40: DAP
D41: Coopecarga | E41: 918 | F41: DAP
D42: Chabat | E42: 918
...
