Workbook
Name AtrasoDias: Parametros!$B$10
Name CajasBO: Parametros!$D$15
Name CajasBR: Parametros!$B$15
Name CajasOrigen: Parametros!$B$15:$D$15
Name CajasProm: Parametros!$B$11
Name CajasPY: Parametros!$C$15
Name CapFisica: Parametros!$B$59
Name CapMadurar: Parametros!$B$58
Name CepeaKg: Parametros!$B$21
Name CgCajas: Cargas!$H$5:$H$300
Name CgCarga: Cargas!$B$5:$B$300
Name CgCosto: Cargas!$P$5:$P$300
Name CgCuenta: Cargas!$N$5:$N$300
Name CgEstado: Cargas!$I$5:$I$300
Name CgOrigen: Cargas!$D$5:$D$300
Name CgOTIF: Cargas!$U$5:$U$300
Name CgPipeline: Cargas!$T$5:$T$300
Name CgProductor: Cargas!$E$5:$E$300
Name CgSemana: Cargas!$M$5:$M$300
Name CgSemanaP90: Cargas!$S$5:$S$300
Name CoberturaObjetivo: Parametros!$B$6
Name ConteoBO: Parametros!$D$16
Name ConteoBR: Parametros!$B$16
Name ConteoPY: Parametros!$C$16
Name ConteoTotal: Parametros!$E$16
Name CostoBO: Parametros!$D$33
Name CostoBR: Parametros!$B$33
Name CostoOrigen: Parametros!$B$33:$D$33
Name CostoPY: Parametros!$C$33
Name DemSemana: Demanda!$A$6:$A$18
Name DemVenta: Demanda!$H$6:$H$18
Name DiasMadurar: Parametros!$B$46
Name DiasVenta: Parametros!$B$7
Name EstacTabla: Parametros!$A$36:$B$40
Name FactorEscenario: Parametros!$B$9
Name FechaConteo: Parametros!$B$3
Name FechaHoy: Parametros!$B$4
Name HistSemana: Demanda!$A$22:$A$33
Name HistTotal: Demanda!$G$22:$G$33
Name KgCaja: Parametros!$B$22
Name LagBO: Parametros!$D$14
Name LagBR: Parametros!$B$14
Name LagPY: Parametros!$C$14
Name Lags: Parametros!$B$14:$D$14
Name LagsP90: Parametros!$B$45:$D$45
Name MinimoSabado: Parametros!$B$5
Name MinSugerido: Parametros!$B$52
Name Origenes: Parametros!$B$13:$D$13
Name PrACargar: Proyeccion!$K$6:$K$18
Name PrBO: Proyeccion!$S$6:$S$18
Name PrBOd: Proyeccion!$T$6:$T$18
Name PrBR: Proyeccion!$O$6:$O$18
Name PrBRd: Proyeccion!$P$6:$P$18
Name PrCamiones: Proyeccion!$D$6:$D$18
Name PrCobertura: Proyeccion!$M$6:$M$18
Name PrecioBR_BRL: Parametros!$B$25
Name PrEstado: Proyeccion!$N$6:$N$18
Name PrLimite: Proyeccion!$J$6:$J$18
Name PrProy: Proyeccion!$I$6:$I$18
Name PrPY: Proyeccion!$Q$6:$Q$18

Sheet Inicio
A1: PLAN DE COMPRAS SIMULADO - Almar S.R.L. (banana Brasil + Paraguay + Bolivia)
A2: Generado el 29/09/2026 11:36 a partir de plan_compras.json (conteo del 26/09/2026). Planilla de trabajo: se edita a mano, no la pisa el script.
A4: PARA QUE SIRVE
B5: Proyectar el stock de banana al cierre de cada sabado, saber cuantos camiones cargar y hasta que dia, y probar escenarios (venta distinta a comienzo/fin de mes, atraso en frontera, camiones de mas o de menos).
B6: Sigue las reglas de Almar: el sabado cierra la semana; lo que descarga el lunes suma a la semana siguiente; Paraguay carga domingo-lunes-martes y entra en la semana; los pedidos a Paraguay cierran el miercoles y a Brasil el jueves; minimo 22.500 cajas al cierre del sabado (Bolivia incluida).
B7: Y la practica de las multinacionales de fruta (S&OP semanal): un solo plan de demanda, proyeccion de inventario por semana con dias de cobertura, stock minimo explicito, recomendacion de pedido con fecha limite por lead time, escenarios, KPIs y tablero de proveedores.
A8: COMO SE USA
A9: 1 | B9: Parametros: fecha del conteo, conteo por origen, minimo, lead times, cajas por camion, escenario. Las celdas AMARILLAS son las que se tocan; las blancas son formulas.
A10: 2 | B10: Demanda: venta plan por semana (viene de la hoja ventas_plan), factor por semana del mes (1a, 2a, 3a, 4a/5a) y una columna "Venta manual" que pisa todo. Anota la venta real del ERP cuando cierre la semana: la planilla calcula el desvio.
A11: 3 | B11: Cargas: una fila por camion (Aloha, dictado, supuesto). Para simular, agrega filas: fecha de carga, origen, productor, cajas. La descarga, la semana a la que suma y el costo salen solos.
A12: 4 | B12: Proyeccion: stock al sabado semana por semana, total y por origen, dias de cobertura, camiones a cargar y fecha limite. Los faltantes se arrastran a la semana siguiente (como el simulador web).
A13: 5 | B13: Que cargar: la recomendacion en limpio, con el origen que queda mas justo y el dia en que cierra el pedido.
A14: 6 | B14: Escenarios: la misma proyeccion con venta -10% / base / +10% lado a lado. El atraso en frontera se prueba desde Parametros.
A15: 7 | B15: KPIs: cobertura, semanas bajo minimo, camiones por semana, mix por origen, costo estimado, exactitud del pronostico, y una tabla de referencia de como lo miden las multinacionales.
A16: 8 | B16: Proveedores: capacidad y comportamiento real de cada productor (camiones por semana, lead time real, transportista, dias de carga, precio 2026).
A17: 9 | B17: Glosario: terminos y buenas practicas, con las fuentes consultadas.
A18: 10 | B18: Calendario: la rutina S&OP de la semana (que se mira cada dia, quien decide, con que hoja). Semaforo: una pantalla con el estado por origen para esta semana, la proxima y la siguiente, mas los riesgos abiertos.
A19: 11 | B19: Capacidad: cajas a madurar por semana contra lo que las camaras pueden madurar, y stock contra la capacidad fisica (hay que completar camaras y cajas en Parametros). MercadoPY: exportadores de Paraguay con volumen, como alternativas si falla un proveedor habitual.
A20: CONVENCION | B20: Amarillo = entrada. Blanco = formula (no tocar). Rojo = falta / bajo minimo. Verde = ok. Las fechas van en dd/mm/aaaa.
A21: ORIGEN DE LOS DATOS | B21: plan_compras.json (paso 5j de actualizar_precios.ps1): Plan de Cargas de Aloha, cargas dictadas por Gonzalo (plan_compras.xlsx), supuestos PY, ventas_plan, conteo por camara. Precios: precios_cepea.json (Cepea + cargas 2026).
B22: Para refrescar los datos: volver a correr el script que arma esta planilla (plan_compras\generar_plan_xlsx.ps1) o pegar a mano las cargas nuevas en la hoja Cargas.
A23: QUIEN LA ARMO | B23: Pedido de Gonzalo del 28/09/2026 ("una planilla de plan de compras simulado a medida de mis necesidades y de una empresa multinacional"). La armaron dos sesiones de Claude: una investigo la practica S&OP de las multinacionales de fruta y aporto lead times reales, proveedores, precios de aduana y el mercado exportador de Paraguay; la otra armo las hojas y las formulas sobre los datos del pipeline.

Sheet Calendario
A1: Calendario S&OP semanal de Almar
A2: Rutina fija: que se mira, quien decide y con que hoja, cada dia. Es lo que hacen las multinacionales de fruta (Dole: metricas diarias y semanales de volumen, precio, flete, merma, servicio y capital de trabajo), a escala de 16-17 mil cajas por semana.
A4: Dia | B4: Momento | C4: Que se hace | D4: Decide / carga | E4: Hoja / herramienta
A5: Lunes | B5: manana | C5: Venta real de la semana pasada (ERP) y desvio contra el plan. Si hubo conteo por camara el sabado, actualizar el conteo. Revisar que descargo el fin de semana y el lunes (Aloha). | D5: Gonzalo / administracion | E5: Demanda (col. Venta real ERP), Parametros (conteo), Cargas (descarga real)
A6: Martes | B6: manana | C6: Abastecimiento: bajar el Plan de Cargas de Aloha, marcar camiones en frontera o atrasados, cargar en Cargas lo nuevo, mirar la calidad de lo que llego. | D6: Gonzalo / recepcion | E6: Cargas, Proveedores (lead time real), index_calidad
A7: Miercoles | B7: 12:00 | C7: Llega el WhatsApp del servidor (Cepea, clima, plan de compras). Decision de la semana: cuantos camiones faltan para el sabado siguiente y de que origen. CIERRE DE PEDIDOS PARAGUAY. | D7: Gonzalo | E7: QueCargar, Semaforo, Proveedores (cupos PY)
A8: Jueves | B8: manana | C8: CIERRE DE PEDIDOS BRASIL: confirmar productores, transportistas y dias de carga; dictar las cargas (plan_compras.xlsx) para que entren al plan. | D8: Gonzalo | E8: QueCargar, Proveedores (cupos BR), plan_compras.xlsx hoja cargas_programadas
A9: Viernes | B9: 19:00 | C9: WhatsApp de cierre. Riesgos de la semana que viene: frontera lenta (escenario P90), calidad, Bolivia sin carga, venta distinta a la esperada. Ajustar venta manual si cambio. | D9: Gonzalo | E9: Escenarios, Semaforo, Demanda (venta manual)
A10: Sabado | B10: cierre | C10: Cierre semanal: el stock del sabado es la referencia. Comparar stock real contra el proyectado y anotar la diferencia (merma, conteo, camiones que no llegaron). | D10: Deposito | E10: Parametros (conteo), KPIs
A11: Mensual | B11: primer lunes | C11: Revisar factores de estacionalidad por semana del mes, desvio estandar de la venta, precios de compra por origen, capacidad de camaras, concentracion de proveedores. | D11: Gonzalo | E11: Parametros, Demanda, KPIs, MercadoPY
A13: Reglas fijas: el sabado cierra la semana; lo que descarga el lunes suma a la siguiente; Paraguay carga domingo-lunes-martes (entra en la semana); Brasil cierra pedidos jueves y Paraguay miercoles; minimo 22.500 cajas al sabado, Bolivia incluida.

Sheet Parametros
A1: Parametros
A2: Celdas amarillas: se editan. Todo lo demas de la planilla depende de estas.
A3: Fecha del conteo por camara | B3: 46291 | C3: El stock arranca de aca. Solo cuentan los camiones que descargan DESPUES de esta fecha.
A4: Hoy (FechaHoy) | B4: =TODAY() -> 46294 | C4: Se puede pisar con una fecha fija para revisar un plan viejo.
A5: Minimo al cierre del sabado (cajas) | B5: 22500 | C5: Gonzalo 27/09/2026: "de una semana a otra unas 22/23 mil cajas cerrando el sabado", Bolivia incluida. Equivale a ~7-8 dias de venta (fruta que todavia no maduro: gas + camara).
A6: Cobertura objetivo (dias de venta) | B6: 7 | C6: Referencia para pintar la cobertura: menos que esto = amarillo, menos de 2 = rojo.
A7: Dias de venta por semana | B7: 6 | C7: Lunes a sabado.
A8: Escenario de venta | B8: Base | C8: Multiplica la venta de todas las semanas (salvo las que tengan venta manual). La hoja Escenarios muestra -10% / base / +10% juntos.
A9: Factor de venta del escenario | B9: =IF(B8="Venta +10%",1.1,IF(B8="Venta -10%",0.9,IF(B8="Venta +20%",1.2,IF(B8="Venta -20%",0.8,1)))) -> 1
A10: Atraso extra en frontera (dias) | B10: 0 | C10: Se suma al lead time de todos los camiones sin descarga real. Probar 1 o 2 para ver que pasa si la frontera se traba.
A11: Cajas por camion para los que FALTAN | B11: 1000 | C11: Los camiones reales llevan sus cajas; este promedio se usa para calcular cuantos faltan.
A13: POR ORIGEN | B13: BR | C13: PY | D13: BO | E13: Nota
A14: Dias de carga a descarga (lead time) | B14: 3 | C14: 4 | D14: 6 | E14: Brasil 3: regla de Gonzalo (lo que carga lunes a miercoles entra en la semana; viernes y sabado entra lunes o martes). Paraguay 4: mediana observada en Aloha, decidido por Gonzalo el 28/09/2026 ("paraguay vamos a 4 dias"): un camion PY cargado el martes descarga el sabado y entra en la semana; el del miercoles ya no. Bolivia 6. Los tres valores vienen de plan_compras.json y son los mismos del simulador web y del WhatsApp.
A15: Cajas por camion (tipico) | B15: 1008 | C15: 980 | D15: 1050 | E15: Se usa cuando una fila de Cargas no tiene cajas. 936 los chicos de AXT.
A16: Conteo por camara a la fecha del conteo | B16: 11653 | C16: 13673 | D16: 1646 | E16: =SUM(B16:D16) -> 26972
A17: Cierre de pedidos (dia de la semana anterior) | B17: jueves | C17: miercoles | D17: segun disponibilidad | E17: Gonzalo 27/09: "Brasil cierra los pedidos de la semana siguiente los jueves, Paraguay los miercoles". Por eso el numero tiene que estar el miercoles.
A18: Ultima carga en Aloha | B18: 2026-09-25 | C18: 2026-09-23 | D18: 2026-09-25 | E18: Export de Aloha: Plan - Cargas (export Aloha 2026-09-24).xlsx (2026-09-24 15:51). En el servidor se baja solo en cada corrida.
A20: COSTOS DE REFERENCIA (para el KPI de costo)
A21: Cepea Nanica 1a SC (R$/kg) | B21: 1.18 | C21: semana 2026-09-25
A22: Kg netos por caja | B22: 22
A23: Servicios por caja Brasil (R$: envalado, paletizado, flete interno) | B23: 18 | C23: Gonzalo 27/09: "estoy pagando 18 mas precio na roca". Solo Brasil.
A24: Caja equivalente Cepea (R$) = kg x 22 + servicios | B24: =CepeaKg*KgCaja+ServiciosCaja -> 43.96
A25: Precio promedio pagado Almar Brasil (R$/caja, ponderado 4 semanas) | B25: 36.87 | C25: Gonzalo 28/09: 'Brasil tenes el promedio de la compra semanal que sale en el WhatsApp'. Semanas 05/09 R$ 36.3 (10) · 12/09 R$ 36.5 (14) · 19/09 R$ 38.67 (3) · 26/09 R$ 38.67 (3). Lo regenera el pipeline en precios_cepea.json > almar.semanas.
A26: Tipo de cambio BRL por USD | B26: 5.2
A27: Paraguay: precio por caja (PYG, Carape SIMA) | B27: 60000 | C27: Referencia de mercado, no lo que paga Almar: cambiar por el precio real de compra si se conoce.
A28: Tipo de cambio PYG por USD | B28: 7500
A29: Bolivia: precio de compra | B29: ver fila 32 | C29: Gonzalo lo pasa despues; mientras, la referencia de aduana (fila 31).
A30: COSTO POR CAJA EN USD (lo usan Cargas, KPIs y el valor del stock) | B30: BR | C30: PY | D30: BO | E30: Nota
A31: Referencia: valor declarado en aduana 2026 (VNA, USD/caja) | B31: 11.6 | C31: 11.5 | D31: 10.8 | E31: Penta (aduana UY, ene-ago 2026), USD/kg neto x kg por caja: BR 0,527 x 22 · PY 0,522 x 22 · BO 0,539 x 20. Es CIF-aduana, no precio productor. 2025: 12,7 / 14,9 / 13,8.
A32: Precio de compra real (USD/caja; vacio = referencia) | B32: =ROUND(PrecioBR_BRL/TC_BRL,2) -> 7.09 | C32: 7 | E32: ="Gonzalo 28/09/2026: Paraguay USD 7 por caja; Brasil = promedio ponderado pagado ("&FIXED(PrecioBR_BRL,2)&" R$) / TC "&FIXED(TC_BRL,2)&" (sin los R$ "&ServiciosCaja&" de servicios: puesto en Uruguay serian "&FIXED((PrecioBR_BRL+ServiciosCaja)/TC_BRL,2)&" USD); Bolivia pendiente (queda la referencia de aduana). Carape "&FIXED(PYG_Caja/TC_PYG,2)&" USD es mercado local, no compra." -> Gonzalo 28/09/2026: Paraguay USD 7 por caja; Brasil = promedio ponderado pagado (36,87 R$) / TC 5,20 (sin los R$ 18 de servicios: puesto en Uruguay serian 10,55 USD); Bolivia pendiente (queda la referencia de aduana). Carape 8,00 USD es mercado local, no compra.
A33: USD/caja usado | B33: =IF(B32<>"",B32,B31) -> 7.09 | C33: =IF(C32<>"",C32,C31) -> 7 | D33: =IF(D32<>"",D32,D31) -> 10.8
A34: ESTACIONALIDAD DENTRO DEL MES (factor sobre la venta plan)
A35: Semana del mes | B35: Factor | C35: Nota
A36: 1 | B36: 1 | C36: 1a semana (arranque de mes: sueldos, mas venta)
A37: 2 | B37: 1 | C37: 2a semana
A38: 3 | B38: 1 | C38: 3a semana
A39: 4 | B39: 1 | C39: 4a semana (fin de mes: menos venta)
A40: 5 | B40: 1 | C40: 5a semana (cuando el mes tiene 5 lunes)
A41: Todos en 1,00 hasta que Gonzalo los ajuste con su experiencia (28/09/2026: "las ventas conforme a si es comienzo de mes o final de mes"). Ej: 1,05 / 1,00 / 0,98 / 0,95.
A43: LEAD TIME REAL Y RIESGO (Plan de Cargas Aloha 2024-2026) | B43: BR | C43: PY | D43: BO | E43: Nota
...

Sheet Demanda
A1: Demanda: venta por semana (cajas)
A2: Venta usada = venta manual si hay; si no, venta plan x factor de la semana del mes x factor del escenario. El mix por origen viene de cada fila de la hoja ventas_plan (por eso la semana del 28/09 tiene 54/39/7 y las siguientes 53/38/9: Bolivia 1 carga esa semana); es editable. Anota la venta real del ERP cuando cierre la semana.
A5: Semana (lunes) | B5: Sabado (cierre) | C5: Mes | D5: Semana del mes | E5: Venta plan (cajas) | F5: Factor semana del mes | G5: Venta manual (pisa todo) | H5: VENTA USADA | I5: Mix BR % | J5: Mix PY % | K5: Mix BO % | L5: Venta BR | M5: Venta PY | N5: Venta BO | O5: Venta real ERP (cajas) | P5: Desvio real vs usada | Q5: Fuente / nota
A6: 46286 | B6: =A6+5 -> 46291 | C6: =TEXT(A6,"mmm") -> set | D6: =INT((DAY(A6)-1)/7)+1 -> 3 | E6: 14845 | F6: =IFERROR(VLOOKUP(D6,EstacTabla,2,FALSE),1) -> 1 | H6: =IF(G6<>"",G6,ROUND(E6*F6*FactorEscenario,0)) -> 14845 | I6: 0.533 | J6: 0.419 | K6: =1-I6-J6 -> 0.048 | L6: =ROUND(H6*I6,0) -> 7912 | M6: =ROUND(H6*J6,0) -> 6220 | N6: =H6-L6-M6 -> 713 | O6: 14845 | P6: =IF(O6="","",O6/H6-1) -> 0 | Q6: REAL ERP (captura 29/09/2026)
A7: 46293 | B7: =A7+5 -> 46298 | C7: =TEXT(A7,"mmm") -> set | D7: =INT((DAY(A7)-1)/7)+1 -> 4 | E7: 16000 | F7: =IFERROR(VLOOKUP(D7,EstacTabla,2,FALSE),1) -> 1 | H7: =IF(G7<>"",G7,ROUND(E7*F7*FactorEscenario,0)) -> 16000 | I7: 0.54 | J7: 0.394 | K7: =1-I7-J7 -> 0.066 | L7: =ROUND(H7*I7,0) -> 8640 | M7: =ROUND(H7*J7,0) -> 6304 | N7: =H7-L7-M7 -> 1056 | P7: =IF(O7="","",O7/H7-1) | Q7: Gonzalo 27/09: se pide vender 16.000; Bolivia 1 carga, el resto PY y BR
A8: 46300 | B8: =A8+5 -> 46305 | C8: =TEXT(A8,"mmm") -> Oct | D8: =INT((DAY(A8)-1)/7)+1 -> 1 | E8: 17000 | F8: =IFERROR(VLOOKUP(D8,EstacTabla,2,FALSE),1) -> 1 | H8: =IF(G8<>"",G8,ROUND(E8*F8*FactorEscenario,0)) -> 17000 | I8: 0.617 | J8: 0.312 | K8: =1-I8-J8 -> 0.071 | L8: =ROUND(H8*I8,0) -> 10489 | M8: =ROUND(H8*J8,0) -> 5304 | N8: =H8-L8-M8 -> 1207 | P8: =IF(O8="","",O8/H8-1) | Q8: SUPUESTO = semana anterior (confirmar)
A9: 46307 | B9: =A9+5 -> 46312 | C9: =TEXT(A9,"mmm") -> Oct | D9: =INT((DAY(A9)-1)/7)+1 -> 2 | E9: 17000 | F9: =IFERROR(VLOOKUP(D9,EstacTabla,2,FALSE),1) -> 1 | H9: =IF(G9<>"",G9,ROUND(E9*F9*FactorEscenario,0)) -> 17000 | I9: 0.617 | J9: 0.312 | K9: =1-I9-J9 -> 0.071 | L9: =ROUND(H9*I9,0) -> 10489 | M9: =ROUND(H9*J9,0) -> 5304 | N9: =H9-L9-M9 -> 1207 | P9: =IF(O9="","",O9/H9-1) | Q9: SUPUESTO = semana anterior (confirmar)
A10: 46314 | B10: =A10+5 -> 46319 | C10: =TEXT(A10,"mmm") -> Oct | D10: =INT((DAY(A10)-1)/7)+1 -> 3 | E10: 17000 | F10: =IFERROR(VLOOKUP(D10,EstacTabla,2,FALSE),1) -> 1 | H10: =IF(G10<>"",G10,ROUND(E10*F10*FactorEscenario,0)) -> 17000 | I10: 0.617 | J10: 0.312 | K10: =1-I10-J10 -> 0.071 | L10: =ROUND(H10*I10,0) -> 10489 | M10: =ROUND(H10*J10,0) -> 5304 | N10: =H10-L10-M10 -> 1207 | P10: =IF(O10="","",O10/H10-1) | Q10: SUPUESTO = semana anterior (confirmar)
A11: 46321 | B11: =A11+5 -> 46326 | C11: =TEXT(A11,"mmm") -> Oct | D11: =INT((DAY(A11)-1)/7)+1 -> 4 | E11: 17000 | F11: =IFERROR(VLOOKUP(D11,EstacTabla,2,FALSE),1) -> 1 | H11: =IF(G11<>"",G11,ROUND(E11*F11*FactorEscenario,0)) -> 17000 | I11: 0.617 | J11: 0.312 | K11: =1-I11-J11 -> 0.071 | L11: =ROUND(H11*I11,0) -> 10489 | M11: =ROUND(H11*J11,0) -> 5304 | N11: =H11-L11-M11 -> 1207 | P11: =IF(O11="","",O11/H11-1) | Q11: sin fila en ventas_plan: copia de la semana del 19/10 (SUPUESTO)
A12: 46328 | B12: =A12+5 -> 46333 | C12: =TEXT(A12,"mmm") -> Nov | D12: =INT((DAY(A12)-1)/7)+1 -> 1 | E12: 17000 | F12: =IFERROR(VLOOKUP(D12,EstacTabla,2,FALSE),1) -> 1 | H12: =IF(G12<>"",G12,ROUND(E12*F12*FactorEscenario,0)) -> 17000 | I12: 0.617 | J12: 0.312 | K12: =1-I12-J12 -> 0.071 | L12: =ROUND(H12*I12,0) -> 10489 | M12: =ROUND(H12*J12,0) -> 5304 | N12: =H12-L12-M12 -> 1207 | P12: =IF(O12="","",O12/H12-1) | Q12: sin fila en ventas_plan: copia de la semana del 19/10 (SUPUESTO)
A13: 46335 | B13: =A13+5 -> 46340 | C13: =TEXT(A13,"mmm") -> Nov | D13: =INT((DAY(A13)-1)/7)+1 -> 2 | E13: 17000 | F13: =IFERROR(VLOOKUP(D13,EstacTabla,2,FALSE),1) -> 1 | H13: =IF(G13<>"",G13,ROUND(E13*F13*FactorEscenario,0)) -> 17000 | I13: 0.617 | J13: 0.312 | K13: =1-I13-J13 -> 0.071 | L13: =ROUND(H13*I13,0) -> 10489 | M13: =ROUND(H13*J13,0) -> 5304 | N13: =H13-L13-M13 -> 1207 | P13: =IF(O13="","",O13/H13-1) | Q13: sin fila en ventas_plan: copia de la semana del 19/10 (SUPUESTO)
A14: 46342 | B14: =A14+5 -> 46347 | C14: =TEXT(A14,"mmm") -> Nov | D14: =INT((DAY(A14)-1)/7)+1 -> 3 | E14: 17000 | F14: =IFERROR(VLOOKUP(D14,EstacTabla,2,FALSE),1) -> 1 | H14: =IF(G14<>"",G14,ROUND(E14*F14*FactorEscenario,0)) -> 17000 | I14: 0.617 | J14: 0.312 | K14: =1-I14-J14 -> 0.071 | L14: =ROUND(H14*I14,0) -> 10489 | M14: =ROUND(H14*J14,0) -> 5304 | N14: =H14-L14-M14 -> 1207 | P14: =IF(O14="","",O14/H14-1) | Q14: sin fila en ventas_plan: copia de la semana del 19/10 (SUPUESTO)
A15: 46349 | B15: =A15+5 -> 46354 | C15: =TEXT(A15,"mmm") -> Nov | D15: =INT((DAY(A15)-1)/7)+1 -> 4 | E15: 17000 | F15: =IFERROR(VLOOKUP(D15,EstacTabla,2,FALSE),1) -> 1 | H15: =IF(G15<>"",G15,ROUND(E15*F15*FactorEscenario,0)) -> 17000 | I15: 0.617 | J15: 0.312 | K15: =1-I15-J15 -> 0.071 | L15: =ROUND(H15*I15,0) -> 10489 | M15: =ROUND(H15*J15,0) -> 5304 | N15: =H15-L15-M15 -> 1207 | P15: =IF(O15="","",O15/H15-1) | Q15: sin fila en ventas_plan: copia de la semana del 19/10 (SUPUESTO)
A16: 46356 | B16: =A16+5 -> 46361 | C16: =TEXT(A16,"mmm") -> Nov | D16: =INT((DAY(A16)-1)/7)+1 -> 5 | E16: 17000 | F16: =IFERROR(VLOOKUP(D16,EstacTabla,2,FALSE),1) -> 1 | H16: =IF(G16<>"",G16,ROUND(E16*F16*FactorEscenario,0)) -> 17000 | I16: 0.617 | J16: 0.312 | K16: =1-I16-J16 -> 0.071 | L16: =ROUND(H16*I16,0) -> 10489 | M16: =ROUND(H16*J16,0) -> 5304 | N16: =H16-L16-M16 -> 1207 | P16: =IF(O16="","",O16/H16-1) | Q16: sin fila en ventas_plan: copia de la semana del 19/10 (SUPUESTO)
A17: 46363 | B17: =A17+5 -> 46368 | C17: =TEXT(A17,"mmm") -> Dic | D17: =INT((DAY(A17)-1)/7)+1 -> 1 | E17: 17000 | F17: =IFERROR(VLOOKUP(D17,EstacTabla,2,FALSE),1) -> 1 | H17: =IF(G17<>"",G17,ROUND(E17*F17*FactorEscenario,0)) -> 17000 | I17: 0.617 | J17: 0.312 | K17: =1-I17-J17 -> 0.071 | L17: =ROUND(H17*I17,0) -> 10489 | M17: =ROUND(H17*J17,0) -> 5304 | N17: =H17-L17-M17 -> 1207 | P17: =IF(O17="","",O17/H17-1) | Q17: sin fila en ventas_plan: copia de la semana del 19/10 (SUPUESTO)
A18: 46370 | B18: =A18+5 -> 46375 | C18: =TEXT(A18,"mmm") -> Dic | D18: =INT((DAY(A18)-1)/7)+1 -> 2 | E18: 17000 | F18: =IFERROR(VLOOKUP(D18,EstacTabla,2,FALSE),1) -> 1 | H18: =IF(G18<>"",G18,ROUND(E18*F18*FactorEscenario,0)) -> 17000 | I18: 0.617 | J18: 0.312 | K18: =1-I18-J18 -> 0.071 | L18: =ROUND(H18*I18,0) -> 10489 | M18: =ROUND(H18*J18,0) -> 5304 | N18: =H18-L18-M18 -> 1207 | P18: =IF(O18="","",O18/H18-1) | Q18: sin fila en ventas_plan: copia de la semana del 19/10 (SUPUESTO)
A20: HISTORIAL DE VENTA REAL (ERP, cajas por semana lunes-sabado). Agregar semanas en plan_compras.xlsx > ventas_semanales.
A21: Semana (lunes) | B21: Sabado | C21: BR | D21: PY | E21: BO | F21: Ecuador (otro canal) | G21: TOTAL banana (BR+PY+BO) | H21: Semana del mes
A22: 46209 | B22: 46214 | C22: 8884 | D22: 4896 | E22: 713 | F22: 7277 | G22: =C22+D22+E22 -> 14493 | H22: =INT((DAY(A22)-1)/7)+1 -> 1
A23: 46216 | B23: 46221 | C23: 8547 | D23: 3607 | E23: 344 | F23: 6900 | G23: =C23+D23+E23 -> 12498 | H23: =INT((DAY(A23)-1)/7)+1 -> 2
A24: 46223 | B24: 46228 | C24: 11589 | D24: 2140 | E24: 1025 | F24: 7601 | G24: =C24+D24+E24 -> 14754 | H24: =INT((DAY(A24)-1)/7)+1 -> 3
A25: 46230 | B25: 46235 | C25: 9196 | D25: 4748 | E25: 0 | F25: 7884 | G25: =C25+D25+E25 -> 13944 | H25: =INT((DAY(A25)-1)/7)+1 -> 4
A26: 46237 | B26: 46242 | C26: 9880 | D26: 5192 | E26: 866 | F26: 7601 | G26: =C26+D26+E26 -> 15938 | H26: =INT((DAY(A26)-1)/7)+1 -> 1
A27: 46244 | B27: 46249 | C27: 6972 | D27: 6201 | E27: 1816 | F27: 6647 | G27: =C27+D27+E27 -> 14989 | H27: =INT((DAY(A27)-1)/7)+1 -> 2
A28: 46251 | B28: 46256 | C28: 8041 | D28: 5861 | E28: 34 | F28: 6290 | G28: =C28+D28+E28 -> 13936 | H28: =INT((DAY(A28)-1)/7)+1 -> 3
A29: 46258 | B29: 46263 | C29: 6633 | D29: 7058 | E29: 1051 | F29: 4669 | G29: =C29+D29+E29 -> 14742 | H29: =INT((DAY(A29)-1)/7)+1 -> 4
A30: 46265 | B30: 46270 | C30: 11032 | D30: 5369 | E30: 873 | F30: 7102 | G30: =C30+D30+E30 -> 17274 | H30: =INT((DAY(A30)-1)/7)+1 -> 5
A31: 46272 | B31: 46277 | C31: 12293 | D31: 2770 | E31: 1486 | F31: 6924 | G31: =C31+D31+E31 -> 16549 | H31: =INT((DAY(A31)-1)/7)+1 -> 1
A32: 46279 | B32: 46284 | C32: 8590 | D32: 5769 | E32: 1492 | F32: 6673 | G32: =C32+D32+E32 -> 15851 | H32: =INT((DAY(A32)-1)/7)+1 -> 2
A33: 46286 | B33: 46291 | C33: 7919 | D33: 6221 | E33: 705 | F33: 6718 | G33: =C33+D33+E33 -> 14845 | H33: =INT((DAY(A33)-1)/7)+1 -> 3
A35: Promedio de todas las semanas | C35: =ROUND(AVERAGE(C22:C33),0) -> 9131 | D35: =ROUND(AVERAGE(D22:D33),0) -> 4986 | E35: =ROUND(AVERAGE(E22:E33),0) -> 867 | F35: =ROUND(AVERAGE(F22:F33),0) -> 6857 | G35: =ROUND(AVERAGE(G22:G33),0) -> 14984
A36: Promedio ultimas 4 semanas | C36: =ROUND(AVERAGE(C30:C33),0) -> 9959 | D36: =ROUND(AVERAGE(D30:D33),0) -> 5032 | E36: =ROUND(AVERAGE(E30:E33),0) -> 1139 | F36: =ROUND(AVERAGE(F30:F33),0) -> 6854 | G36: =ROUND(AVERAGE(G30:G33),0) -> 16130
A37: Desvio estandar (todas) | C37: =ROUND(STDEV(C22:C33),0) -> 1770 | D37: =ROUND(STDEV(D22:D33),0) -> 1472 | E37: =ROUND(STDEV(E22:E33),0) -> 564 | F37: =ROUND(STDEV(F22:F33),0) -> 832 | G37: =ROUND(STDEV(G22:G33),0) -> 1282
A38: Mix ultimas 4 semanas (sobre banana) | C38: =SUM(C30:C33)/SUM(G30:G33) -> 0.61739953 | D38: =SUM(D30:D33)/SUM(G30:G33) -> 0.31198562 | E38: =SUM(E30:E33)/SUM(G30:G33) -> 0.070614858 | F38: ="" | G38: =1 -> 1
A39: Lectura: el plan usa 16.000 (sem 28/09) y 17.000 (despues) contra un promedio real de las ultimas 4 semanas que se ve arriba; el mix real de esas 4 semanas es el que reparte los SUPUESTOS de ventas_plan desde el 29/09. El desvio estandar del total alimenta el stock de seguridad de Parametros.

Sheet Cargas
A1: Cargas: un camion por fila
A2: Amarillo = se carga a mano. Descarga = fecha real si la hay; si no, carga + lead time del origen + atraso del escenario. Solo suman los que descargan despues del conteo (Cuenta = 1). Para simular: agregar filas abajo con Estado = Simulado.
A4: N | B4: Fecha carga | C4: Dia | D4: Origen | E4: Productor | F4: Transportista | G4: Cajas (vacio = tipico) | H4: Cajas usadas | I4: Estado | J4: Descarga real | K4: Lead time (dias) | L4: Fecha descarga | M4: Semana de venta (lunes) | N4: Cuenta | O4: USD/caja | P4: Costo USD | Q4: Nota | R4: Descarga pesimista (P90) | S4: Semana de venta P90 | T4: Pipeline (cargado, sin descargar) | U4: OTIF (1 = descargo a tiempo)
A5: =IF(B5="","",ROW()-4) -> 1 | B5: 46288 | C5: =IF(B5="","",TEXT(B5,"ddd")) -> mié | D5: PY | E5: Paraguay AS | F5: MARSO EMPRENDIMIENTOS S.R.L. | G5: 980 | H5: =IF(B5="","",IF(G5<>"",G5,IFERROR(INDEX(CajasOrigen,MATCH(D5,Origenes,0)),CajasProm))) -> 980 | I5: Aloha | J5: 46292 | K5: =IF(B5="","",IFERROR(INDEX(Lags,MATCH(D5,Origenes,0)),LagBR)+IF(J5<>"",0,AtrasoDias)) -> 4 | L5: =IF(B5="","",IF(J5<>"",J5,B5+K5)) -> 46292 | M5: =IF(L5="","",L5-WEEKDAY(L5,2)+1) -> 46286 | N5: =IF(L5="","",IF(L5>FechaConteo,1,0)*IF(I5="Supuesto",SupPY,IF(I5="Supuesto BR",SupBR,1))) -> 1 | O5: =IF(D5="","",IFERROR(INDEX(CostoOrigen,MATCH(D5,Origenes,0)),0)) -> 7 | P5: =IF(H5="","",H5*O5) -> 6860 | Q5: descarga real confirmada por Gonzalo 28/09/2026 ("domingo 27/09 si descarga"): despues del conteo del sabado 26, suma a la semana del 28/09 | R5: =IF(B5="","",IF(J5<>"",J5,B5+IFERROR(INDEX(LagsP90,MATCH(D5,Origenes,0)),K5))) -> 46292 | S5: =IF(R5="","",R5-WEEKDAY(R5,2)+1) -> 46286 | T5: =IF(B5="","",IF(AND(B5<=FechaHoy,J5="",I5<>"Supuesto",I5<>"Simulado"),H5,0)) -> 0 | U5: =IF(J5="","",IF(J5-B5<=K5+1,1,0)) -> 1
A6: =IF(B6="","",ROW()-4) -> 2 | B6: 46290 | C6: =IF(B6="","",TEXT(B6,"ddd")) -> vie | D6: BO | E6: Bolivia | G6: 1050 | H6: =IF(B6="","",IF(G6<>"",G6,IFERROR(INDEX(CajasOrigen,MATCH(D6,Origenes,0)),CajasProm))) -> 1050 | I6: Aloha | K6: =IF(B6="","",IFERROR(INDEX(Lags,MATCH(D6,Origenes,0)),LagBR)+IF(J6<>"",0,AtrasoDias)) -> 6 | L6: =IF(B6="","",IF(J6<>"",J6,B6+K6)) -> 46296 | M6: =IF(L6="","",L6-WEEKDAY(L6,2)+1) -> 46293 | N6: =IF(L6="","",IF(L6>FechaConteo,1,0)*IF(I6="Supuesto",SupPY,IF(I6="Supuesto BR",SupBR,1))) -> 1 | O6: =IF(D6="","",IFERROR(INDEX(CostoOrigen,MATCH(D6,Origenes,0)),0)) -> 10.8 | P6: =IF(H6="","",H6*O6) -> 11340 | Q6: Aloha: Solicitado | R6: =IF(B6="","",IF(J6<>"",J6,B6+IFERROR(INDEX(LagsP90,MATCH(D6,Origenes,0)),K6))) -> 46298 | S6: =IF(R6="","",R6-WEEKDAY(R6,2)+1) -> 46293 | T6: =IF(B6="","",IF(AND(B6<=FechaHoy,J6="",I6<>"Supuesto",I6<>"Simulado"),H6,0)) -> 1050 | U6: =IF(J6="","",IF(J6-B6<=K6+1,1,0))
A7: =IF(B7="","",ROW()-4) -> 3 | B7: 46290 | C7: =IF(B7="","",TEXT(B7,"ddd")) -> vie | D7: BR | E7: Cassio Hauck | G7: 936 | H7: =IF(B7="","",IF(G7<>"",G7,IFERROR(INDEX(CajasOrigen,MATCH(D7,Origenes,0)),CajasProm))) -> 936 | I7: Aloha | K7: =IF(B7="","",IFERROR(INDEX(Lags,MATCH(D7,Origenes,0)),LagBR)+IF(J7<>"",0,AtrasoDias)) -> 3 | L7: =IF(B7="","",IF(J7<>"",J7,B7+K7)) -> 46293 | M7: =IF(L7="","",L7-WEEKDAY(L7,2)+1) -> 46293 | N7: =IF(L7="","",IF(L7>FechaConteo,1,0)*IF(I7="Supuesto",SupPY,IF(I7="Supuesto BR",SupBR,1))) -> 1 | O7: =IF(D7="","",IFERROR(INDEX(CostoOrigen,MATCH(D7,Origenes,0)),0)) -> 7.09 | P7: =IF(H7="","",H7*O7) -> 6636.24 | Q7: Aloha: Solicitado | R7: =IF(B7="","",IF(J7<>"",J7,B7+IFERROR(INDEX(LagsP90,MATCH(D7,Origenes,0)),K7))) -> 46296 | S7: =IF(R7="","",R7-WEEKDAY(R7,2)+1) -> 46293 | T7: =IF(B7="","",IF(AND(B7<=FechaHoy,J7="",I7<>"Supuesto",I7<>"Simulado"),H7,0)) -> 936 | U7: =IF(J7="","",IF(J7-B7<=K7+1,1,0))
A8: =IF(B8="","",ROW()-4) -> 4 | B8: 46290 | C8: =IF(B8="","",TEXT(B8,"ddd")) -> vie | D8: BR | E8: Corupá | F8: FG | G8: 1008 | H8: =IF(B8="","",IF(G8<>"",G8,IFERROR(INDEX(CajasOrigen,MATCH(D8,Origenes,0)),CajasProm))) -> 1008 | I8: Aloha | K8: =IF(B8="","",IFERROR(INDEX(Lags,MATCH(D8,Origenes,0)),LagBR)+IF(J8<>"",0,AtrasoDias)) -> 3 | L8: =IF(B8="","",IF(J8<>"",J8,B8+K8)) -> 46293 | M8: =IF(L8="","",L8-WEEKDAY(L8,2)+1) -> 46293 | N8: =IF(L8="","",IF(L8>FechaConteo,1,0)*IF(I8="Supuesto",SupPY,IF(I8="Supuesto BR",SupBR,1))) -> 1 | O8: =IF(D8="","",IFERROR(INDEX(CostoOrigen,MATCH(D8,Origenes,0)),0)) -> 7.09 | P8: =IF(H8="","",H8*O8) -> 7146.72 | Q8: Aloha: Solicitado | R8: =IF(B8="","",IF(J8<>"",J8,B8+IFERROR(INDEX(LagsP90,MATCH(D8,Origenes,0)),K8))) -> 46296 | S8: =IF(R8="","",R8-WEEKDAY(R8,2)+1) -> 46293 | T8: =IF(B8="","",IF(AND(B8<=FechaHoy,J8="",I8<>"Supuesto",I8<>"Simulado"),H8,0)) -> 1008 | U8: =IF(J8="","",IF(J8-B8<=K8+1,1,0))
A9: =IF(B9="","",ROW()-4) -> 5 | B9: 46293 | C9: =IF(B9="","",TEXT(B9,"ddd")) -> lun | D9: PY | E9: Paraguay AS | G9: 980 | H9: =IF(B9="","",IF(G9<>"",G9,IFERROR(INDEX(CajasOrigen,MATCH(D9,Origenes,0)),CajasProm))) -> 980 | I9: Dictado | K9: =IF(B9="","",IFERROR(INDEX(Lags,MATCH(D9,Origenes,0)),LagBR)+IF(J9<>"",0,AtrasoDias)) -> 4 | L9: =IF(B9="","",IF(J9<>"",J9,B9+K9)) -> 46297 | M9: =IF(L9="","",L9-WEEKDAY(L9,2)+1) -> 46293 | N9: =IF(L9="","",IF(L9>FechaConteo,1,0)*IF(I9="Supuesto",SupPY,IF(I9="Supuesto BR",SupBR,1))) -> 1 | O9: =IF(D9="","",IFERROR(INDEX(CostoOrigen,MATCH(D9,Origenes,0)),0)) -> 7 | P9: =IF(H9="","",H9*O9) -> 6860 | Q9: nota 25/09: Alvarito 1, nota completa 25/09: lunes confirmado | R9: =IF(B9="","",IF(J9<>"",J9,B9+IFERROR(INDEX(LagsP90,MATCH(D9,Origenes,0)),K9))) -> 46298 | S9: =IF(R9="","",R9-WEEKDAY(R9,2)+1) -> 46293 | T9: =IF(B9="","",IF(AND(B9<=FechaHoy,J9="",I9<>"Supuesto",I9<>"Simulado"),H9,0)) -> 980 | U9: =IF(J9="","",IF(J9-B9<=K9+1,1,0))
A10: =IF(B10="","",ROW()-4) -> 6 | B10: 46293 | C10: =IF(B10="","",TEXT(B10,"ddd")) -> lun | D10: PY | E10: Paraguay DF | G10: 980 | H10: =IF(B10="","",IF(G10<>"",G10,IFERROR(INDEX(CajasOrigen,MATCH(D10,Origenes,0)),CajasProm))) -> 980 | I10: Dictado | K10: =IF(B10="","",IFERROR(INDEX(Lags,MATCH(D10,Origenes,0)),LagBR)+IF(J10<>"",0,AtrasoDias)) -> 4 | L10: =IF(B10="","",IF(J10<>"",J10,B10+K10)) -> 46297 | M10: =IF(L10="","",L10-WEEKDAY(L10,2)+1) -> 46293 | N10: =IF(L10="","",IF(L10>FechaConteo,1,0)*IF(I10="Supuesto",SupPY,IF(I10="Supuesto BR",SupBR,1))) -> 1 | O10: =IF(D10="","",IFERROR(INDEX(CostoOrigen,MATCH(D10,Origenes,0)),0)) -> 7 | P10: =IF(H10="","",H10*O10) -> 6860 | Q10: nota 25/09: Diego 2, nota completa 25/09: lunes confirmado | R10: =IF(B10="","",IF(J10<>"",J10,B10+IFERROR(INDEX(LagsP90,MATCH(D10,Origenes,0)),K10))) -> 46298 | S10: =IF(R10="","",R10-WEEKDAY(R10,2)+1) -> 46293 | T10: =IF(B10="","",IF(AND(B10<=FechaHoy,J10="",I10<>"Supuesto",I10<>"Simulado"),H10,0)) -> 980 | U10: =IF(J10="","",IF(J10-B10<=K10+1,1,0))
A11: =IF(B11="","",ROW()-4) -> 7 | B11: 46293 | C11: =IF(B11="","",TEXT(B11,"ddd")) -> lun | D11: PY | E11: Paraguay MS | G11: 980 | H11: =IF(B11="","",IF(G11<>"",G11,IFERROR(INDEX(CajasOrigen,MATCH(D11,Origenes,0)),CajasProm))) -> 980 | I11: Dictado | K11: =IF(B11="","",IFERROR(INDEX(Lags,MATCH(D11,Origenes,0)),LagBR)+IF(J11<>"",0,AtrasoDias)) -> 4 | L11: =IF(B11="","",IF(J11<>"",J11,B11+K11)) -> 46297 | M11: =IF(L11="","",L11-WEEKDAY(L11,2)+1) -> 46293 | N11: =IF(L11="","",IF(L11>FechaConteo,1,0)*IF(I11="Supuesto",SupPY,IF(I11="Supuesto BR",SupBR,1))) -> 1 | O11: =IF(D11="","",IFERROR(INDEX(CostoOrigen,MATCH(D11,Origenes,0)),0)) -> 7 | P11: =IF(H11="","",H11*O11) -> 6860 | Q11: nota 25/09: Milciades 1, nota completa 25/09: lunes confirmado | R11: =IF(B11="","",IF(J11<>"",J11,B11+IFERROR(INDEX(LagsP90,MATCH(D11,Origenes,0)),K11))) -> 46298 | S11: =IF(R11="","",R11-WEEKDAY(R11,2)+1) -> 46293 | T11: =IF(B11="","",IF(AND(B11<=FechaHoy,J11="",I11<>"Supuesto",I11<>"Simulado"),H11,0)) -> 980 | U11: =IF(J11="","",IF(J11-B11<=K11+1,1,0))
A12: =IF(B12="","",ROW()-4) -> 8 | B12: 46294 | C12: =IF(B12="","",TEXT(B12,"ddd")) -> mar | D12: BR | E12: Ivo zimer | F12: Chabat | G12: 1008 | H12: =IF(B12="","",IF(G12<>"",G12,IFERROR(INDEX(CajasOrigen,MATCH(D12,Origenes,0)),CajasProm))) -> 1008 | I12: Dictado | K12: =IF(B12="","",IFERROR(INDEX(Lags,MATCH(D12,Origenes,0)),LagBR)+IF(J12<>"",0,AtrasoDias)) -> 3 | L12: =IF(B12="","",IF(J12<>"",J12,B12+K12)) -> 46297 | M12: =IF(L12="","",L12-WEEKDAY(L12,2)+1) -> 46293 | N12: =IF(L12="","",IF(L12>FechaConteo,1,0)*IF(I12="Supuesto",SupPY,IF(I12="Supuesto BR",SupBR,1))) -> 1 | O12: =IF(D12="","",IFERROR(INDEX(CostoOrigen,MATCH(D12,Origenes,0)),0)) -> 7.09 | P12: =IF(H12="","",H12*O12) -> 7146.72 | Q12: nota 25/09: tersa | R12: =IF(B12="","",IF(J12<>"",J12,B12+IFERROR(INDEX(LagsP90,MATCH(D12,Origenes,0)),K12))) -> 46300 | S12: =IF(R12="","",R12-WEEKDAY(R12,2)+1) -> 46300 | T12: =IF(B12="","",IF(AND(B12<=FechaHoy,J12="",I12<>"Supuesto",I12<>"Simulado"),H12,0)) -> 1008 | U12: =IF(J12="","",IF(J12-B12<=K12+1,1,0))
A13: =IF(B13="","",ROW()-4) -> 9 | B13: 46294 | C13: =IF(B13="","",TEXT(B13,"ddd")) -> mar | D13: PY | E13: Paraguay DF | G13: 980 | H13: =IF(B13="","",IF(G13<>"",G13,IFERROR(INDEX(CajasOrigen,MATCH(D13,Origenes,0)),CajasProm))) -> 980 | I13: Dictado | K13: =IF(B13="","",IFERROR(INDEX(Lags,MATCH(D13,Origenes,0)),LagBR)+IF(J13<>"",0,AtrasoDias)) -> 4 | L13: =IF(B13="","",IF(J13<>"",J13,B13+K13)) -> 46298 | M13: =IF(L13="","",L13-WEEKDAY(L13,2)+1) -> 46293 | N13: =IF(L13="","",IF(L13>FechaConteo,1,0)*IF(I13="Supuesto",SupPY,IF(I13="Supuesto BR",SupBR,1))) -> 1 | O13: =IF(D13="","",IFERROR(INDEX(CostoOrigen,MATCH(D13,Origenes,0)),0)) -> 7 | P13: =IF(H13="","",H13*O13) -> 6860 | Q13: nota 25/09: Diego 2, nota completa 25/09: martes confirmado | R13: =IF(B13="","",IF(J13<>"",J13,B13+IFERROR(INDEX(LagsP90,MATCH(D13,Origenes,0)),K13))) -> 46299 | S13: =IF(R13="","",R13-WEEKDAY(R13,2)+1) -> 46293 | T13: =IF(B13="","",IF(AND(B13<=FechaHoy,J13="",I13<>"Supuesto",I13<>"Simulado"),H13,0)) -> 980 | U13: =IF(J13="","",IF(J13-B13<=K13+1,1,0))
A14: =IF(B14="","",ROW()-4) -> 10 | B14: 46295 | C14: =IF(B14="","",TEXT(B14,"ddd")) -> mié | D14: BR | E14: Agrocurupa | F14: Nilton | G14: 1008 | H14: =IF(B14="","",IF(G14<>"",G14,IFERROR(INDEX(CajasOrigen,MATCH(D14,Origenes,0)),CajasProm))) -> 1008 | I14: Dictado | K14: =IF(B14="","",IFERROR(INDEX(Lags,MATCH(D14,Origenes,0)),LagBR)+IF(J14<>"",0,AtrasoDias)) -> 3 | L14: =IF(B14="","",IF(J14<>"",J14,B14+K14)) -> 46298 | M14: =IF(L14="","",L14-WEEKDAY(L14,2)+1) -> 46293 | N14: =IF(L14="","",IF(L14>FechaConteo,1,0)*IF(I14="Supuesto",SupPY,IF(I14="Supuesto BR",SupBR,1))) -> 1 | O14: =IF(D14="","",IFERROR(INDEX(CostoOrigen,MATCH(D14,Origenes,0)),0)) -> 7.09 | P14: =IF(H14="","",H14*O14) -> 7146.72 | Q14: nota 25/09: cuarta | R14: =IF(B14="","",IF(J14<>"",J14,B14+IFERROR(INDEX(LagsP90,MATCH(D14,Origenes,0)),K14))) -> 46301 | S14: =IF(R14="","",R14-WEEKDAY(R14,2)+1) -> 46300 | T14: =IF(B14="","",IF(AND(B14<=FechaHoy,J14="",I14<>"Supuesto",I14<>"Simulado"),H14,0)) -> 0 | U14: =IF(J14="","",IF(J14-B14<=K14+1,1,0))
A15: =IF(B15="","",ROW()-4) -> 11 | B15: 46295 | C15: =IF(B15="","",TEXT(B15,"ddd")) -> mié | D15: BR | E15: Fisher | F15: Amaro | G15: 1008 | H15: =IF(B15="","",IF(G15<>"",G15,IFERROR(INDEX(CajasOrigen,MATCH(D15,Origenes,0)),CajasProm))) -> 1008 | I15: Dictado | K15: =IF(B15="","",IFERROR(INDEX(Lags,MATCH(D15,Origenes,0)),LagBR)+IF(J15<>"",0,AtrasoDias)) -> 3 | L15: =IF(B15="","",IF(J15<>"",J15,B15+K15)) -> 46298 | M15: =IF(L15="","",L15-WEEKDAY(L15,2)+1) -> 46293 | N15: =IF(L15="","",IF(L15>FechaConteo,1,0)*IF(I15="Supuesto",SupPY,IF(I15="Supuesto BR",SupBR,1))) -> 1 | O15: =IF(D15="","",IFERROR(INDEX(CostoOrigen,MATCH(D15,Origenes,0)),0)) -> 7.09 | P15: =IF(H15="","",H15*O15) -> 7146.72 | Q15: nota 25/09: cuarta | R15: =IF(B15="","",IF(J15<>"",J15,B15+IFERROR(INDEX(LagsP90,MATCH(D15,Origenes,0)),K15))) -> 46301 | S15: =IF(R15="","",R15-WEEKDAY(R15,2)+1) -> 46300 | T15: =IF(B15="","",IF(AND(B15<=FechaHoy,J15="",I15<>"Supuesto",I15<>"Simulado"),H15,0)) -> 0 | U15: =IF(J15="","",IF(J15-B15<=K15+1,1,0))
A16: =IF(B16="","",ROW()-4) -> 12 | B16: 46295 | C16: =IF(B16="","",TEXT(B16,"ddd")) -> mié | D16: BR | E16: Stein | F16: Nilton | G16: 1008 | H16: =IF(B16="","",IF(G16<>"",G16,IFERROR(INDEX(CajasOrigen,MATCH(D16,Origenes,0)),CajasProm))) -> 1008 | I16: Dictado | K16: =IF(B16="","",IFERROR(INDEX(Lags,MATCH(D16,Origenes,0)),LagBR)+IF(J16<>"",0,AtrasoDias)) -> 3 | L16: =IF(B16="","",IF(J16<>"",J16,B16+K16)) -> 46298 | M16: =IF(L16="","",L16-WEEKDAY(L16,2)+1) -> 46293 | N16: =IF(L16="","",IF(L16>FechaConteo,1,0)*IF(I16="Supuesto",SupPY,IF(I16="Supuesto BR",SupBR,1))) -> 1 | O16: =IF(D16="","",IFERROR(INDEX(CostoOrigen,MATCH(D16,Origenes,0)),0)) -> 7.09 | P16: =IF(H16="","",H16*O16) -> 7146.72 | Q16: carga extra: "asi cierro mejor pensando en futuro" (ademas de la sexta ya dictada) | R16: =IF(B16="","",IF(J16<>"",J16,B16+IFERROR(INDEX(LagsP90,MATCH(D16,Origenes,0)),K16))) -> 46301 | S16: =IF(R16="","",R16-WEEKDAY(R16,2)+1) -> 46300 | T16: =IF(B16="","",IF(AND(B16<=FechaHoy,J16="",I16<>"Supuesto",I16<>"Simulado"),H16,0)) -> 0 | U16: =IF(J16="","",IF(J16-B16<=K16+1,1,0))
A17: =IF(B17="","",ROW()-4) -> 13 | B17: 46297 | C17: =IF(B17="","",TEXT(B17,"ddd")) -> vie | D17: BR | E17: Agrocurupa | F17: Nilton | G17: 1008 | H17: =IF(B17="","",IF(G17<>"",G17,IFERROR(INDEX(CajasOrigen,MATCH(D17,Origenes,0)),CajasProm))) -> 1008 | I17: Dictado | K17: =IF(B17="","",IFERROR(INDEX(Lags,MATCH(D17,Origenes,0)),LagBR)+IF(J17<>"",0,AtrasoDias)) -> 3 | L17: =IF(B17="","",IF(J17<>"",J17,B17+K17)) -> 46300 | M17: =IF(L17="","",L17-WEEKDAY(L17,2)+1) -> 46300 | N17: =IF(L17="","",IF(L17>FechaConteo,1,0)*IF(I17="Supuesto",SupPY,IF(I17="Supuesto BR",SupBR,1))) -> 1 | O17: =IF(D17="","",IFERROR(INDEX(CostoOrigen,MATCH(D17,Origenes,0)),0)) -> 7.09 | P17: =IF(H17="","",H17*O17) -> 7146.72 | Q17: nota 25/09: sexta | R17: =IF(B17="","",IF(J17<>"",J17,B17+IFERROR(INDEX(LagsP90,MATCH(D17,Origenes,0)),K17))) -> 46303 | S17: =IF(R17="","",R17-WEEKDAY(R17,2)+1) -> 46300 | T17: =IF(B17="","",IF(AND(B17<=FechaHoy,J17="",I17<>"Supuesto",I17<>"Simulado"),H17,0)) -> 0 | U17: =IF(J17="","",IF(J17-B17<=K17+1,1,0))
A18: =IF(B18="","",ROW()-4) -> 14 | B18: 46297 | C18: =IF(B18="","",TEXT(B18,"ddd")) -> vie | D18: BR | E18: Cassio | F18: Axt | G18: 936 | H18: =IF(B18="","",IF(G18<>"",G18,IFERROR(INDEX(CajasOrigen,MATCH(D18,Origenes,0)),CajasProm))) -> 936 | I18: Dictado | K18: =IF(B18="","",IFERROR(INDEX(Lags,MATCH(D18,Origenes,0)),LagBR)+IF(J18<>"",0,AtrasoDias)) -> 3 | L18: =IF(B18="","",IF(J18<>"",J18,B18+K18)) -> 46300 | M18: =IF(L18="","",L18-WEEKDAY(L18,2)+1) -> 46300 | N18: =IF(L18="","",IF(L18>FechaConteo,1,0)*IF(I18="Supuesto",SupPY,IF(I18="Supuesto BR",SupBR,1))) -> 1 | O18: =IF(D18="","",IFERROR(INDEX(CostoOrigen,MATCH(D18,Origenes,0)),0)) -> 7.09 | P18: =IF(H18="","",H18*O18) -> 6636.24 | Q18: nota 25/09: sexta | R18: =IF(B18="","",IF(J18<>"",J18,B18+IFERROR(INDEX(LagsP90,MATCH(D18,Origenes,0)),K18))) -> 46303 | S18: =IF(R18="","",R18-WEEKDAY(R18,2)+1) -> 46300 | T18: =IF(B18="","",IF(AND(B18<=FechaHoy,J18="",I18<>"Supuesto",I18<>"Simulado"),H18,0)) -> 0 | U18: =IF(J18="","",IF(J18-B18<=K18+1,1,0))
A19: =IF(B19="","",ROW()-4) -> 15 | B19: 46297 | C19: =IF(B19="","",TEXT(B19,"ddd")) -> vie | D19: BR | E19: Fisher | F19: Amaro | G19: 1008 | H19: =IF(B19="","",IF(G19<>"",G19,IFERROR(INDEX(CajasOrigen,MATCH(D19,Origenes,0)),CajasProm))) -> 1008 | I19: Dictado | K19: =IF(B19="","",IFERROR(INDEX(Lags,MATCH(D19,Origenes,0)),LagBR)+IF(J19<>"",0,AtrasoDias)) -> 3 | L19: =IF(B19="","",IF(J19<>"",J19,B19+K19)) -> 46300 | M19: =IF(L19="","",L19-WEEKDAY(L19,2)+1) -> 46300 | N19: =IF(L19="","",IF(L19>FechaConteo,1,0)*IF(I19="Supuesto",SupPY,IF(I19="Supuesto BR",SupBR,1))) -> 1 | O19: =IF(D19="","",IFERROR(INDEX(CostoOrigen,MATCH(D19,Origenes,0)),0)) -> 7.09 | P19: =IF(H19="","",H19*O19) -> 7146.72 | Q19: nota 25/09: sexta | R19: =IF(B19="","",IF(J19<>"",J19,B19+IFERROR(INDEX(LagsP90,MATCH(D19,Origenes,0)),K19))) -> 46303 | S19: =IF(R19="","",R19-WEEKDAY(R19,2)+1) -> 46300 | T19: =IF(B19="","",IF(AND(B19<=FechaHoy,J19="",I19<>"Supuesto",I19<>"Simulado"),H19,0)) -> 0 | U19: =IF(J19="","",IF(J19-B19<=K19+1,1,0))
A20: =IF(B20="","",ROW()-4) -> 16 | B20: 46297 | C20: =IF(B20="","",TEXT(B20,"ddd")) -> vie | D20: BR | E20: Gilson | F20: Nilton | G20: 1008 | H20: =IF(B20="","",IF(G20<>"",G20,IFERROR(INDEX(CajasOrigen,MATCH(D20,Origenes,0)),CajasProm))) -> 1008 | I20: Dictado | K20: =IF(B20="","",IFERROR(INDEX(Lags,MATCH(D20,Origenes,0)),LagBR)+IF(J20<>"",0,AtrasoDias)) -> 3 | L20: =IF(B20="","",IF(J20<>"",J20,B20+K20)) -> 46300 | M20: =IF(L20="","",L20-WEEKDAY(L20,2)+1) -> 46300 | N20: =IF(L20="","",IF(L20>FechaConteo,1,0)*IF(I20="Supuesto",SupPY,IF(I20="Supuesto BR",SupBR,1))) -> 1 | O20: =IF(D20="","",IFERROR(INDEX(CostoOrigen,MATCH(D20,Origenes,0)),0)) -> 7.09 | P20: =IF(H20="","",H20*O20) -> 7146.72 | Q20: nota 25/09: sexta | R20: =IF(B20="","",IF(J20<>"",J20,B20+IFERROR(INDEX(LagsP90,MATCH(D20,Origenes,0)),K20))) -> 46303 | S20: =IF(R20="","",R20-WEEKDAY(R20,2)+1) -> 46300 | T20: =IF(B20="","",IF(AND(B20<=FechaHoy,J20="",I20<>"Supuesto",I20<>"Simulado"),H20,0)) -> 0 | U20: =IF(J20="","",IF(J20-B20<=K20+1,1,0))
A21: =IF(B21="","",ROW()-4) -> 17 | B21: 46297 | C21: =IF(B21="","",TEXT(B21,"ddd")) -> vie | D21: BR | E21: Ivo zimer | F21: Chabat | G21: 1008 | H21: =IF(B21="","",IF(G21<>"",G21,IFERROR(INDEX(CajasOrigen,MATCH(D21,Origenes,0)),CajasProm))) -> 1008 | I21: Dictado | K21: =IF(B21="","",IFERROR(INDEX(Lags,MATCH(D21,Origenes,0)),LagBR)+IF(J21<>"",0,AtrasoDias)) -> 3 | L21: =IF(B21="","",IF(J21<>"",J21,B21+K21)) -> 46300 | M21: =IF(L21="","",L21-WEEKDAY(L21,2)+1) -> 46300 | N21: =IF(L21="","",IF(L21>FechaConteo,1,0)*IF(I21="Supuesto",SupPY,IF(I21="Supuesto BR",SupBR,1))) -> 1 | O21: =IF(D21="","",IFERROR(INDEX(CostoOrigen,MATCH(D21,Origenes,0)),0)) -> 7.09 | P21: =IF(H21="","",H21*O21) -> 7146.72 | Q21: nota 25/09: sexta | R21: =IF(B21="","",IF(J21<>"",J21,B21+IFERROR(INDEX(LagsP90,MATCH(D21,Origenes,0)),K21))) -> 46303 | S21: =IF(R21="","",R21-WEEKDAY(R21,2)+1) -> 46300 | T21: =IF(B21="","",IF(AND(B21<=FechaHoy,J21="",I21<>"Supuesto",I21<>"Simulado"),H21,0)) -> 0 | U21: =IF(J21="","",IF(J21-B21<=K21+1,1,0))
A22: =IF(B22="","",ROW()-4) -> 18 | B22: 46297 | C22: =IF(B22="","",TEXT(B22,"ddd")) -> vie | D22: BR | E22: Josemar | F22: Nilton | G22: 1008 | H22: =IF(B22="","",IF(G22<>"",G22,IFERROR(INDEX(CajasOrigen,MATCH(D22,Origenes,0)),CajasProm))) -> 1008 | I22: Dictado | K22: =IF(B22="","",IFERROR(INDEX(Lags,MATCH(D22,Origenes,0)),LagBR)+IF(J22<>"",0,AtrasoDias)) -> 3 | L22: =IF(B22="","",IF(J22<>"",J22,B22+K22)) -> 46300 | M22: =IF(L22="","",L22-WEEKDAY(L22,2)+1) -> 46300 | N22: =IF(L22="","",IF(L22>FechaConteo,1,0)*IF(I22="Supuesto",SupPY,IF(I22="Supuesto BR",SupBR,1))) -> 1 | O22: =IF(D22="","",IFERROR(INDEX(CostoOrigen,MATCH(D22,Origenes,0)),0)) -> 7.09 | P22: =IF(H22="","",H22*O22) -> 7146.72 | Q22: nota 25/09: sexta | R22: =IF(B22="","",IF(J22<>"",J22,B22+IFERROR(INDEX(LagsP90,MATCH(D22,Origenes,0)),K22))) -> 46303 | S22: =IF(R22="","",R22-WEEKDAY(R22,2)+1) -> 46300 | T22: =IF(B22="","",IF(AND(B22<=FechaHoy,J22="",I22<>"Supuesto",I22<>"Simulado"),H22,0)) -> 0 | U22: =IF(J22="","",IF(J22-B22<=K22+1,1,0))
A23: =IF(B23="","",ROW()-4) -> 19 | B23: 46297 | C23: =IF(B23="","",TEXT(B23,"ddd")) -> vie | D23: BR | E23: Marconi | F23: Chabat | G23: 1008 | H23: =IF(B23="","",IF(G23<>"",G23,IFERROR(INDEX(CajasOrigen,MATCH(D23,Origenes,0)),CajasProm))) -> 1008 | I23: Dictado | K23: =IF(B23="","",IFERROR(INDEX(Lags,MATCH(D23,Origenes,0)),LagBR)+IF(J23<>"",0,AtrasoDias)) -> 3 | L23: =IF(B23="","",IF(J23<>"",J23,B23+K23)) -> 46300 | M23: =IF(L23="","",L23-WEEKDAY(L23,2)+1) -> 46300 | N23: =IF(L23="","",IF(L23>FechaConteo,1,0)*IF(I23="Supuesto",SupPY,IF(I23="Supuesto BR",SupBR,1))) -> 1 | O23: =IF(D23="","",IFERROR(INDEX(CostoOrigen,MATCH(D23,Origenes,0)),0)) -> 7.09 | P23: =IF(H23="","",H23*O23) -> 7146.72 | Q23: nota 25/09: sexta | R23: =IF(B23="","",IF(J23<>"",J23,B23+IFERROR(INDEX(LagsP90,MATCH(D23,Origenes,0)),K23))) -> 46303 | S23: =IF(R23="","",R23-WEEKDAY(R23,2)+1) -> 46300 | T23: =IF(B23="","",IF(AND(B23<=FechaHoy,J23="",I23<>"Supuesto",I23<>"Simulado"),H23,0)) -> 0 | U23: =IF(J23="","",IF(J23-B23<=K23+1,1,0))
A24: =IF(B24="","",ROW()-4) -> 20 | B24: 46297 | C24: =IF(B24="","",TEXT(B24,"ddd")) -> vie | D24: BR | E24: Stein | F24: Nilton | G24: 1008 | H24: =IF(B24="","",IF(G24<>"",G24,IFERROR(INDEX(CajasOrigen,MATCH(D24,Origenes,0)),CajasProm))) -> 1008 | I24: Dictado | K24: =IF(B24="","",IFERROR(INDEX(Lags,MATCH(D24,Origenes,0)),LagBR)+IF(J24<>"",0,AtrasoDias)) -> 3 | L24: =IF(B24="","",IF(J24<>"",J24,B24+K24)) -> 46300 | M24: =IF(L24="","",L24-WEEKDAY(L24,2)+1) -> 46300 | N24: =IF(L24="","",IF(L24>FechaConteo,1,0)*IF(I24="Supuesto",SupPY,IF(I24="Supuesto BR",SupBR,1))) -> 1 | O24: =IF(D24="","",IFERROR(INDEX(CostoOrigen,MATCH(D24,Origenes,0)),0)) -> 7.09 | P24: =IF(H24="","",H24*O24) -> 7146.72 | Q24: nota 25/09: sexta | R24: =IF(B24="","",IF(J24<>"",J24,B24+IFERROR(INDEX(LagsP90,MATCH(D24,Origenes,0)),K24))) -> 46303 | S24: =IF(R24="","",R24-WEEKDAY(R24,2)+1) -> 46300 | T24: =IF(B24="","",IF(AND(B24<=FechaHoy,J24="",I24<>"Supuesto",I24<>"Simulado"),H24,0)) -> 0 | U24: =IF(J24="","",IF(J24-B24<=K24+1,1,0))
A25: =IF(B25="","",ROW()-4) -> 21 | B25: 46300 | C25: =IF(B25="","",TEXT(B25,"ddd")) -> lun | D25: PY | E25: Paraguay (supuesto) | G25: 980 | H25: =IF(B25="","",IF(G25<>"",G25,IFERROR(INDEX(CajasOrigen,MATCH(D25,Origenes,0)),CajasProm))) -> 980 | I25: Supuesto | K25: =IF(B25="","",IFERROR(INDEX(Lags,MATCH(D25,Origenes,0)),LagBR)+IF(J25<>"",0,AtrasoDias)) -> 4 | L25: =IF(B25="","",IF(J25<>"",J25,B25+K25)) -> 46304 | M25: =IF(L25="","",L25-WEEKDAY(L25,2)+1) -> 46300 | N25: =IF(L25="","",IF(L25>FechaConteo,1,0)*IF(I25="Supuesto",SupPY,IF(I25="Supuesto BR",SupBR,1))) -> 1 | O25: =IF(D25="","",IFERROR(INDEX(CostoOrigen,MATCH(D25,Origenes,0)),0)) -> 7 | P25: =IF(H25="","",H25*O25) -> 6860 | Q25: supuesto: 5 camiones PY por semana, cargan dom-lun-mar (Gonzalo 27/09) | R25: =IF(B25="","",IF(J25<>"",J25,B25+IFERROR(INDEX(LagsP90,MATCH(D25,Origenes,0)),K25))) -> 46305 | S25: =IF(R25="","",R25-WEEKDAY(R25,2)+1) -> 46300 | T25: =IF(B25="","",IF(AND(B25<=FechaHoy,J25="",I25<>"Supuesto",I25<>"Simulado"),H25,0)) -> 0 | U25: =IF(J25="","",IF(J25-B25<=K25+1,1,0))
A26: =IF(B26="","",ROW()-4) -> 22 | B26: 46300 | C26: =IF(B26="","",TEXT(B26,"ddd")) -> lun | D26: PY | E26: Paraguay (supuesto) | G26: 980 | H26: =IF(B26="","",IF(G26<>"",G26,IFERROR(INDEX(CajasOrigen,MATCH(D26,Origenes,0)),CajasProm))) -> 980 | I26: Supuesto | K26: =IF(B26="","",IFERROR(INDEX(Lags,MATCH(D26,Origenes,0)),LagBR)+IF(J26<>"",0,AtrasoDias)) -> 4 | L26: =IF(B26="","",IF(J26<>"",J26,B26+K26)) -> 46304 | M26: =IF(L26="","",L26-WEEKDAY(L26,2)+1) -> 46300 | N26: =IF(L26="","",IF(L26>FechaConteo,1,0)*IF(I26="Supuesto",SupPY,IF(I26="Supuesto BR",SupBR,1))) -> 1 | O26: =IF(D26="","",IFERROR(INDEX(CostoOrigen,MATCH(D26,Origenes,0)),0)) -> 7 | P26: =IF(H26="","",H26*O26) -> 6860 | Q26: supuesto: 5 camiones PY por semana, cargan dom-lun-mar (Gonzalo 27/09) | R26: =IF(B26="","",IF(J26<>"",J26,B26+IFERROR(INDEX(LagsP90,MATCH(D26,Origenes,0)),K26))) -> 46305 | S26: =IF(R26="","",R26-WEEKDAY(R26,2)+1) -> 46300 | T26: =IF(B26="","",IF(AND(B26<=FechaHoy,J26="",I26<>"Supuesto",I26<>"Simulado"),H26,0)) -> 0 | U26: =IF(J26="","",IF(J26-B26<=K26+1,1,0))
A27: =IF(B27="","",ROW()-4) -> 23 | B27: 46300 | C27: =IF(B27="","",TEXT(B27,"ddd")) -> lun | D27: PY | E27: Paraguay (supuesto) | G27: 980 | H27: =IF(B27="","",IF(G27<>"",G27,IFERROR(INDEX(CajasOrigen,MATCH(D27,Origenes,0)),CajasProm))) -> 980 | I27: Supuesto | K27: =IF(B27="","",IFERROR(INDEX(Lags,MATCH(D27,Origenes,0)),LagBR)+IF(J27<>"",0,AtrasoDias)) -> 4 | L27: =IF(B27="","",IF(J27<>"",J27,B27+K27)) -> 46304 | M27: =IF(L27="","",L27-WEEKDAY(L27,2)+1) -> 46300 | N27: =IF(L27="","",IF(L27>FechaConteo,1,0)*IF(I27="Supuesto",SupPY,IF(I27="Supuesto BR",SupBR,1))) -> 1 | O27: =IF(D27="","",IFERROR(INDEX(CostoOrigen,MATCH(D27,Origenes,0)),0)) -> 7 | P27: =IF(H27="","",H27*O27) -> 6860 | Q27: supuesto: 5 camiones PY por semana, cargan dom-lun-mar (Gonzalo 27/09) | R27: =IF(B27="","",IF(J27<>"",J27,B27+IFERROR(INDEX(LagsP90,MATCH(D27,Origenes,0)),K27))) -> 46305 | S27: =IF(R27="","",R27-WEEKDAY(R27,2)+1) -> 46300 | T27: =IF(B27="","",IF(AND(B27<=FechaHoy,J27="",I27<>"Supuesto",I27<>"Simulado"),H27,0)) -> 0 | U27: =IF(J27="","",IF(J27-B27<=K27+1,1,0))
A28: =IF(B28="","",ROW()-4) -> 24 | B28: 46300 | C28: =IF(B28="","",TEXT(B28,"ddd")) -> lun | D28: PY | E28: Paraguay (supuesto) | G28: 980 | H28: =IF(B28="","",IF(G28<>"",G28,IFERROR(INDEX(CajasOrigen,MATCH(D28,Origenes,0)),CajasProm))) -> 980 | I28: Supuesto | K28: =IF(B28="","",IFERROR(INDEX(Lags,MATCH(D28,Origenes,0)),LagBR)+IF(J28<>"",0,AtrasoDias)) -> 4 | L28: =IF(B28="","",IF(J28<>"",J28,B28+K28)) -> 46304 | M28: =IF(L28="","",L28-WEEKDAY(L28,2)+1) -> 46300 | N28: =IF(L28="","",IF(L28>FechaConteo,1,0)*IF(I28="Supuesto",SupPY,IF(I28="Supuesto BR",SupBR,1))) -> 1 | O28: =IF(D28="","",IFERROR(INDEX(CostoOrigen,MATCH(D28,Origenes,0)),0)) -> 7 | P28: =IF(H28="","",H28*O28) -> 6860 | Q28: supuesto: 5 camiones PY por semana, cargan dom-lun-mar (Gonzalo 27/09) | R28: =IF(B28="","",IF(J28<>"",J28,B28+IFERROR(INDEX(LagsP90,MATCH(D28,Origenes,0)),K28))) -> 46305 | S28: =IF(R28="","",R28-WEEKDAY(R28,2)+1) -> 46300 | T28: =IF(B28="","",IF(AND(B28<=FechaHoy,J28="",I28<>"Supuesto",I28<>"Simulado"),H28,0)) -> 0 | U28: =IF(J28="","",IF(J28-B28<=K28+1,1,0))
A29: =IF(B29="","",ROW()-4) -> 25 | B29: 46300 | C29: =IF(B29="","",TEXT(B29,"ddd")) -> lun | D29: PY | E29: Paraguay (supuesto) | G29: 980 | H29: =IF(B29="","",IF(G29<>"",G29,IFERROR(INDEX(CajasOrigen,MATCH(D29,Origenes,0)),CajasProm))) -> 980 | I29: Supuesto | K29: =IF(B29="","",IFERROR(INDEX(Lags,MATCH(D29,Origenes,0)),LagBR)+IF(J29<>"",0,AtrasoDias)) -> 4 | L29: =IF(B29="","",IF(J29<>"",J29,B29+K29)) -> 46304 | M29: =IF(L29="","",L29-WEEKDAY(L29,2)+1) -> 46300 | N29: =IF(L29="","",IF(L29>FechaConteo,1,0)*IF(I29="Supuesto",SupPY,IF(I29="Supuesto BR",SupBR,1))) -> 1 | O29: =IF(D29="","",IFERROR(INDEX(CostoOrigen,MATCH(D29,Origenes,0)),0)) -> 7 | P29: =IF(H29="","",H29*O29) -> 6860 | Q29: supuesto: 5 camiones PY por semana, cargan dom-lun-mar (Gonzalo 27/09) | R29: =IF(B29="","",IF(J29<>"",J29,B29+IFERROR(INDEX(LagsP90,MATCH(D29,Origenes,0)),K29))) -> 46305 | S29: =IF(R29="","",R29-WEEKDAY(R29,2)+1) -> 46300 | T29: =IF(B29="","",IF(AND(B29<=FechaHoy,J29="",I29<>"Supuesto",I29<>"Simulado"),H29,0)) -> 0 | U29: =IF(J29="","",IF(J29-B29<=K29+1,1,0))
A30: =IF(B30="","",ROW()-4) -> 26 | B30: 46304 | C30: =IF(B30="","",TEXT(B30,"ddd")) -> vie | D30: BR | E30: Brasil (supuesto) | G30: 1008 | H30: =IF(B30="","",IF(G30<>"",G30,IFERROR(INDEX(CajasOrigen,MATCH(D30,Origenes,0)),CajasProm))) -> 1008 | I30: Supuesto BR | K30: =IF(B30="","",IFERROR(INDEX(Lags,MATCH(D30,Origenes,0)),LagBR)+IF(J30<>"",0,AtrasoDias)) -> 3 | L30: =IF(B30="","",IF(J30<>"",J30,B30+K30)) -> 46307 | M30: =IF(L30="","",L30-WEEKDAY(L30,2)+1) -> 46307 | N30: =IF(L30="","",IF(L30>FechaConteo,1,0)*IF(I30="Supuesto",SupPY,IF(I30="Supuesto BR",SupBR,1))) -> 1 | O30: =IF(D30="","",IFERROR(INDEX(CostoOrigen,MATCH(D30,Origenes,0)),0)) -> 7.09 | P30: =IF(H30="","",H30*O30) -> 7146.72 | Q30: supuesto: 8 camiones BR los viernes, ritmo habitual (Gonzalo 28/09); se apaga en Parametros > SupBR | R30: =IF(B30="","",IF(J30<>"",J30,B30+IFERROR(INDEX(LagsP90,MATCH(D30,Origenes,0)),K30))) -> 46310 | S30: =IF(R30="","",R30-WEEKDAY(R30,2)+1) -> 46307 | T30: =IF(B30="","",IF(AND(B30<=FechaHoy,J30="",I30<>"Supuesto",I30<>"Simulado"),H30,0)) -> 0 | U30: =IF(J30="","",IF(J30-B30<=K30+1,1,0))
A31: =IF(B31="","",ROW()-4) -> 27 | B31: 46304 | C31: =IF(B31="","",TEXT(B31,"ddd")) -> vie | D31: BR | E31: Brasil (supuesto) | G31: 1008 | H31: =IF(B31="","",IF(G31<>"",G31,IFERROR(INDEX(CajasOrigen,MATCH(D31,Origenes,0)),CajasProm))) -> 1008 | I31: Supuesto BR | K31: =IF(B31="","",IFERROR(INDEX(Lags,MATCH(D31,Origenes,0)),LagBR)+IF(J31<>"",0,AtrasoDias)) -> 3 | L31: =IF(B31="","",IF(J31<>"",J31,B31+K31)) -> 46307 | M31: =IF(L31="","",L31-WEEKDAY(L31,2)+1) -> 46307 | N31: =IF(L31="","",IF(L31>FechaConteo,1,0)*IF(I31="Supuesto",SupPY,IF(I31="Supuesto BR",SupBR,1))) -> 1 | O31: =IF(D31="","",IFERROR(INDEX(CostoOrigen,MATCH(D31,Origenes,0)),0)) -> 7.09 | P31: =IF(H31="","",H31*O31) -> 7146.72 | Q31: supuesto: 8 camiones BR los viernes, ritmo habitual (Gonzalo 28/09); se apaga en Parametros > SupBR | R31: =IF(B31="","",IF(J31<>"",J31,B31+IFERROR(INDEX(LagsP90,MATCH(D31,Origenes,0)),K31))) -> 46310 | S31: =IF(R31="","",R31-WEEKDAY(R31,2)+1) -> 46307 | T31: =IF(B31="","",IF(AND(B31<=FechaHoy,J31="",I31<>"Supuesto",I31<>"Simulado"),H31,0)) -> 0 | U31: =IF(J31="","",IF(J31-B31<=K31+1,1,0))
A32: =IF(B32="","",ROW()-4) -> 28 | B32: 46304 | C32: =IF(B32="","",TEXT(B32,"ddd")) -> vie | D32: BR | E32: Brasil (supuesto) | G32: 1008 | H32: =IF(B32="","",IF(G32<>"",G32,IFERROR(INDEX(CajasOrigen,MATCH(D32,Origenes,0)),CajasProm))) -> 1008 | I32: Supuesto BR | K32: =IF(B32="","",IFERROR(INDEX(Lags,MATCH(D32,Origenes,0)),LagBR)+IF(J32<>"",0,AtrasoDias)) -> 3 | L32: =IF(B32="","",IF(J32<>"",J32,B32+K32)) -> 46307 | M32: =IF(L32="","",L32-WEEKDAY(L32,2)+1) -> 46307 | N32: =IF(L32="","",IF(L32>FechaConteo,1,0)*IF(I32="Supuesto",SupPY,IF(I32="Supuesto BR",SupBR,1))) -> 1 | O32: =IF(D32="","",IFERROR(INDEX(CostoOrigen,MATCH(D32,Origenes,0)),0)) -> 7.09 | P32: =IF(H32="","",H32*O32) -> 7146.72 | Q32: supuesto: 8 camiones BR los viernes, ritmo habitual (Gonzalo 28/09); se apaga en Parametros > SupBR | R32: =IF(B32="","",IF(J32<>"",J32,B32+IFERROR(INDEX(LagsP90,MATCH(D32,Origenes,0)),K32))) -> 46310 | S32: =IF(R32="","",R32-WEEKDAY(R32,2)+1) -> 46307 | T32: =IF(B32="","",IF(AND(B32<=FechaHoy,J32="",I32<>"Supuesto",I32<>"Simulado"),H32,0)) -> 0 | U32: =IF(J32="","",IF(J32-B32<=K32+1,1,0))
A33: =IF(B33="","",ROW()-4) -> 29 | B33: 46304 | C33: =IF(B33="","",TEXT(B33,"ddd")) -> vie | D33: BR | E33: Brasil (supuesto) | G33: 1008 | H33: =IF(B33="","",IF(G33<>"",G33,IFERROR(INDEX(CajasOrigen,MATCH(D33,Origenes,0)),CajasProm))) -> 1008 | I33: Supuesto BR | K33: =IF(B33="","",IFERROR(INDEX(Lags,MATCH(D33,Origenes,0)),LagBR)+IF(J33<>"",0,AtrasoDias)) -> 3 | L33: =IF(B33="","",IF(J33<>"",J33,B33+K33)) -> 46307 | M33: =IF(L33="","",L33-WEEKDAY(L33,2)+1) -> 46307 | N33: =IF(L33="","",IF(L33>FechaConteo,1,0)*IF(I33="Supuesto",SupPY,IF(I33="Supuesto BR",SupBR,1))) -> 1 | O33: =IF(D33="","",IFERROR(INDEX(CostoOrigen,MATCH(D33,Origenes,0)),0)) -> 7.09 | P33: =IF(H33="","",H33*O33) -> 7146.72 | Q33: supuesto: 8 camiones BR los viernes, ritmo habitual (Gonzalo 28/09); se apaga en Parametros > SupBR | R33: =IF(B33="","",IF(J33<>"",J33,B33+IFERROR(INDEX(LagsP90,MATCH(D33,Origenes,0)),K33))) -> 46310 | S33: =IF(R33="","",R33-WEEKDAY(R33,2)+1) -> 46307 | T33: =IF(B33="","",IF(AND(B33<=FechaHoy,J33="",I33<>"Supuesto",I33<>"Simulado"),H33,0)) -> 0 | U33: =IF(J33="","",IF(J33-B33<=K33+1,1,0))
A34: =IF(B34="","",ROW()-4) -> 30 | B34: 46304 | C34: =IF(B34="","",TEXT(B34,"ddd")) -> vie | D34: BR | E34: Brasil (supuesto) | G34: 1008 | H34: =IF(B34="","",IF(G34<>"",G34,IFERROR(INDEX(CajasOrigen,MATCH(D34,Origenes,0)),CajasProm))) -> 1008 | I34: Supuesto BR | K34: =IF(B34="","",IFERROR(INDEX(Lags,MATCH(D34,Origenes,0)),LagBR)+IF(J34<>"",0,AtrasoDias)) -> 3 | L34: =IF(B34="","",IF(J34<>"",J34,B34+K34)) -> 46307 | M34: =IF(L34="","",L34-WEEKDAY(L34,2)+1) -> 46307 | N34: =IF(L34="","",IF(L34>FechaConteo,1,0)*IF(I34="Supuesto",SupPY,IF(I34="Supuesto BR",SupBR,1))) -> 1 | O34: =IF(D34="","",IFERROR(INDEX(CostoOrigen,MATCH(D34,Origenes,0)),0)) -> 7.09 | P34: =IF(H34="","",H34*O34) -> 7146.72 | Q34: supuesto: 8 camiones BR los viernes, ritmo habitual (Gonzalo 28/09); se apaga en Parametros > SupBR | R34: =IF(B34="","",IF(J34<>"",J34,B34+IFERROR(INDEX(LagsP90,MATCH(D34,Origenes,0)),K34))) -> 46310 | S34: =IF(R34="","",R34-WEEKDAY(R34,2)+1) -> 46307 | T34: =IF(B34="","",IF(AND(B34<=FechaHoy,J34="",I34<>"Supuesto",I34<>"Simulado"),H34,0)) -> 0 | U34: =IF(J34="","",IF(J34-B34<=K34+1,1,0))
A35: =IF(B35="","",ROW()-4) -> 31 | B35: 46304 | C35: =IF(B35="","",TEXT(B35,"ddd")) -> vie | D35: BR | E35: Brasil (supuesto) | G35: 1008 | H35: =IF(B35="","",IF(G35<>"",G35,IFERROR(INDEX(CajasOrigen,MATCH(D35,Origenes,0)),CajasProm))) -> 1008 | I35: Supuesto BR | K35: =IF(B35="","",IFERROR(INDEX(Lags,MATCH(D35,Origenes,0)),LagBR)+IF(J35<>"",0,AtrasoDias)) -> 3 | L35: =IF(B35="","",IF(J35<>"",J35,B35+K35)) -> 46307 | M35: =IF(L35="","",L35-WEEKDAY(L35,2)+1) -> 46307 | N35: =IF(L35="","",IF(L35>FechaConteo,1,0)*IF(I35="Supuesto",SupPY,IF(I35="Supuesto BR",SupBR,1))) -> 1 | O35: =IF(D35="","",IFERROR(INDEX(CostoOrigen,MATCH(D35,Origenes,0)),0)) -> 7.09 | P35: =IF(H35="","",H35*O35) -> 7146.72 | Q35: supuesto: 8 camiones BR los viernes, ritmo habitual (Gonzalo 28/09); se apaga en Parametros > SupBR | R35: =IF(B35="","",IF(J35<>"",J35,B35+IFERROR(INDEX(LagsP90,MATCH(D35,Origenes,0)),K35))) -> 46310 | S35: =IF(R35="","",R35-WEEKDAY(R35,2)+1) -> 46307 | T35: =IF(B35="","",IF(AND(B35<=FechaHoy,J35="",I35<>"Supuesto",I35<>"Simulado"),H35,0)) -> 0 | U35: =IF(J35="","",IF(J35-B35<=K35+1,1,0))
A36: =IF(B36="","",ROW()-4) -> 32 | B36: 46304 | C36: =IF(B36="","",TEXT(B36,"ddd")) -> vie | D36: BR | E36: Brasil (supuesto) | G36: 1008 | H36: =IF(B36="","",IF(G36<>"",G36,IFERROR(INDEX(CajasOrigen,MATCH(D36,Origenes,0)),CajasProm))) -> 1008 | I36: Supuesto BR | K36: =IF(B36="","",IFERROR(INDEX(Lags,MATCH(D36,Origenes,0)),LagBR)+IF(J36<>"",0,AtrasoDias)) -> 3 | L36: =IF(B36="","",IF(J36<>"",J36,B36+K36)) -> 46307 | M36: =IF(L36="","",L36-WEEKDAY(L36,2)+1) -> 46307 | N36: =IF(L36="","",IF(L36>FechaConteo,1,0)*IF(I36="Supuesto",SupPY,IF(I36="Supuesto BR",SupBR,1))) -> 1 | O36: =IF(D36="","",IFERROR(INDEX(CostoOrigen,MATCH(D36,Origenes,0)),0)) -> 7.09 | P36: =IF(H36="","",H36*O36) -> 7146.72 | Q36: supuesto: 8 camiones BR los viernes, ritmo habitual (Gonzalo 28/09); se apaga en Parametros > SupBR | R36: =IF(B36="","",IF(J36<>"",J36,B36+IFERROR(INDEX(LagsP90,MATCH(D36,Origenes,0)),K36))) -> 46310 | S36: =IF(R36="","",R36-WEEKDAY(R36,2)+1) -> 46307 | T36: =IF(B36="","",IF(AND(B36<=FechaHoy,J36="",I36<>"Supuesto",I36<>"Simulado"),H36,0)) -> 0 | U36: =IF(J36="","",IF(J36-B36<=K36+1,1,0))
... A127: =IF(B127="","",ROW()-4) -> 123 | B127: 46374 | C127: =IF(B127="","",TEXT(B127,"ddd")) -> vie | D127: BR | E127: Brasil (supuesto) | G127: 1008 | H127: =IF(B127="","",IF(G127<>"",G127,IFERROR(INDEX(CajasOrigen,MATCH(D127,Origenes,0)),CajasProm))) -> 1008 | I127: Supuesto BR | K127: =IF(B127="","",IFERROR(INDEX(Lags,MATCH(D127,Origenes,0)),LagBR)+IF(J127<>"",0,AtrasoDias)) -> 3 | L127: =IF(B127="","",IF(J127<>"",J127,B127+K127)) -> 46377 | M127: =IF(L127="","",L127-WEEKDAY(L127,2)+1) -> 46377 | N127: =IF(L127="","",IF(L127>FechaConteo,1,0)*IF(I127="Supuesto",SupPY,IF(I127="Supuesto BR",SupBR,1))) -> 1 | O127: =IF(D127="","",IFERROR(INDEX(CostoOrigen,MATCH(D127,Origenes,0)),0)) -> 7.09 | P127: =IF(H127="","",H127*O127) -> 7146.72 | Q127: supuesto: 8 camiones BR los viernes, ritmo habitual (Gonzalo 28/09); se apaga en Parametros > SupBR | R127: =IF(B127="","",IF(J127<>"",J127,B127+IFERROR(INDEX(LagsP90,MATCH(D127,Origenes,0)),K127))) -> 46380 | S127: =IF(R127="","",R127-WEEKDAY(R127,2)+1) -> 46377 | T127: =IF(B127="","",IF(AND(B127<=FechaHoy,J127="",I127<>"Supuesto",I127<>"Simulado"),H127,0)) -> 0 | U127: =IF(J127="","",IF(J127-B127<=K127+1,1,0))
