Workbook
Name Fronteras: 'Rangos'!$G$5:$G$9
Name Productos: 'Rangos'!$I$5:$I$22
Name Status: 'Rangos'!$B$5:$B$28
Name Transporte: 'Rangos'!$D$5:$D$33

Sheet Cargas
B2: PROGRAMA DE ARRIBOS 2014
B3: PLAN ARRIBOS DESDE 2024
O4: Detalle/descripción presentaciòn producto
A5: Desc. Sem.# | B5: Status List | C5: Factura Export. | D5: Productos | E5: Fecha de Carga | F5: Carpeta Import. | G5: Pais origen | H5: AFIDI | I5: Transportista | J5: Exportador | K5: Fecha Frontera | L5: Frontera | M5: Fecha Descarga | N5: TT | O5: Cajas | P5: Cannt Camiones | Q5: Cajas Descargadas | R5: CANT. DE PALLET | S5: CANT.KILOS POR CAJAS | T5: MGAP | U5: MIC / CONTENEDOR | V5: CODIGO DE VIAJE | W5: PLACAS T | X5: Observaciones
A6: 50 | B6: Cancelado | C6: xx | D6: Banana | E6: 44553 | F6: =IF(C6<>"",VLOOKUP($C6,Carpetas!$C$5:$L$2060,2,FALSE),"") -> xx | G6: BO | H6: =IF(C6<>"",VLOOKUP($C6,Carpetas!$C$5:$L$2060,9,FALSE),"") -> xx | I6: =IF(C6<>"",VLOOKUP($C6,Carpetas!$C$5:$L$2060,5,FALSE),"") -> xx | K6: =E6+5 -> 44558 | L6: =VLOOKUP($C6,Carpetas!$C$5:$L$2060,4,FALSE) -> xx | M6: =K6+1 -> 44559 | N6: =IF(M6<>"",M6-E6,"-") -> 6 | O6: 1000
A7: 51 | B7: Cancelado | C7: xx | D7: Banana | E7: 44554 | F7: =IF(C7<>"",VLOOKUP($C7,Carpetas!$C$5:$L$2060,2,FALSE),"") -> xx | G7: BO | H7: =IF(C7<>"",VLOOKUP($C7,Carpetas!$C$5:$L$2060,9,FALSE),"") -> xx | I7: =IF(C7<>"",VLOOKUP($C7,Carpetas!$C$5:$L$2060,5,FALSE),"") -> xx | K7: =E7+5 -> 44559 | L7: =VLOOKUP($C7,Carpetas!$C$5:$L$2060,4,FALSE) -> xx | M7: =K7+1 -> 44560 | N7: =IF(M7<>"",M7-E7,"-") -> 6 | O7: 1000
A8: 50 | B8: Cancelado | C8: xx | D8: Banana | E8: 44555 | F8: =IF(C8<>"",VLOOKUP($C8,Carpetas!$C$5:$L$2060,2,FALSE),"") -> xx | G8: BO | H8: =IF(C8<>"",VLOOKUP($C8,Carpetas!$C$5:$L$2060,9,FALSE),"") -> xx | I8: =IF(C8<>"",VLOOKUP($C8,Carpetas!$C$5:$L$2060,5,FALSE),"") -> xx | K8: =E8+5 -> 44560 | L8: =VLOOKUP($C8,Carpetas!$C$5:$L$2060,4,FALSE) -> xx | M8: =K8+1 -> 44561 | N8: =IF(M8<>"",M8-E8,"-") -> 6 | O8: 1000
B9: Descargado | C9: 525/ | D9: Arandano | E9: 45307 | F9: =IF(C9<>"",VLOOKUP($C9,Carpetas!$C$5:$L$2060,2,FALSE),"") -> CLA001 | G9: CL | H9: =IF(C9<>"",VLOOKUP($C9,Carpetas!$C$5:$L$2060,9,FALSE),"") -> 0 | I9: =IF(C9<>"",VLOOKUP($C9,Carpetas!$C$5:$L$2060,5,FALSE),"") -> Nihuil | K9: 45310 | L9: =VLOOKUP($C9,Carpetas!$C$5:$L$2060,4,FALSE) -> Fray Bentos | M9: =K9+1 -> 45311 | N9: =IF(M9<>"",M9-E9,"-") -> 4 | O9: 2925
B10: Descargado | C10: 23/01229/ | D10: Kiwi | E10: 45273 | F10: =IF(C10<>"",VLOOKUP($C10,Carpetas!$C$5:$L$2060,2,FALSE),"") -> ITK009 | G10: IT | H10: =IF(C10<>"",VLOOKUP($C10,Carpetas!$C$5:$L$2060,9,FALSE),"") -> 0 | I10: =IF(C10<>"",VLOOKUP($C10,Carpetas!$C$5:$L$2060,5,FALSE),"") -> Ciatran | K10: 45314 | L10: =VLOOKUP($C10,Carpetas!$C$5:$L$2060,4,FALSE) -> Montevideo | M10: =K10+1 -> 45315 | N10: =IF(M10<>"",M10-E10,"-") -> 42 | O10: 2310
B11: Descargado | C11: FT3/163/ | D11: Kiwi | E11: 45276 | F11: =IF(C11<>"",VLOOKUP($C11,Carpetas!$C$5:$L$2060,2,FALSE),"") -> ITK010 | G11: IT | H11: =IF(C11<>"",VLOOKUP($C11,Carpetas!$C$5:$L$2060,9,FALSE),"") -> 0 | I11: =IF(C11<>"",VLOOKUP($C11,Carpetas!$C$5:$L$2060,5,FALSE),"") -> Ciatran | K11: 45314 | L11: =VLOOKUP($C11,Carpetas!$C$5:$L$2060,4,FALSE) -> Montevideo | M11: =K11+1 -> 45315 | N11: =IF(M11<>"",M11-E11,"-") -> 39 | O11: 2310 | Q11: 2310 | X11: SE DESCARGO EN RIQUEZA NATURAL KIWI CAL 33 630 CAJAS, KIWI CAL 30 896 CAJAS Y KIWI CAL 27 784 CAJAS EL DIA 27/1/2024
B12: Descargado | C12: 9480/ | D12: Piña | E12: 45300 | F12: =IF(C12<>"",VLOOKUP($C12,Carpetas!$C$5:$L$2060,2,FALSE),"") -> ECA002 | G12: EC | H12: =IF(C12<>"",VLOOKUP($C12,Carpetas!$C$5:$L$2060,9,FALSE),"") -> 1481832 | I12: =IF(C12<>"",VLOOKUP($C12,Carpetas!$C$5:$L$2060,5,FALSE),"") -> Andino | K12: 45318 | L12: =VLOOKUP($C12,Carpetas!$C$5:$L$2060,4,FALSE) -> Fray Bentos | M12: =K12+1 -> 45319 | N12: =IF(M12<>"",M12-E12,"-") -> 19 | O12: 1680
B13: Descargado | C13: 7683/ | D13: Banana | E13: 45300 | F13: =IF(C13<>"",VLOOKUP($C13,Carpetas!$C$5:$L$2060,2,FALSE),"") -> ECE001 | G13: EC | H13: =IF(C13<>"",VLOOKUP($C13,Carpetas!$C$5:$L$2060,9,FALSE),"") -> 148.18.43 | I13: =IF(C13<>"",VLOOKUP($C13,Carpetas!$C$5:$L$2060,5,FALSE),"") -> Andino | K13: 45320 | L13: =VLOOKUP($C13,Carpetas!$C$5:$L$2060,4,FALSE) -> Fray Bentos | M13: 45320 | N13: =IF(M13<>"",M13-E13,"-") -> 20 | O13: 2192 | Q13: 2192 | W13: KCTC64//PYCJ21 | X13: MM 30/01 : DESCARGADO EN RIQUEZA NATURAL 2052 CAJAS DE BANANA BAGNO Y 140 CAJAS DE PLATANO BAGNO.
B14: Descargado | C14: 54065/ | D14: Palta | E14: 45315 | F14: =IF(C14<>"",VLOOKUP($C14,Carpetas!$C$5:$L$2060,2,FALSE),"") -> CLP001 | G14: EC | H14: =IF(C14<>"",VLOOKUP($C14,Carpetas!$C$5:$L$2060,9,FALSE),"") -> 148.30.99 | I14: =IF(C14<>"",VLOOKUP($C14,Carpetas!$C$5:$L$2060,5,FALSE),"") -> Nihuil | K14: 45320 | L14: =VLOOKUP($C14,Carpetas!$C$5:$L$2060,4,FALSE) -> Fray Bentos | M14: =K14+1 -> 45321 | N14: =IF(M14<>"",M14-E14,"-") -> 6 | O14: 2112
B15: Descargado | C15: 7674/ | D15: Banana | E15: 45307 | F15: =IF(C15<>"",VLOOKUP($C15,Carpetas!$C$5:$L$2060,2,FALSE),"") -> ECE002 | G15: EC | H15: =IF(C15<>"",VLOOKUP($C15,Carpetas!$C$5:$L$2060,9,FALSE),"") -> 148.18.43 | I15: =IF(C15<>"",VLOOKUP($C15,Carpetas!$C$5:$L$2060,5,FALSE),"") -> Andino | K15: 45324 | L15: =VLOOKUP($C15,Carpetas!$C$5:$L$2060,4,FALSE) -> Fray Bentos | M15: =K15+1 -> 45325 | N15: =IF(M15<>"",M15-E15,"-") -> 18 | O15: 3239 | Q15: 2159 | X15: AL: SE DESCARGARON EN RIQUEZA NATURAL 2159 CAJAS DE BAGNO.
B16: Descargado | C16: 7681/ | D16: Banana | E16: 45307 | F16: =IF(C16<>"",VLOOKUP($C16,Carpetas!$C$5:$L$2060,2,FALSE),"") -> ECE003 | G16: EC | H16: =IF(C16<>"",VLOOKUP($C16,Carpetas!$C$5:$L$2060,9,FALSE),"") -> 148.18.43 | I16: =IF(C16<>"",VLOOKUP($C16,Carpetas!$C$5:$L$2060,5,FALSE),"") -> Andino | K16: 45324 | L16: =VLOOKUP($C16,Carpetas!$C$5:$L$2060,4,FALSE) -> Fray Bentos | M16: =K16+1 -> 45325 | N16: =IF(M16<>"",M16-E16,"-") -> 18 | O16: 1112 | Q16: 1128 | X16: AL: SEDESCARGARON EN RIQUEZA NATURAL_: 918 CAJAS DE BANANA BAGNO, 210 CAJAS DE PLATANO,
B17: Descargado | C17: 9500/ | D17: Piña | E17: 45307 | F17: =IF(C17<>"",VLOOKUP($C17,Carpetas!$C$5:$L$2060,2,FALSE),"") -> ECA003 | G17: EC | H17: =IF(C17<>"",VLOOKUP($C17,Carpetas!$C$5:$L$2060,9,FALSE),"") -> 1482156 | I17: =IF(C17<>"",VLOOKUP($C17,Carpetas!$C$5:$L$2060,5,FALSE),"") -> Andino | K17: 45324 | L17: =VLOOKUP($C17,Carpetas!$C$5:$L$2060,4,FALSE) -> Fray Bentos | M17: =K17+1 -> 45325 | N17: =IF(M17<>"",M17-E17,"-") -> 18 | O17: 1680
B18: Descargado | C18: 10557/ | D18: Banana | E18: 45314 | F18: =IF(C18<>"",VLOOKUP($C18,Carpetas!$C$5:$L$2060,2,FALSE),"") -> ECB001 | G18: EC | H18: =IF(C18<>"",VLOOKUP($C18,Carpetas!$C$5:$L$2060,9,FALSE),"") -> 1482155 | I18: =IF(C18<>"",VLOOKUP($C18,Carpetas!$C$5:$L$2060,5,FALSE),"") -> Andino | K18: 45330 | L18: =VLOOKUP($C18,Carpetas!$C$5:$L$2060,4,FALSE) -> Fray Bentos | M18: =K18+1 -> 45331 | N18: =IF(M18<>"",M18-E18,"-") -> 17 | O18: 2160 | Q18: 2160 | V18: BONITA | W18: RBXC26 | X18: SE DESCARGARON EN RIQUEZA NATURAL 2160 CAJA DE BANANA BONITA
B19: Descargado | C19: 9529/ | D19: Piña | E19: 45314 | F19: =IF(C19<>"",VLOOKUP($C19,Carpetas!$C$5:$L$2060,2,FALSE),"") -> ECA004 | G19: EC | H19: =IF(C19<>"",VLOOKUP($C19,Carpetas!$C$5:$L$2060,9,FALSE),"") -> 1482164 | I19: =IF(C19<>"",VLOOKUP($C19,Carpetas!$C$5:$L$2060,5,FALSE),"") -> Andino | K19: 45330 | L19: =VLOOKUP($C19,Carpetas!$C$5:$L$2060,4,FALSE) -> Fray Bentos | M19: =K19+1 -> 45331 | N19: =IF(M19<>"",M19-E19,"-") -> 17 | O19: 1680
B20: Descargado | C20: 7694/ | D20: Banana | E20: 45314 | F20: =IF(C20<>"",VLOOKUP($C20,Carpetas!$C$5:$L$2060,2,FALSE),"") -> ECE004 | G20: EC | H20: =IF(C20<>"",VLOOKUP($C20,Carpetas!$C$5:$L$2060,9,FALSE),"") -> 1482615 | I20: =IF(C20<>"",VLOOKUP($C20,Carpetas!$C$5:$L$2060,5,FALSE),"") -> Andino | K20: 45331 | L20: =VLOOKUP($C20,Carpetas!$C$5:$L$2060,4,FALSE) -> Fray Bentos | M20: =K20+1 -> 45332 | N20: =IF(M20<>"",M20-E20,"-") -> 18 | O20: 5400 | Q20: 5400 | V20: BAGNO | W20: LJV47/KKWF65/PYCJ21/PJJR55 | X20: SE DESCARGARON EN RIQUEZA NATURAL 5400 CAJAS DE BANANA EC BAGNO.
B21: Descargado | C21: 7695/ | D21: Banana | E21: 45314 | F21: =IF(C21<>"",VLOOKUP($C21,Carpetas!$C$5:$L$2060,2,FALSE),"") -> ECE005 | G21: EC | H21: =IF(C21<>"",VLOOKUP($C21,Carpetas!$C$5:$L$2060,9,FALSE),"") -> 1482616 | I21: =IF(C21<>"",VLOOKUP($C21,Carpetas!$C$5:$L$2060,5,FALSE),"") -> Andino | K21: 45331 | L21: =VLOOKUP($C21,Carpetas!$C$5:$L$2060,4,FALSE) -> Fray Bentos | M21: =K21+1 -> 45332 | N21: =IF(M21<>"",M21-E21,"-") -> 18 | O21: 1112 | Q21: 1112 | V21: BAGNO | W21: PLFP86 | X21: SE DESCARGARON EN RIQUEZA NATURAL 972 CAJA DE BANANA BONITA, Y 140 DE PLATANO.
B22: Descargado | C22: 10634/ | D22: Banana | E22: 45321 | F22: =IF(C22<>"",VLOOKUP($C22,Carpetas!$C$5:$L$2060,2,FALSE),"") -> ECB002 | G22: EC | H22: =IF(C22<>"",VLOOKUP($C22,Carpetas!$C$5:$L$2060,9,FALSE),"") -> 1483128 | I22: =IF(C22<>"",VLOOKUP($C22,Carpetas!$C$5:$L$2060,5,FALSE),"") -> Andino | K22: 45336 | L22: =VLOOKUP($C22,Carpetas!$C$5:$L$2060,4,FALSE) -> Fray Bentos | M22: =K22+1 -> 45337 | N22: =IF(M22<>"",M22-E22,"-") -> 16 | O22: 2160 | Q22: 2160 | V22: BONITA | W22: RBXC27 | X22: 15/02: Se descargaron en Riqueza natural 2160 cajas de banana ecuador Bonita.
B23: Descargado | C23: 7703/ | D23: Banana | E23: 45321 | F23: =IF(C23<>"",VLOOKUP($C23,Carpetas!$C$5:$L$2060,2,FALSE),"") -> ECE006 | G23: EC | H23: =IF(C23<>"",VLOOKUP($C23,Carpetas!$C$5:$L$2060,9,FALSE),"") -> 1483125 | I23: =IF(C23<>"",VLOOKUP($C23,Carpetas!$C$5:$L$2060,5,FALSE),"") -> Andino | K23: 45336 | L23: =VLOOKUP($C23,Carpetas!$C$5:$L$2060,4,FALSE) -> Fray Bentos | M23: =K23+1 -> 45337 | N23: =IF(M23<>"",M23-E23,"-") -> 16 | O23: 3240 | Q23: 3240 | V23: BAGNO | W23: PYCJ24 / KFPF34/PJJR58 | X23: 15/02: Se descargaron en Riqueza natural 3240 cajas de banana ecuador BAGNO.
B24: Descargado | C24: 7704/ | D24: Banana | E24: 45321 | F24: =IF(C24<>"",VLOOKUP($C24,Carpetas!$C$5:$L$2060,2,FALSE),"") -> ECE007 | G24: EC | H24: =IF(C24<>"",VLOOKUP($C24,Carpetas!$C$5:$L$2060,9,FALSE),"") -> 1483127 | I24: =IF(C24<>"",VLOOKUP($C24,Carpetas!$C$5:$L$2060,5,FALSE),"") -> Andino | K24: 45336 | L24: =VLOOKUP($C24,Carpetas!$C$5:$L$2060,4,FALSE) -> Fray Bentos | M24: =K24+1 -> 45337 | N24: =IF(M24<>"",M24-E24,"-") -> 16 | O24: 1144 | Q24: 1144 | V24: bagno-platano | W24: kctc65 | X24: se descargo en riqueza natural 864 cajas de bagno y 280 cajas de platano el dia 15/2/2024
B25: Descargado | C25: 529/ | D25: Arandano | E25: 45334 | F25: =IF(C25<>"",VLOOKUP($C25,Carpetas!$C$5:$L$2060,2,FALSE),"") -> CLA002 | G25: CL | H25: =IF(C25<>"",VLOOKUP($C25,Carpetas!$C$5:$L$2060,9,FALSE),"") -> 0 | I25: =IF(C25<>"",VLOOKUP($C25,Carpetas!$C$5:$L$2060,5,FALSE),"") -> Nihuil | K25: =E25+4 -> 45338 | L25: =VLOOKUP($C25,Carpetas!$C$5:$L$2060,4,FALSE) -> Fray Bentos | M25: =K25+1 -> 45339 | N25: =IF(M25<>"",M25-E25,"-") -> 5 | O25: =990+6270 -> 7260
B26: Descargado | C26: 96326/ | D26: Palta | E26: 45314 | F26: =IF(C26<>"",VLOOKUP($C26,Carpetas!$C$5:$L$2060,2,FALSE),"") -> MXP001 | G26: MX | H26: =IF(C26<>"",VLOOKUP($C26,Carpetas!$C$5:$L$2060,9,FALSE),"") -> 0 | I26: =IF(C26<>"",VLOOKUP($C26,Carpetas!$C$5:$L$2060,5,FALSE),"") -> Andino | K26: 45340 | L26: =VLOOKUP($C26,Carpetas!$C$5:$L$2060,4,FALSE) -> Fray Bentos | M26: 45341 | N26: =IF(M26<>"",M26-E26,"-") -> 27 | O26: 1920 | Q26: 1920 | X26: SE DESCARGO EN RIQUEZA NATURAL 1920 CAJAS DE PALTA CAL 60 EL DIA 19/2/2024
B27: Descargado | C27: 96325/ | D27: Palta | E27: 45314 | F27: =IF(C27<>"",VLOOKUP($C27,Carpetas!$C$5:$L$2060,2,FALSE),"") -> MXP002 | G27: MX | H27: =IF(C27<>"",VLOOKUP($C27,Carpetas!$C$5:$L$2060,9,FALSE),"") -> 0 | I27: =IF(C27<>"",VLOOKUP($C27,Carpetas!$C$5:$L$2060,5,FALSE),"") -> Andino | K27: 45340 | L27: =VLOOKUP($C27,Carpetas!$C$5:$L$2060,4,FALSE) -> Fray Bentos | M27: 45341 | N27: =IF(M27<>"",M27-E27,"-") -> 27 | O27: 1920 | Q27: 1920 | X27: se descargo en riqueza natural 1920 cajas de palta 84 malla el dia 20/2/2024
B28: Descargado | C28: 7714/ | D28: Banana | E28: 45328 | F28: =IF(C28<>"",VLOOKUP($C28,Carpetas!$C$5:$L$2060,2,FALSE),"") -> ECE008 | G28: EC | H28: =IF(C28<>"",VLOOKUP($C28,Carpetas!$C$5:$L$2060,9,FALSE),"") -> 1483563 | I28: =IF(C28<>"",VLOOKUP($C28,Carpetas!$C$5:$L$2060,5,FALSE),"") -> Andino | K28: 45342 | L28: =VLOOKUP($C28,Carpetas!$C$5:$L$2060,4,FALSE) -> Fray Bentos | M28: =K28+1 -> 45343 | N28: =IF(M28<>"",M28-E28,"-") -> 15 | O28: 3240 | Q28: 3240 | V28: BAGNO | W28: PYCJ24/RBXC27/RBXC26/ | X28: SE DESCARGO EN RIQUEZA NATURAL 3240 CAJAS DE BAGNO EL DIA 21/2/2024
B29: Descargado | C29: 7715/ | D29: Banana | E29: 45328 | F29: =IF(C29<>"",VLOOKUP($C29,Carpetas!$C$5:$L$2060,2,FALSE),"") -> ECE009 | G29: EC | H29: =IF(C29<>"",VLOOKUP($C29,Carpetas!$C$5:$L$2060,9,FALSE),"") -> 1483858 | I29: =IF(C29<>"",VLOOKUP($C29,Carpetas!$C$5:$L$2060,5,FALSE),"") -> Andino | K29: 45342 | L29: =VLOOKUP($C29,Carpetas!$C$5:$L$2060,4,FALSE) -> Fray Bentos | M29: =K29+1 -> 45343 | N29: =IF(M29<>"",M29-E29,"-") -> 15 | O29: 2160 | Q29: 2160 | V29: BAGNO | W29: KKWF65/KFPF36 | X29: SE DESCARGO EN RIQUEZA NATURAL 2160 CAJAS DE BAGNO EL DIA 21/2/2024
B30: Descargado | C30: 10672/ | D30: Banana | E30: 45328 | F30: =IF(C30<>"",VLOOKUP($C30,Carpetas!$C$5:$L$2060,2,FALSE),"") -> ECB003 | G30: EC | H30: =IF(C30<>"",VLOOKUP($C30,Carpetas!$C$5:$L$2060,9,FALSE),"") -> 1483708 | I30: =IF(C30<>"",VLOOKUP($C30,Carpetas!$C$5:$L$2060,5,FALSE),"") -> Andino | K30: 45346 | L30: =VLOOKUP($C30,Carpetas!$C$5:$L$2060,4,FALSE) -> Fray Bentos | M30: =K30+1 -> 45347 | N30: =IF(M30<>"",M30-E30,"-") -> 19 | O30: 2160 | Q30: 2160 | V30: BONITA | W30: PYCJ22 / KFPF34 | X30: SE DESCARGO EN RIQUEZA NATURAL 2160CAJAS DE BONITA EL DIA 24/4/2024 Y 26/2/2024
B31: Descargado | C31: 96651/ | D31: Palta | E31: 45322 | F31: =IF(C31<>"",VLOOKUP($C31,Carpetas!$C$5:$L$2060,2,FALSE),"") -> MXP003 | G31: MX | H31: =IF(C31<>"",VLOOKUP($C31,Carpetas!$C$5:$L$2060,9,FALSE),"") -> 0 | I31: =IF(C31<>"",VLOOKUP($C31,Carpetas!$C$5:$L$2060,5,FALSE),"") -> Andino | K31: 45349 | L31: =VLOOKUP($C31,Carpetas!$C$5:$L$2060,4,FALSE) -> Fray Bentos | M31: =K31+1 -> 45350 | N31: =IF(M31<>"",M31-E31,"-") -> 28 | O31: 1920 | Q31: 1920 | V31: EXOTICO | W31: KKWF66 | X31: SE DESCARGO ENR IQUEZA NATURAL 1920 CAJAS DE PALTA CAL 84 MALLA EL DIA 28/2/2024
B32: Descargado | C32: 96650/ | D32: Palta | E32: 45322 | F32: =IF(C32<>"",VLOOKUP($C32,Carpetas!$C$5:$L$2060,2,FALSE),"") -> MXP004 | G32: MX | H32: =IF(C32<>"",VLOOKUP($C32,Carpetas!$C$5:$L$2060,9,FALSE),"") -> 0 | I32: =IF(C32<>"",VLOOKUP($C32,Carpetas!$C$5:$L$2060,5,FALSE),"") -> Andino | K32: 45349 | L32: =VLOOKUP($C32,Carpetas!$C$5:$L$2060,4,FALSE) -> Fray Bentos | M32: =K32+1 -> 45350 | N32: =IF(M32<>"",M32-E32,"-") -> 28 | O32: 1920 | Q32: 1920 | V32: EXOTICO | W32: KCTC65 | X32: SE DESCARGO ENR IQUEZA NATURAL 1920 CAJAS DE PALTA CAL 60 EL DIA 28/2/2024
B33: Descargado | C33: 9584/ | D33: Piña | E33: 45333 | F33: =IF(C33<>"",VLOOKUP($C33,Carpetas!$C$5:$L$2060,2,FALSE),"") -> ECA005 | G33: EC | H33: =IF(C33<>"",VLOOKUP($C33,Carpetas!$C$5:$L$2060,9,FALSE),"") -> 1484118 | I33: =IF(C33<>"",VLOOKUP($C33,Carpetas!$C$5:$L$2060,5,FALSE),"") -> Andino | K33: 45349 | L33: =VLOOKUP($C33,Carpetas!$C$5:$L$2060,4,FALSE) -> Fray Bentos | M33: =K33+1 -> 45350 | N33: =IF(M33<>"",M33-E33,"-") -> 17 | O33: 1680
B34: Descargado | C34: 10685/ | D34: Banana | E34: 45333 | F34: =IF(C34<>"",VLOOKUP($C34,Carpetas!$C$5:$L$2060,2,FALSE),"") -> ECB004 | G34: EC | H34: =IF(C34<>"",VLOOKUP($C34,Carpetas!$C$5:$L$2060,9,FALSE),"") -> 1484050 | I34: =IF(C34<>"",VLOOKUP($C34,Carpetas!$C$5:$L$2060,5,FALSE),"") -> Andino | K34: 45350 | L34: =VLOOKUP($C34,Carpetas!$C$5:$L$2060,4,FALSE) -> Fray Bentos | M34: =K34+1 -> 45351 | N34: =IF(M34<>"",M34-E34,"-") -> 18 | O34: 1080 | Q34: 1080 | V34: BONITA | W34: PYCJ19 | X34: SE DESCARGO EN RIQUEZA NATURAL 1080 CAJAS DE BONITA EL DIA 29/2/2024
B35: Descargado | C35: 7724/ | D35: Banana | E35: 45333 | F35: =IF(C35<>"",VLOOKUP($C35,Carpetas!$C$5:$L$2060,2,FALSE),"") -> ECE010 | G35: EC | H35: =IF(C35<>"",VLOOKUP($C35,Carpetas!$C$5:$L$2060,9,FALSE),"") -> 1484015 | I35: =IF(C35<>"",VLOOKUP($C35,Carpetas!$C$5:$L$2060,5,FALSE),"") -> Andino | K35: 45350 | L35: =VLOOKUP($C35,Carpetas!$C$5:$L$2060,4,FALSE) -> Fray Bentos | M35: =K35+1 -> 45351 | N35: =IF(M35<>"",M35-E35,"-") -> 18 | O35: 1080 | Q35: 1080 | V35: BAGNO | W35: RBXC27 / JC2408 | X35: 29/02: SE RECIBIERON EN RIQUEZA NATURAL 1080 CAJAS DE BANANA BAGNO.
B36: Descargado | C36: 7724/ | D36: Banana | E36: 45333 | F36: =IF(C36<>"",VLOOKUP($C36,Carpetas!$C$5:$L$2060,2,FALSE),"") -> ECE010 | G36: EC | H36: =IF(C36<>"",VLOOKUP($C36,Carpetas!$C$5:$L$2060,9,FALSE),"") -> 1484015 | I36: =IF(C36<>"",VLOOKUP($C36,Carpetas!$C$5:$L$2060,5,FALSE),"") -> Andino | K36: 45350 | L36: =VLOOKUP($C36,Carpetas!$C$5:$L$2060,4,FALSE) -> Fray Bentos | M36: =K36+1 -> 45351 | N36: =IF(M36<>"",M36-E36,"-") -> 18 | O36: 1080 | Q36: 1080 | V36: BAGNO | W36: KFPF36 | X36: SE DESCARGO EN RIQUEZA NATURAL 1080 CAJAS DE BAGNO EL DIA 29/2/2024
B37: Descargado | C37: 7725/ | D37: Banana | E37: 45333 | F37: =IF(C37<>"",VLOOKUP($C37,Carpetas!$C$5:$L$2060,2,FALSE),"") -> ECE011 | G37: EC | H37: =IF(C37<>"",VLOOKUP($C37,Carpetas!$C$5:$L$2060,9,FALSE),"") -> 1484016 | I37: =IF(C37<>"",VLOOKUP($C37,Carpetas!$C$5:$L$2060,5,FALSE),"") -> Andino | K37: 45350 | L37: =VLOOKUP($C37,Carpetas!$C$5:$L$2060,4,FALSE) -> Fray Bentos | M37: =K37+1 -> 45351 | N37: =IF(M37<>"",M37-E37,"-") -> 18 | O37: 1144 | Q37: 1144 | V37: RBXC26 | X37: SE DESCARGO EN RIQUEZA NATURAL 280 CAJAS DE PLATANO Y 864 CAJAS DE BAGNO EL DIA 29/2/2024
B38: Descargado | C38: 7724/ | D38: Banana | E38: 45333 | F38: =IF(C38<>"",VLOOKUP($C38,Carpetas!$C$5:$L$2060,2,FALSE),"") -> ECE010 | G38: EC | H38: =IF(C38<>"",VLOOKUP($C38,Carpetas!$C$5:$L$2060,9,FALSE),"") -> 1484015 | I38: =IF(C38<>"",VLOOKUP($C38,Carpetas!$C$5:$L$2060,5,FALSE),"") -> Andino | K38: 45351 | L38: =VLOOKUP($C38,Carpetas!$C$5:$L$2060,4,FALSE) -> Fray Bentos | M38: =K38+1 -> 45352 | N38: =IF(M38<>"",M38-E38,"-") -> 19 | O38: 1080 | Q38: 1080 | V38: BAGNO | W38: PJJR58 | X38: SE DESCARGO EN RIQUEZA NATURAL 1080 CAJAS DE BAGNO EL DIA 01/3/2024
B39: Descargado | C39: 10685/ | D39: Banana | E39: 45333 | F39: =IF(C39<>"",VLOOKUP($C39,Carpetas!$C$5:$L$2060,2,FALSE),"") -> ECB004 | G39: EC | H39: =IF(C39<>"",VLOOKUP($C39,Carpetas!$C$5:$L$2060,9,FALSE),"") -> 1484050 | I39: =IF(C39<>"",VLOOKUP($C39,Carpetas!$C$5:$L$2060,5,FALSE),"") -> Andino | K39: 45351 | L39: =VLOOKUP($C39,Carpetas!$C$5:$L$2060,4,FALSE) -> Fray Bentos | M39: =K39+1 -> 45352 | N39: =IF(M39<>"",M39-E39,"-") -> 19 | O39: 1080 | Q39: 1080 | V39: BONITA | W39: PYCJ24 | X39: SE DESCARGO EN RIQUEZA NATURAL 1080 CAJAS DE BONITA EL DIA 01/3/2024
B40: Descargado | C40: 10685/ | D40: Banana | E40: 45333 | F40: =IF(C40<>"",VLOOKUP($C40,Carpetas!$C$5:$L$2060,2,FALSE),"") -> ECB004 | G40: EC | H40: =IF(C40<>"",VLOOKUP($C40,Carpetas!$C$5:$L$2060,9,FALSE),"") -> 1484050 | I40: =IF(C40<>"",VLOOKUP($C40,Carpetas!$C$5:$L$2060,5,FALSE),"") -> Andino | K40: 45351 | L40: =VLOOKUP($C40,Carpetas!$C$5:$L$2060,4,FALSE) -> Fray Bentos | M40: =K40+1 -> 45352 | N40: =IF(M40<>"",M40-E40,"-") -> 19 | O40: 1080 | Q40: 1080 | V40: BONITA | W40: KFPF33 | X40: SE DESCARGO EN RIQUEZA NATURAL 1080 CAJAS DE BONITA EL DIA 01/3/2024
B41: Descargado | C41: 54169/ | D41: Palta | E41: 45350 | F41: =IF(C41<>"",VLOOKUP($C41,Carpetas!$C$5:$L$2060,2,FALSE),"") -> CLP002 | G41: CL | H41: =IF(C41<>"",VLOOKUP($C41,Carpetas!$C$5:$L$2060,9,FALSE),"") -> 148.30.99 | I41: =IF(C41<>"",VLOOKUP($C41,Carpetas!$C$5:$L$2060,5,FALSE),"") -> Nihuil | K41: 45355 | L41: =VLOOKUP($C41,Carpetas!$C$5:$L$2060,4,FALSE) -> Fray Bentos | M41: =K41+1 -> 45356 | N41: =IF(M41<>"",M41-E41,"-") -> 6 | O41: 2112 | Q41: 2112 | W41: RKHT85/PWYZ75 | X41: 05/03: SE DESCARGARON EN RIQUEZA NATURAL 1936 CAJAS DE PALTA PROPAL CAL. 60 Y 176 DE CAL. 84.
...

Sheet Carpetas
B2: CARPETAS DE IMPORTACIÓN - CONTROL DE CARGAS y SALDOS
B4: Fecha | C4: Fatura | D4: Carpeta | E4: Export | F4: Frontera | G4: Transp. | H4: Qtde | I4: Cargado | J4: Saldo | K4: Afidi | L4: DUA
B5: 43070 | C5: xx | D5: xx | E5: xx | F5: xx | G5: xx | H5: 1000000 | I5: =SUMIF(Cargas!$C$6:$C$1064,C5,Cargas!$O$6:$O$1064) -> 8920 | J5: =IF(ABS(H5-I5)<20,0,H5-I5) -> 991080 | K5: xx | L5: xx
B6: 43467 | C6: 2062/ | D6: ECE001 | E6: Exporsweet | F6: Montevideo | G6: Ciatran | H6: 4320 | I6: =SUMIF(Cargas!$C$6:$C$1064,C6,Cargas!$O$6:$O$1064) -> 0 | J6: =IF(ABS(H6-I6)<20,0,H6-I6) -> 4320 | K6: 1340207 | L6: 20347
B7: 43469 | C7: 3461/ | D7: ECA001 | E7: Agroeden | F7: Fray Bentos | G7: Andino | H7: 1680 | I7: =SUMIF(Cargas!$C$6:$C$1064,C7,Cargas!$O$6:$O$1064) -> 0 | J7: =IF(ABS(H7-I7)<20,0,H7-I7) -> 1680 | K7: 1340204 | L7: 11187
B8: 43469 | C8: 5/8/ | D8: ITK001 | E8: RK | F8: Montevideo | G8: Ciatran | H8: 2310 | I8: =SUMIF(Cargas!$C$6:$C$1064,C8,Cargas!$O$6:$O$1064) -> 0 | J8: =IF(ABS(H8-I8)<20,0,H8-I8) -> 2310 | K8: 1339959 | L8: 20998
B9: 43470 | C9: 4679/ | D9: ECR001 | E9: Truisfruit | F9: Fray Bentos | G9: Andino | H9: =1050*3 -> 3150 | I9: =SUMIF(Cargas!$C$6:$C$1064,C9,Cargas!$O$6:$O$1064) -> 0 | J9: =IF(ABS(H9-I9)<20,0,H9-I9) -> 3150 | K9: 1340205 | L9: 11029
B10: 43471 | C10: 4685/ | D10: ECB001 | E10: Truisfruit | F10: Montevideo | G10: Ciatran | H10: 3240 | I10: =SUMIF(Cargas!$C$6:$C$1064,C10,Cargas!$O$6:$O$1064) -> 0 | J10: =IF(ABS(H10-I10)<20,0,H10-I10) -> 3240 | K10: 1340206 | L10: 24801
B11: 43474 | C11: 2111/ | D11: ECE002 | E11: Exporsweet | F11: Montevideo | G11: Ciatran | H11: 4320 | I11: =SUMIF(Cargas!$C$6:$C$1064,C11,Cargas!$O$6:$O$1064) -> 0 | J11: =IF(ABS(H11-I11)<20,0,H11-I11) -> 4320 | K11: 1340380 | L11: 24807
B12: 43476 | C12: 2121/ | D12: ECE003 | E12: Exporsweet | F12: Montevideo | G12: Ciatran | H12: 4320 | I12: =SUMIF(Cargas!$C$6:$C$1064,C12,Cargas!$O$6:$O$1064) -> 0 | J12: =IF(ABS(H12-I12)<20,0,H12-I12) -> 4320 | K12: 1340597 | L12: 15575
B13: 43476 | C13: 4681/ | D13: ECR002 | E13: Truisfruit | F13: Fray Bentos | G13: Andino | H13: =1050*3 -> 3150 | I13: =SUMIF(Cargas!$C$6:$C$1064,C13,Cargas!$O$6:$O$1064) -> 0 | J13: =IF(ABS(H13-I13)<20,0,H13-I13) -> 3150 | K13: 1340379 | L13: 13790
B14: 43478 | C14: 4686/ | D14: ECB002 | E14: Truisfruit | F14: Montevideo | G14: Ciatran | H14: 3240 | I14: =SUMIF(Cargas!$C$6:$C$1064,C14,Cargas!$O$6:$O$1064) -> 0 | J14: =IF(ABS(H14-I14)<20,0,H14-I14) -> 3240 | K14: 1340378 | L14: 24806
B15: 43481 | C15: 2154/ | D15: ECE004 | E15: Exporsweet | F15: Montevideo | G15: Ciatran | H15: 4320 | I15: =SUMIF(Cargas!$C$6:$C$1064,C15,Cargas!$O$6:$O$1064) -> 0 | J15: =IF(ABS(H15-I15)<20,0,H15-I15) -> 4320 | K15: 1340797 | L15: 32387
B16: 43483 | C16: 3517/ | D16: ECA002 | E16: Agroeden | F16: Fray Bentos | G16: Andino | H16: 1680 | I16: =SUMIF(Cargas!$C$6:$C$1064,C16,Cargas!$O$6:$O$1064) -> 0 | J16: =IF(ABS(H16-I16)<20,0,H16-I16) -> 1680 | K16: 1340798 | L16: 18364
B17: 43483 | C17: 4709/ | D17: ECR003 | E17: Truisfruit | F17: Fray Bentos | G17: Andino | H17: =1050*3 -> 3150 | I17: =SUMIF(Cargas!$C$6:$C$1064,C17,Cargas!$O$6:$O$1064) -> 0 | J17: =IF(ABS(H17-I17)<20,0,H17-I17) -> 3150 | K17: 1340795 | L17: 18328
B18: 43485 | C18: 4710/ | D18: ECB003 | E18: Truisfruit | F18: Montevideo | G18: Ciatran | H18: 3240 | I18: =SUMIF(Cargas!$C$6:$C$1064,C18,Cargas!$O$6:$O$1064) -> 0 | J18: =IF(ABS(H18-I18)<20,0,H18-I18) -> 3240 | K18: 1340796 | L18: 32469
B19: 43487 | C19: 33/8 | D19: ITK002 | E19: RK | F19: Montevideo | G19: Ciatran | H19: 2310 | I19: =SUMIF(Cargas!$C$6:$C$1064,C19,Cargas!$O$6:$O$1064) -> 0 | J19: =IF(ABS(H19-I19)<20,0,H19-I19) -> 2310 | K19: 1341046 | L19: 30805
B20: 43488 | C20: 2192/ | D20: ECE005 | E20: Exporsweet | F20: Montevideo | G20: Ciatran | H20: 4320 | I20: =SUMIF(Cargas!$C$6:$C$1064,C20,Cargas!$O$6:$O$1064) -> 0 | J20: =IF(ABS(H20-I20)<20,0,H20-I20) -> 4320 | K20: 1341132 | L20: 32564
B21: 43489 | C21: 188/ | D21: CLP001 | E21: Fruchac | F21: Fray Bentos | G21: Nihuil | H21: 2392 | I21: =SUMIF(Cargas!$C$6:$C$1064,C21,Cargas!$O$6:$O$1064) -> 0 | J21: =IF(ABS(H21-I21)<20,0,H21-I21) -> 2392 | K21: 1341457 | L21: 15522
B22: 43491 | C22: 4729/ | D22: ECR004 | E22: Truisfruit | F22: Fray Bentos | G22: Andino | H22: =1050*3 -> 3150 | I22: =SUMIF(Cargas!$C$6:$C$1064,C22,Cargas!$O$6:$O$1064) -> 0 | J22: =IF(ABS(H22-I22)<20,0,H22-I22) -> 3150 | K22: 1341130 | L22: 22607
B23: 43491 | C23: 4750/ | D23: ECR005 | E23: Truisfruit | F23: Fray Bentos | G23: Andino | H23: =1050*3 -> 3150 | I23: =SUMIF(Cargas!$C$6:$C$1064,C23,Cargas!$O$6:$O$1064) -> 0 | J23: =IF(ABS(H23-I23)<20,0,H23-I23) -> 3150 | K23: 1341639 | L23: 27591
B24: 43492 | C24: 4730/ | D24: ECB004 | E24: Truisfruit | F24: Montevideo | G24: Ciatran | H24: 3240 | I24: =SUMIF(Cargas!$C$6:$C$1064,C24,Cargas!$O$6:$O$1064) -> 0 | J24: =IF(ABS(H24-I24)<20,0,H24-I24) -> 3240 | K24: 1341131 | L24: 32638
B25: 43495 | C25: 2229/ | D25: ECE006 | E25: Exporsweet | F25: Montevideo | G25: Ciatran | H25: 4320 | I25: =SUMIF(Cargas!$C$6:$C$1064,C25,Cargas!$O$6:$O$1064) -> 0 | J25: =IF(ABS(H25-I25)<20,0,H25-I25) -> 4320 | K25: 1341367 | L25: 37222
B26: 43498 | C26: 3563/ | D26: ECA003 | E26: Agroeden | F26: Fray Bentos | G26: Andino | H26: 1680 | I26: =SUMIF(Cargas!$C$6:$C$1064,C26,Cargas!$O$6:$O$1064) -> 0 | J26: =IF(ABS(H26-I26)<20,0,H26-I26) -> 1680 | K26: 1341640 | L26: 27614
B27: 43499 | C27: 4751/ | D27: ECB005 | E27: Truisfruit | F27: Montevideo | G27: Ciatran | H27: 3240 | I27: =SUMIF(Cargas!$C$6:$C$1064,C27,Cargas!$O$6:$O$1064) -> 0 | J27: =IF(ABS(H27-I27)<20,0,H27-I27) -> 3240 | K27: 1341639 | L27: 37223
B28: 43502 | C28: 2264/ | D28: ECE007 | E28: Exporsweet | F28: Montevideo | G28: Ciatran | H28: 4320 | I28: =SUMIF(Cargas!$C$6:$C$1064,C28,Cargas!$O$6:$O$1064) -> 0 | J28: =IF(ABS(H28-I28)<20,0,H28-I28) -> 4320 | K28: 1342093 | L28: 40102
B29: 43505 | C29: 3581/ | D29: ECA004 | E29: Agroeden | F29: Fray Bentos | G29: Andino | H29: 1680 | I29: =SUMIF(Cargas!$C$6:$C$1064,C29,Cargas!$O$6:$O$1064) -> 0 | J29: =IF(ABS(H29-I29)<20,0,H29-I29) -> 1680 | K29: 1342366 | L29: 31734
B30: 43505 | C30: 4774/ | D30: ECR006 | E30: Truisfruit | F30: Fray Bentos | G30: Uribe | H30: =1050*3 -> 3150 | I30: =SUMIF(Cargas!$C$6:$C$1064,C30,Cargas!$O$6:$O$1064) -> 0 | J30: =IF(ABS(H30-I30)<20,0,H30-I30) -> 3150 | K30: 1342091 | L30: 30897
B31: 43506 | C31: 4775/ | D31: ECB006 | E31: Truisfruit | F31: Montevideo | G31: Ciatran | H31: 3240 | I31: =SUMIF(Cargas!$C$6:$C$1064,C31,Cargas!$O$6:$O$1064) -> 0 | J31: =IF(ABS(H31-I31)<20,0,H31-I31) -> 3240 | K31: 1342092 | L31: 40758
B32: 43508 | C32: 194/ | D32: CLP002 | E32: Fruchac | F32: Fray Bentos | G32: Sarla y Ramón | H32: 2288 | I32: =SUMIF(Cargas!$C$6:$C$1064,C32,Cargas!$O$6:$O$1064) -> 0 | J32: =IF(ABS(H32-I32)<20,0,H32-I32) -> 2288 | K32: 134.25.23 | L32: 27521
B33: 43509 | C33: 2306/ | D33: ECE008 | E33: Exporsweet | F33: Montevideo | G33: Ciatran | H33: 4320 | I33: =SUMIF(Cargas!$C$6:$C$1064,C33,Cargas!$O$6:$O$1064) -> 0 | J33: =IF(ABS(H33-I33)<20,0,H33-I33) -> 4320 | K33: 1342522 | L33: 45635
B34: 43512 | C34: 4808/ | D34: ECR007 | E34: Truisfruit | F34: Fray Bentos | G34: Andino | H34: =1050*3 -> 3150 | I34: =SUMIF(Cargas!$C$6:$C$1064,C34,Cargas!$O$6:$O$1064) -> 0 | J34: =IF(ABS(H34-I34)<20,0,H34-I34) -> 3150 | K34: 1342520 | L34: 36590
B35: 43513 | C35: 4809/ | D35: ECB007 | E35: Truisfruit | F35: Montevideo | G35: Ciatran | H35: 3240 | I35: =SUMIF(Cargas!$C$6:$C$1064,C35,Cargas!$O$6:$O$1064) -> 0 | J35: =IF(ABS(H35-I35)<20,0,H35-I35) -> 3240 | K35: 1342521 | L35: 45552
B36: 43516 | C36: 2344/ | D36: ECE009 | E36: Exporsweet | F36: Montevideo | G36: Ciatran | H36: 4320 | I36: =SUMIF(Cargas!$C$6:$C$1064,C36,Cargas!$O$6:$O$1064) -> 0 | J36: =IF(ABS(H36-I36)<20,0,H36-I36) -> 4320 | K36: 1342951 | L36: 54829
B37: 43519 | C37: 3616/ | D37: ECA005 | E37: Agroeden | F37: Fray Bentos | G37: Uribe | H37: 1680 | I37: =SUMIF(Cargas!$C$6:$C$1064,C37,Cargas!$O$6:$O$1064) -> 0 | J37: =IF(ABS(H37-I37)<20,0,H37-I37) -> 1680 | K37: 1342952 | L37: 38751
B38: 43519 | C38: 2348/ | D38: ECE010 | E38: Exporsweet | F38: Fray Bentos | G38: Sarla y Ramón | H38: 2160 | I38: =SUMIF(Cargas!$C$6:$C$1064,C38,Cargas!$O$6:$O$1064) -> 0 | J38: =IF(ABS(H38-I38)<20,0,H38-I38) -> 2160 | K38: 1343036 | L38: 38214
B39: 43519 | C39: 4834/ | D39: ECR008 | E39: Truisfruit | F39: Fray Bentos | G39: Andino | H39: =1050*3 -> 3150 | I39: =SUMIF(Cargas!$C$6:$C$1064,C39,Cargas!$O$6:$O$1064) -> 0 | J39: =IF(ABS(H39-I39)<20,0,H39-I39) -> 3150 | K39: 1342950 | L39: 38964
B40: 43520 | C40: 4835/ | D40: ECB008 | E40: Truisfruit | F40: Montevideo | G40: Ciatran | H40: 3240 | I40: =SUMIF(Cargas!$C$6:$C$1064,C40,Cargas!$O$6:$O$1064) -> 0 | J40: =IF(ABS(H40-I40)<20,0,H40-I40) -> 3240 | K40: 1342949 | L40: 59131
B41: 43525 | C41: 197/ | D41: CLP003 | E41: Fruchac | F41: Fray Bentos | G41: Nihuil | H41: 1760 | I41: =SUMIF(Cargas!$C$6:$C$1064,C41,Cargas!$O$6:$O$1064) -> 0 | J41: =IF(ABS(H41-I41)<20,0,H41-I41) -> 1760 | K41: 134.33.85 | L41: 37006
B42: 43526 | C42: 3635/ | D42: ECA006 | E42: Agroeden | F42: Fray Bentos | G42: BOER-RCT | H42: 1680 | I42: =SUMIF(Cargas!$C$6:$C$1064,C42,Cargas!$O$6:$O$1064) -> 0 | J42: =IF(ABS(H42-I42)<20,0,H42-I42) -> 1680 | K42: 1343319 | L42: 44538
...

Sheet Hoja1

Sheet Rangos
B2: Listas para validación de datos
B4: Status List | D4: Transporte | E4: Cajas x Viaje | G4: Fronteras | I4: Productos | J4: Iniciales
B5: Solicitado | D5: Carrusel | E5: 1080 | G5: Fray Bentos | I5: Manzana | J5: Mz
B6: Confirmado | D6: Ciatran | E6: 1080 | G6: Montevideo | I6: Papa | J6: Pa
B7: Cancelado | D7: Sarla y Ramón | E7: 1080 | G7: Salto | I7: Banana | J7: Ba
G8: Carrasco | I8: Carozos | J8: Cr
B9: Cargado | D9: Cordoba | G9: xx | I9: Kiwi | J9: Kw
I10: Palta | J10: Pl
B11: Frontera | D11: Cigliuti | E11: 1080 | I11: Cebolla | J11: CB
B12: Liberado | D12: Decre | E12: 1080 | I12: Pera | J12: Pr
I13: Boniato | J13: Bo
B14: Arribado | D14: Allen | E14: 1080 | I14: Limón | J14: Lm
B15: Puerto | D15: CSAV | E15: 2310 | I15: Varios | J15: Vr
B16: Mar | D16: El Palomar | E16: 1000 | I16: Naranja | J16: Nj
B17: Tierra | D17: xx | E17: 1000 | I17: Pomelo | J17: Pm
B18: Chile | D18: Transporte Moro | E18: 1056 | I18: Arandano | J18: Ar
B19: Aeropuerto | D19: Arcadian ltda | E19: 1080 | I19: Cereza | J19: Cr
B20: TCP | D20: Nihuil | E20: 1080 | I20: Zanahoria | J20: Zn
I21: Esparrago | J21: Es
B22: U-Log | D22: Los Primos | E22: 1080 | I22: Piña | J22: Pn
B23: Montecon | D23: BOER-RCT | E23: 1080
B24: Lobraus | D24: Andino | E24: 1080
B25: Destruida | D25: Uribe | E25: 1080
B26: Dervalix | D26: Villavicencio | E26: 1080
B27: Joanico | D27: San Bernardo | E27: 1000
B28: Descargado | D28: transur | E28: 1000
D29: Valle Grande | E29: 1080
D30: Transporte CDC
D31: 1 Sarla / 1 Nihuil
D33: Cid | E33: 1080
