Workbook
Name Fronteras: Rangos!$H$5:$H$11
Name Productores: Rangos!$J$5:$J$69
Name Status: Rangos!$B$5:$B$14
Name Transporte: Rangos!$D$5:$D$75

Sheet Cargas
H1: --
A2: PROGRAMA DE CARGAS EN BRASIL desde 2024
O3: Detalle/descripción presentación producto
A4: Carga Sem.# | B4: Status | C4: Factura | D4: Productor | E4: Fecha de Carga | F4: Carpeta Import. | G4: AFIDI | H4: Transportista | I4: Exportador | J4: Fecha Frontera | K4: Frontera | L4: Productos | M4: Fecha Descarga | N4: TT | O4: Cajas MIC | P4: Cajas Desc | Q4: CANT. DE PALLET | R4: CANT. KILOS POR CAJA/BOLSA | S4: Código de viaje | U4: MIC | V4: PLACAS T | W4: PLACAS R | X4: Chofer | Y4: Celular | Z4: Observaciones
A5: 2 | B5: Descargado | C5: 001/24 | D5: Jaime | E5: 45300 | F5: =VLOOKUP($C5,Carpetas!$C$5:$M$2666,2,FALSE) -> BRB001 | G5: =VLOOKUP($C5,Carpetas!$C$5:$M$2666,10,FALSE) -> 148,22,17 | H5: =VLOOKUP($C5,Carpetas!$C$5:$M$2666,6,FALSE) -> Zanini | I5: =VLOOKUP($C5,Carpetas!$C$5:$M$2666,4,FALSE) -> 0 | J5: 45301 | K5: =VLOOKUP($C5,Carpetas!$C$5:$M$2666,5,FALSE) -> Rio Branco | M5: =J5+1 -> 45302 | N5: =IF(E5<>"",M5-E5,"-") -> 2 | O5: 918 | P5: 919 | S5: JM001 | U5: 4157 | V5: RLL 2A97 | W5: QHK 7710 | X5: Benhur da Rosa | Y5: =VLOOKUP(X5,Choferes!$B$2:$C$500,2,FALSE) -> +5555991366995 | Z5: MM 11/01 : DESCARGADO EN RIQUEZA NATURAL 919 CAJAS DE BRASIL FIBRA.
A6: 1 | B6: Descargado | C6: 021//24 | D6: Varios | E6: 45296 | F6: =VLOOKUP($C6,Carpetas!$C$5:$M$2666,2,FALSE) -> BRE002 | G6: =VLOOKUP($C6,Carpetas!$C$5:$M$2666,10,FALSE) -> 1481758/1411756/1411757/1471759 | H6: =VLOOKUP($C6,Carpetas!$C$5:$M$2666,6,FALSE) -> Benini | I6: =VLOOKUP($C6,Carpetas!$C$5:$M$2666,4,FALSE) -> 0 | J6: =E6+5 -> 45301 | K6: =VLOOKUP($C6,Carpetas!$C$5:$M$2666,5,FALSE) -> Rio Branco | M6: =J6+1+2 -> 45304 | N6: =IF(E6<>"",M6-E6,"-") -> 8 | O6: 1054 | U6: 58 | V6: RHB3A77 | W6: BEN2E70 | Y6: =VLOOKUP(X6,Choferes!$B$2:$C$500,2,FALSE) -> #N/A
A7: 2 | B7: Descargado | C7: 010/ | D7: Paraguay GM | E7: 45300 | F7: =VLOOKUP($C7,Carpetas!$C$5:$M$2666,2,FALSE) -> PYB005 | G7: =VLOOKUP($C7,Carpetas!$C$5:$M$2666,10,FALSE) -> 148,17,39 | H7: =VLOOKUP($C7,Carpetas!$C$5:$M$2666,6,FALSE) -> 0 | J7: 45303 | K7: =VLOOKUP($C7,Carpetas!$C$5:$M$2666,5,FALSE) -> Salto | M7: =J7+1 -> 45304 | N7: =IF(E7<>"",M7-E7,"-") -> 4 | O7: 930 | P7: 972 | S7: PY GM 003 | V7: AAGJ923 | W7: AADL399 | Y7: =VLOOKUP(X7,Choferes!$B$2:$C$500,2,FALSE) -> #N/A | Z7: se descargo en riqueza natural 972 cajas de py2 el dia 13/1/2024
A8: 2 | B8: Descargado | C8: 1183/ | D8: Paraguay EC | E8: 45301 | F8: =VLOOKUP($C8,Carpetas!$C$5:$M$2666,2,FALSE) -> PYB007 | G8: =VLOOKUP($C8,Carpetas!$C$5:$M$2666,10,FALSE) -> 148.21.72 | H8: =VLOOKUP($C8,Carpetas!$C$5:$M$2666,6,FALSE) -> 0 | J8: 45303 | K8: =VLOOKUP($C8,Carpetas!$C$5:$M$2666,5,FALSE) -> Salto | M8: =J8+1 -> 45304 | N8: =IF(E8<>"",M8-E8,"-") -> 3 | O8: 930 | P8: 930 | S8: PYEC006 | V8: AAEH166 | W8: AADU451 | Y8: =VLOOKUP(X8,Choferes!$B$2:$C$500,2,FALSE) -> #N/A | Z8: MM 15/01 : DESCARGADO EN RIQUEZA NATURAL 930 CAJAS DE PARAGUAY EXTRA.
A9: 2 | B9: Descargado | C9: 1182/ | D9: Paraguay EC | E9: 45300 | F9: =VLOOKUP($C9,Carpetas!$C$5:$M$2666,2,FALSE) -> PYB006 | G9: =VLOOKUP($C9,Carpetas!$C$5:$M$2666,10,FALSE) -> 148.21.71 | H9: =VLOOKUP($C9,Carpetas!$C$5:$M$2666,6,FALSE) -> 0 | J9: =E9+5 -> 45305 | K9: =VLOOKUP($C9,Carpetas!$C$5:$M$2666,5,FALSE) -> Salto | M9: =J9+1 -> 45306 | N9: =IF(E9<>"",M9-E9,"-") -> 6 | O9: 930 | P9: 930 | S9: PY EC 004 | V9: BOT019 | Y9: =VLOOKUP(X9,Choferes!$B$2:$C$500,2,FALSE) -> #N/A | Z9: SE DESCARGO EN RIQUEZA NATURAL 930 CAJAS DE PY EL DIA 12/1/2024
A10: 2 | B10: Descargado | C10: 001/24 | D10: Jaime | E10: 45303 | F10: =VLOOKUP($C10,Carpetas!$C$5:$M$2666,2,FALSE) -> BRB001 | G10: =VLOOKUP($C10,Carpetas!$C$5:$M$2666,10,FALSE) -> 148,22,17 | H10: =VLOOKUP($C10,Carpetas!$C$5:$M$2666,6,FALSE) -> Zanini | J10: =E10+2 -> 45305 | K10: =VLOOKUP($C10,Carpetas!$C$5:$M$2666,5,FALSE) -> Rio Branco | M10: 45307 | N10: =IF(E10<>"",M10-E10,"-") -> 4 | O10: 918 | P10: 918 | S10: JM002 | U10: 4161 | V10: RYK 8E00 | W10: RYF 1D53 | X10: Carlos Pompermaier | Y10: =VLOOKUP(X10,Choferes!$B$2:$C$500,2,FALSE) -> +5547991777362 | Z10: MM 16/01 : DESCARGADO EN RIQUEZA NATURAL 918 CAJAS DE BRASIL FBRA.
A11: 1 | B11: Descargado | C11: AL001/2024 | D11: Nordeste | E11: 45296 | F11: =VLOOKUP($C11,Carpetas!$C$5:$M$2666,2,FALSE) -> BRA001 | G11: =VLOOKUP($C11,Carpetas!$C$5:$M$2666,10,FALSE) -> 147,76,57 | H11: =VLOOKUP($C11,Carpetas!$C$5:$M$2666,6,FALSE) -> Silvio | J11: =E11+10 -> 45306 | K11: =VLOOKUP($C11,Carpetas!$C$5:$M$2666,5,FALSE) -> Rio Branco | M11: =J11+1 -> 45307 | N11: =IF(E11<>"",M11-E11,"-") -> 11 | O11: 1104 | S11: 1103 | U11: 6669 | V11: RXT 0A05 | W11: RXT 0A04 | X11: Rogerio Fagundes | Y11: =VLOOKUP(X11,Choferes!$B$2:$C$500,2,FALSE) -> +5555996711696 | Z11: SE DESCARGO EN RIQUEZA NATURAL 1103 CAJAS DE PURA VIDA EL DIA 16/1/2024. VINO EL CAMION CON FRUTA SENTIDA Y ALGUNOS PALLETS SIN FLEJES
A12: 2 | B12: Descargado | C12: 1182/ | D12: Paraguay EC | E12: 45301 | F12: =VLOOKUP($C12,Carpetas!$C$5:$M$2666,2,FALSE) -> PYB006 | G12: =VLOOKUP($C12,Carpetas!$C$5:$M$2666,10,FALSE) -> 148.21.71 | H12: =VLOOKUP($C12,Carpetas!$C$5:$M$2666,6,FALSE) -> 0 | J12: =E12+5 -> 45306 | K12: =VLOOKUP($C12,Carpetas!$C$5:$M$2666,5,FALSE) -> Salto | M12: =J12+1 -> 45307 | N12: =IF(E12<>"",M12-E12,"-") -> 6 | O12: 930 | P12: 932 | S12: PYEC005 | V12: AAAK129 | W12: CDP119 | Y12: =VLOOKUP(X12,Choferes!$B$2:$C$500,2,FALSE) -> #N/A | Z12: MM 15/01 : DESCARGADO EN RIQUEZA NATURAL 932 CAJAS DE PARAGUAY EXTRA.
A13: 2 | B13: Descargado | C13: 1185/ | D13: Paraguay EC | E13: 45302 | F13: =VLOOKUP($C13,Carpetas!$C$5:$M$2666,2,FALSE) -> PYB008 | G13: =VLOOKUP($C13,Carpetas!$C$5:$M$2666,10,FALSE) -> 148.22.46 | H13: =VLOOKUP($C13,Carpetas!$C$5:$M$2666,6,FALSE) -> 0 | J13: =E13+5 -> 45307 | K13: =VLOOKUP($C13,Carpetas!$C$5:$M$2666,5,FALSE) -> Salto | M13: =J13+1 -> 45308 | N13: =IF(E13<>"",M13-E13,"-") -> 6 | O13: 930 | P13: 933 | S13: PYEC007 | V13: AAHG850 | W13: AAHG813 | Y13: =VLOOKUP(X13,Choferes!$B$2:$C$500,2,FALSE) -> #N/A | Z13: MM 16/01 : DESCARGADO EN RIQUEZA NATURAL 933 CAJAS DE PARAGUAY EXTRA.
A14: 3 | B14: Descargado | C14: 002/24 | D14: Claudia | E14: 45306 | F14: =VLOOKUP($C14,Carpetas!$C$5:$M$2666,2,FALSE) -> BRB002 | G14: =VLOOKUP($C14,Carpetas!$C$5:$M$2666,10,FALSE) -> 148,25,12 | H14: =VLOOKUP($C14,Carpetas!$C$5:$M$2666,6,FALSE) -> Zanini | J14: =E14+2 -> 45308 | K14: =VLOOKUP($C14,Carpetas!$C$5:$M$2666,5,FALSE) -> Rio Branco | M14: =J14+1 -> 45309 | N14: =IF(E14<>"",M14-E14,"-") -> 3 | O14: 900 | P14: 900 | S14: CH002 | U14: 4167 | V14: EOE 2457 | W14: MJY 7674 | Y14: =VLOOKUP(X14,Choferes!$B$2:$C$500,2,FALSE) -> #N/A | Z14: MM 19/01 : DESCARGADO EN RIQUEZA NATURAL 900 CAJAS DE BRASIL FIBRA EXTRA.
A15: 3 | B15: Descargado | C15: 001/24 | D15: Jaime | E15: 45306 | F15: =VLOOKUP($C15,Carpetas!$C$5:$M$2666,2,FALSE) -> BRB001 | G15: =VLOOKUP($C15,Carpetas!$C$5:$M$2666,10,FALSE) -> 148,22,17 | H15: =VLOOKUP($C15,Carpetas!$C$5:$M$2666,6,FALSE) -> Zanini | J15: =E15+2 -> 45308 | K15: =VLOOKUP($C15,Carpetas!$C$5:$M$2666,5,FALSE) -> Rio Branco | M15: =J15+1 -> 45309 | N15: =IF(E15<>"",M15-E15,"-") -> 3 | O15: 918 | P15: 919 | S15: JM003 | U15: 4168 | V15: MGK 9855 | W15: EOE 2359 | Y15: =VLOOKUP(X15,Choferes!$B$2:$C$500,2,FALSE) -> #N/A | Z15: MM 19/01 : DESCARGADO EN RIQUEZA NATURAL 919 CAJAS DE BRASIL FIBRA EXTRA.
A16: 3 | B16: Descargado | C16: 001/24 | D16: Junkes | E16: 45307 | F16: =VLOOKUP($C16,Carpetas!$C$5:$M$2666,2,FALSE) -> BRB001 | G16: =VLOOKUP($C16,Carpetas!$C$5:$M$2666,10,FALSE) -> 148,22,17 | H16: =VLOOKUP($C16,Carpetas!$C$5:$M$2666,6,FALSE) -> Zanini | J16: =E16+2 -> 45309 | K16: =VLOOKUP($C16,Carpetas!$C$5:$M$2666,5,FALSE) -> Rio Branco | M16: =J16+1 -> 45310 | N16: =IF(E16<>"",M16-E16,"-") -> 3 | O16: 918 | P16: 918 | S16: JS001 | U16: 4175 | V16: RYH 3A87 | W16: RYH 2A07 | Y16: =VLOOKUP(X16,Choferes!$B$2:$C$500,2,FALSE) -> #N/A | Z16: se descargo en riqueza natural 918 cajas de brasil fibra el dia 19/1/2024
A17: 3 | B17: Descargado | C17: 1182/ | D17: Paraguay EC | E17: 45306 | F17: =VLOOKUP($C17,Carpetas!$C$5:$M$2666,2,FALSE) -> PYB006 | G17: =VLOOKUP($C17,Carpetas!$C$5:$M$2666,10,FALSE) -> 148.21.71 | H17: =VLOOKUP($C17,Carpetas!$C$5:$M$2666,6,FALSE) -> 0 | J17: 45310 | K17: =VLOOKUP($C17,Carpetas!$C$5:$M$2666,5,FALSE) -> Salto | M17: =J17+1 -> 45311 | N17: =IF(E17<>"",M17-E17,"-") -> 5 | O17: 930 | P17: 932 | S17: PYEC008 | V17: AAAG911 | W17: HFD454 | Y17: =VLOOKUP(X17,Choferes!$B$2:$C$500,2,FALSE) -> #N/A | Z17: MM 20/01: DESCARGADO EN RIQUEZA NATURAL 932 CAJAS DE PARAGUAY EXTRA,
A18: 3 | B18: Descargado | C18: 1187/ | D18: Paraguay EC | E18: 45307 | F18: =VLOOKUP($C18,Carpetas!$C$5:$M$2666,2,FALSE) -> PYB012 | G18: =VLOOKUP($C18,Carpetas!$C$5:$M$2666,10,FALSE) -> 148.26.79 | H18: =VLOOKUP($C18,Carpetas!$C$5:$M$2666,6,FALSE) -> 0 | J18: 45310 | K18: =VLOOKUP($C18,Carpetas!$C$5:$M$2666,5,FALSE) -> Salto | M18: =J18+1 -> 45311 | N18: =IF(E18<>"",M18-E18,"-") -> 4 | O18: 930 | P18: 930 | S18: PYEC009 | V18: AAIS133 | W18: AYZ125 | Y18: =VLOOKUP(X18,Choferes!$B$2:$C$500,2,FALSE) -> #N/A | Z18: MM 22/01 : DESCARGADO EN RIQUEZA NATURAL 930 CAJAS DE PARAGUAY EXTRA.
A19: 3 | B19: Descargado | C19: 307/ | D19: Paraguay MS | E19: 45307 | F19: =VLOOKUP($C19,Carpetas!$C$5:$M$2666,2,FALSE) -> PYB009 | G19: =VLOOKUP($C19,Carpetas!$C$5:$M$2666,10,FALSE) -> 148.22.30 | H19: =VLOOKUP($C19,Carpetas!$C$5:$M$2666,6,FALSE) -> 0 | J19: 45310 | K19: =VLOOKUP($C19,Carpetas!$C$5:$M$2666,5,FALSE) -> Salto | M19: =J19+1 -> 45311 | N19: =IF(E19<>"",M19-E19,"-") -> 4 | O19: 980 | V19: AACG469 | Y19: =VLOOKUP(X19,Choferes!$B$2:$C$500,2,FALSE) -> #N/A | Z19: 20/01: DESCARGADO EN RIQUEZA NATURAL 980 CAJAS DE PARAGUAY EXTRA.
A20: 3 | B20: Descargado | C20: 002/24 | D20: Claudia | E20: 45308 | F20: =VLOOKUP($C20,Carpetas!$C$5:$M$2666,2,FALSE) -> BRB002 | G20: =VLOOKUP($C20,Carpetas!$C$5:$M$2666,10,FALSE) -> 148,25,12 | H20: =VLOOKUP($C20,Carpetas!$C$5:$M$2666,6,FALSE) -> Zanini | J20: =E20+2 -> 45310 | K20: =VLOOKUP($C20,Carpetas!$C$5:$M$2666,5,FALSE) -> Rio Branco | M20: =J20+1 -> 45311 | N20: =IF(E20<>"",M20-E20,"-") -> 3 | O20: 900 | P20: 900 | S20: CH003 | U20: 4181 | V20: RKX 1F29 | W20: REA 1H91 | X20: Diego Lopes | Y20: =VLOOKUP(X20,Choferes!$B$2:$C$500,2,FALSE) -> +5542991092026 | Z20: MM 20/01 : DESCARGADO EN RIQUEZA NATURAL 900 CAJAS DE BRASIL FIBRA EXTRA.
A21: 3 | B21: Descargado | C21: 001/24 | D21: Corupá | E21: 45308 | F21: =VLOOKUP($C21,Carpetas!$C$5:$M$2666,2,FALSE) -> BRB001 | G21: =VLOOKUP($C21,Carpetas!$C$5:$M$2666,10,FALSE) -> 148,22,17 | H21: =VLOOKUP($C21,Carpetas!$C$5:$M$2666,6,FALSE) -> Zanini | J21: =E21+2 -> 45310 | K21: =VLOOKUP($C21,Carpetas!$C$5:$M$2666,5,FALSE) -> Rio Branco | M21: =J21+1 -> 45311 | N21: =IF(E21<>"",M21-E21,"-") -> 3 | O21: 918 | P21: 919 | S21: CP002 | U21: 4180 | V21: EOE 2456 | W21: EOE 2444 | X21: Edenilson S. de Almeida | Y21: =VLOOKUP(X21,Choferes!$B$2:$C$500,2,FALSE) -> +5542998101794 | Z21: MM 20/01 : DESCARGADO EN RIQUEZA NATURAL 919 CAJAS DE BRASIL COMUN.
A22: 3 | B22: Descargado | C22: 307/ | D22: Paraguay MS | E22: 45308 | F22: =VLOOKUP($C22,Carpetas!$C$5:$M$2666,2,FALSE) -> PYB009 | G22: =VLOOKUP($C22,Carpetas!$C$5:$M$2666,10,FALSE) -> 148.22.30 | H22: =VLOOKUP($C22,Carpetas!$C$5:$M$2666,6,FALSE) -> 0 | J22: 45310 | K22: =VLOOKUP($C22,Carpetas!$C$5:$M$2666,5,FALSE) -> Salto | M22: =J22+1 -> 45311 | N22: =IF(E22<>"",M22-E22,"-") -> 3 | O22: 980 | P22: 980 | S22: PYMS004 | V22: AAGO344 | W22: AAGX855 | Y22: =VLOOKUP(X22,Choferes!$B$2:$C$500,2,FALSE) -> #N/A | Z22: MM 20/01: DESCARGADO EN RIQUEZA NATURAL 980 CAJAS DE PARAGUAY EXTRA,
A23: 3 | B23: Descargado | C23: 097/ | D23: Paraguay DF | E23: 45308 | F23: =VLOOKUP($C23,Carpetas!$C$5:$M$2666,2,FALSE) -> PYB010 | G23: =VLOOKUP($C23,Carpetas!$C$5:$M$2666,10,FALSE) -> 148.22.93 | H23: =VLOOKUP($C23,Carpetas!$C$5:$M$2666,6,FALSE) -> 0 | J23: 45310 | K23: =VLOOKUP($C23,Carpetas!$C$5:$M$2666,5,FALSE) -> Salto | M23: =J23+1 -> 45311 | N23: =IF(E23<>"",M23-E23,"-") -> 3 | O23: 980 | P23: 982 | S23: PYDF001 | V23: KAZ602 | W23: HBA800 | Y23: =VLOOKUP(X23,Choferes!$B$2:$C$500,2,FALSE) -> #N/A | Z23: MM 20/01 : DESCARGADO EN RIQUEZA NATURAL 982 CAJAS DE PARAGUAY SEGUNDA.
A24: 3 | B24: Descargado | C24: 011/ | D24: Paraguay GM | E24: 45306 | F24: =VLOOKUP($C24,Carpetas!$C$5:$M$2666,2,FALSE) -> PYB011 | G24: =VLOOKUP($C24,Carpetas!$C$5:$M$2666,10,FALSE) -> 148,22,92 | H24: =VLOOKUP($C24,Carpetas!$C$5:$M$2666,6,FALSE) -> 0 | J24: 45310 | K24: =VLOOKUP($C24,Carpetas!$C$5:$M$2666,5,FALSE) -> Salto | M24: =J24+1+3 -> 45314 | N24: =IF(E24<>"",M24-E24,"-") -> 8 | O24: 972 | P24: 972 | S24: PYGM004 | V24: NBR357 | W24: NBR474 | Y24: =VLOOKUP(X24,Choferes!$B$2:$C$500,2,FALSE) -> #N/A | Z24: AL 23/01 : SE DESCARGARON EN RIQUEZA NATURAL 972 CAJAS DE PARAGUAY 2ª.
A25: 2 | B25: Descargado | C25: AL002/2024 | D25: Nordeste | E25: 45304 | F25: =VLOOKUP($C25,Carpetas!$C$5:$M$2666,2,FALSE) -> BRA002 | G25: =VLOOKUP($C25,Carpetas!$C$5:$M$2666,10,FALSE) -> 0 | H25: =VLOOKUP($C25,Carpetas!$C$5:$M$2666,6,FALSE) -> Silvio | J25: 45313 | K25: =VLOOKUP($C25,Carpetas!$C$5:$M$2666,5,FALSE) -> Rio Branco | M25: =J25+1 -> 45314 | N25: =IF(E25<>"",M25-E25,"-") -> 10 | O25: 1104 | P25: 1104 | S25: 61447 | U25: 6682 | V25: RYK 0G12 | W25: FCE 5549 | X25: Emerson Lappe | Y25: =VLOOKUP(X25,Choferes!$B$2:$C$500,2,FALSE) -> +5549999774835 | Z25: MM 25/01 : DESCARGADO EN RIQUEZA NATURAL 1104 CAJAS DE BRASIL CARTON.
A26: 3 | B26: Descargado | C26: 1188/ | D26: Paraguay EC | E26: 45308 | F26: =VLOOKUP($C26,Carpetas!$C$5:$M$2666,2,FALSE) -> PYB013 | G26: =VLOOKUP($C26,Carpetas!$C$5:$M$2666,10,FALSE) -> 148.26.81 | H26: =VLOOKUP($C26,Carpetas!$C$5:$M$2666,6,FALSE) -> 0 | J26: =E26+5 -> 45313 | K26: =VLOOKUP($C26,Carpetas!$C$5:$M$2666,5,FALSE) -> Salto | M26: =J26+1 -> 45314 | N26: =IF(E26<>"",M26-E26,"-") -> 6 | O26: 930 | P26: 933 | S26: PYEC010 | V26: AAAA288 | W26: AAAA294 | Y26: =VLOOKUP(X26,Choferes!$B$2:$C$500,2,FALSE) -> #N/A | Z26: AL 23/01 : SE DESCARGARON EN RIQUEZA NATURAL 933 CAJAS DE PARAGUAY EXTRA.
A27: 3 | B27: Descargado | C27: 001/24 | D27: Jaime | E27: 45310 | F27: =VLOOKUP($C27,Carpetas!$C$5:$M$2666,2,FALSE) -> BRB001 | G27: =VLOOKUP($C27,Carpetas!$C$5:$M$2666,10,FALSE) -> 148,22,17 | H27: =VLOOKUP($C27,Carpetas!$C$5:$M$2666,6,FALSE) -> Zanini | J27: 45313 | K27: =VLOOKUP($C27,Carpetas!$C$5:$M$2666,5,FALSE) -> Rio Branco | M27: =J27+1+1 -> 45315 | N27: =IF(E27<>"",M27-E27,"-") -> 5 | O27: 918 | P27: 919 | S27: JM004 | U27: 4187 | V27: QIW 6450 | W27: QHT 8275 | Y27: =VLOOKUP(X27,Choferes!$B$2:$C$500,2,FALSE) -> #N/A | Z27: AL 24/01 : DESCARGADO EN RIQUEZA NATURAL 919 CAJAS DE BRASIL FIBRA.
A28: 4 | B28: Descargado | C28: 003/24 | D28: Jaime | E28: 45313 | F28: =VLOOKUP($C28,Carpetas!$C$5:$M$2666,2,FALSE) -> BRB003 | G28: =VLOOKUP($C28,Carpetas!$C$5:$M$2666,10,FALSE) -> 148,30,62 | H28: =VLOOKUP($C28,Carpetas!$C$5:$M$2666,6,FALSE) -> Zanini | J28: =E28+2 -> 45315 | K28: =VLOOKUP($C28,Carpetas!$C$5:$M$2666,5,FALSE) -> Rio Branco | M28: =J28+1 -> 45316 | N28: =IF(E28<>"",M28-E28,"-") -> 3 | O28: 918 | P28: 919 | S28: JM005 | U28: 4192 | V28: FEJ 8C47 | W28: EOE 2445 | Y28: =VLOOKUP(X28,Choferes!$B$2:$C$500,2,FALSE) -> #N/A | Z28: MM 27/01 : DESCARGADO EN RIQUEZA NATURAL 919 CAJAS DE BRASIL FIBRA.
A29: 4 | B29: Descargado | C29: 002/24 | D29: Claudia | E29: 45313 | F29: =VLOOKUP($C29,Carpetas!$C$5:$M$2666,2,FALSE) -> BRB002 | G29: =VLOOKUP($C29,Carpetas!$C$5:$M$2666,10,FALSE) -> 148,25,12 | H29: =VLOOKUP($C29,Carpetas!$C$5:$M$2666,6,FALSE) -> Zanini | J29: =E29+2 -> 45315 | K29: =VLOOKUP($C29,Carpetas!$C$5:$M$2666,5,FALSE) -> Rio Branco | M29: =J29+1 -> 45316 | N29: =IF(E29<>"",M29-E29,"-") -> 3 | O29: 900 | P29: 901 | S29: CH005 | U29: 4191 | V29: RDY 1B34 | W29: RDS 5I03 | Y29: =VLOOKUP(X29,Choferes!$B$2:$C$500,2,FALSE) -> #N/A | Z29: AL 27/01: DESCARGADO EN ROQUEZA NATURAL 901CAJAS DE BRASIL FIBRA EXTRA..
A30: 4 | B30: Descargado | C30: 012/ | D30: Paraguay GM | E30: 45313 | F30: =VLOOKUP($C30,Carpetas!$C$5:$M$2666,2,FALSE) -> PYB016 | G30: =VLOOKUP($C30,Carpetas!$C$5:$M$2666,10,FALSE) -> 148,29,76 | H30: =VLOOKUP($C30,Carpetas!$C$5:$M$2666,6,FALSE) -> 0 | J30: 45315 | K30: =VLOOKUP($C30,Carpetas!$C$5:$M$2666,5,FALSE) -> Salto | M30: =J30+1 -> 45316 | N30: =IF(E30<>"",M30-E30,"-") -> 3 | O30: 980 | P30: 974 | S30: PYGM005 | V30: BHH113 | W30: OBA516 | Y30: =VLOOKUP(X30,Choferes!$B$2:$C$500,2,FALSE) -> #N/A | Z30: MM 25/01 : DESCARGADO EN RIQUEZA NATURAL 974 CAJAS DE PARAGUAY COMUN.
A31: 4 | B31: Descargado | C31: 311/ | D31: Paraguay MS | E31: 45313 | F31: =VLOOKUP($C31,Carpetas!$C$5:$M$2666,2,FALSE) -> PYB018 | G31: =VLOOKUP($C31,Carpetas!$C$5:$M$2666,10,FALSE) -> 148,29,76 | H31: =VLOOKUP($C31,Carpetas!$C$5:$M$2666,6,FALSE) -> 0 | J31: 45315 | K31: =VLOOKUP($C31,Carpetas!$C$5:$M$2666,5,FALSE) -> Salto | M31: =J31+1 -> 45316 | N31: =IF(E31<>"",M31-E31,"-") -> 3 | O31: 980 | P31: 980 | S31: PYMS005 | V31: AAIS110 | W31: OCG216 | Y31: =VLOOKUP(X31,Choferes!$B$2:$C$500,2,FALSE) -> #N/A | Z31: AL 27/01: DESCARGADO EN ROQUEZA NATURAL 980 CAJAS DE PY PEPE
A32: 4 | B32: Descargado | C32: 1190/ | D32: Paraguay EC | E32: 45313 | F32: =VLOOKUP($C32,Carpetas!$C$5:$M$2666,2,FALSE) -> PYB017 | G32: =VLOOKUP($C32,Carpetas!$C$5:$M$2666,10,FALSE) -> 148,29,76 | H32: =VLOOKUP($C32,Carpetas!$C$5:$M$2666,6,FALSE) -> 0 | J32: 45316 | K32: =VLOOKUP($C32,Carpetas!$C$5:$M$2666,5,FALSE) -> Salto | M32: =J32+1 -> 45317 | N32: =IF(E32<>"",M32-E32,"-") -> 4 | O32: 930 | P32: 933 | S32: PYEC011 | V32: ZAE495 | W32: BZR991 | Y32: =VLOOKUP(X32,Choferes!$B$2:$C$500,2,FALSE) -> #N/A | Z32: SE DESCARGO EN RIQUEZA 933 CAJAS DE PY EXTRA EL DIA 27/1/2024
A33: 4 | B33: Descargado | C33: 012/ | D33: Paraguay GM | E33: 45313 | F33: =VLOOKUP($C33,Carpetas!$C$5:$M$2666,2,FALSE) -> PYB016 | G33: =VLOOKUP($C33,Carpetas!$C$5:$M$2666,10,FALSE) -> 148,29,76 | H33: =VLOOKUP($C33,Carpetas!$C$5:$M$2666,6,FALSE) -> 0 | J33: 45316 | K33: =VLOOKUP($C33,Carpetas!$C$5:$M$2666,5,FALSE) -> Salto | M33: =J33+1 -> 45317 | N33: =IF(E33<>"",M33-E33,"-") -> 4 | O33: 980 | P33: 972 | S33: PYGM006 | V33: BFK 528 | W33: BEF 740 | Y33: =VLOOKUP(X33,Choferes!$B$2:$C$500,2,FALSE) -> #N/A | Z33: MM 27/01 : DESCARGADO EN RIQUEZA NATURAL 972 CAJAS DE PARAGUAY,
A34: 4 | B34: Descargado | C34: 004/24 | D34: Junkes | E34: 45314 | F34: =VLOOKUP($C34,Carpetas!$C$5:$M$2666,2,FALSE) -> BRB004 | G34: =VLOOKUP($C34,Carpetas!$C$5:$M$2666,10,FALSE) -> 148,30,63 | H34: =VLOOKUP($C34,Carpetas!$C$5:$M$2666,6,FALSE) -> Silvio | J34: =E34+2 -> 45316 | K34: =VLOOKUP($C34,Carpetas!$C$5:$M$2666,5,FALSE) -> Rio Branco | M34: =J34+1 -> 45317 | N34: =IF(E34<>"",M34-E34,"-") -> 3 | O34: 918 | P34: 918 | S34: JS002 | U34: 6702 | V34: MEA 9B24 | W34: INX 0372 | Y34: =VLOOKUP(X34,Choferes!$B$2:$C$500,2,FALSE) -> #N/A | Z34: MM 27/01 : DESCARGADO EN RIQUEZA NATURAL 918 CAJAS DE BRASIL FIBRA.
A35: 4 | B35: Descargado | C35: 1190/ | D35: Paraguay EC | E35: 45314 | F35: =VLOOKUP($C35,Carpetas!$C$5:$M$2666,2,FALSE) -> PYB017 | G35: =VLOOKUP($C35,Carpetas!$C$5:$M$2666,10,FALSE) -> 148,29,76 | H35: =VLOOKUP($C35,Carpetas!$C$5:$M$2666,6,FALSE) -> 0 | J35: 45316 | K35: =VLOOKUP($C35,Carpetas!$C$5:$M$2666,5,FALSE) -> Salto | M35: =J35+1 -> 45317 | N35: =IF(E35<>"",M35-E35,"-") -> 3 | O35: 930 | P35: 930 | S35: PYEC012 | V35: MBP313 | W35: OBF281 | Y35: =VLOOKUP(X35,Choferes!$B$2:$C$500,2,FALSE) -> #N/A | Z35: AL 27/01: DESCARGADO EN ROQUEZA NATURAL 930 CAJAS DE PY PEPE EXTRA.
A36: 4 | B36: Descargado | C36: 2280/ | D36: Paraguay HF | E36: 45312 | F36: =VLOOKUP($C36,Carpetas!$C$5:$M$2666,2,FALSE) -> PYB014 | G36: =VLOOKUP($C36,Carpetas!$C$5:$M$2666,10,FALSE) -> 148.27.09 | H36: =VLOOKUP($C36,Carpetas!$C$5:$M$2666,6,FALSE) -> 0 | J36: =E36+5 -> 45317 | K36: =VLOOKUP($C36,Carpetas!$C$5:$M$2666,5,FALSE) -> Salto | M36: =J36+1 -> 45318 | N36: =IF(E36<>"",M36-E36,"-") -> 6 | O36: 980 | P36: 980 | S36: PYHF001 | V36: KAO 996 | W36: ZAR 552 | Y36: =VLOOKUP(X36,Choferes!$B$2:$C$500,2,FALSE) -> #N/A | Z36: MM 27/01 : DESCARGADO EN RIQUEZA NATURAL 980 CAJAS DE PARAGUAY,
A37: 4 | B37: Descargado | C37: 002/24 | D37: Claudia | E37: 45316 | F37: =VLOOKUP($C37,Carpetas!$C$5:$M$2666,2,FALSE) -> BRB002 | G37: =VLOOKUP($C37,Carpetas!$C$5:$M$2666,10,FALSE) -> 148,25,12 | H37: =VLOOKUP($C37,Carpetas!$C$5:$M$2666,6,FALSE) -> Zanini | J37: =E37+2 -> 45318 | K37: =VLOOKUP($C37,Carpetas!$C$5:$M$2666,5,FALSE) -> Rio Branco | M37: =J37+1 -> 45319 | N37: =IF(E37<>"",M37-E37,"-") -> 3 | O37: 900 | P37: 901 | S37: CH004 | U37: 4200 | V37: RLL 2A97 | W37: QHK 7710 | Y37: =VLOOKUP(X37,Choferes!$B$2:$C$500,2,FALSE) -> #N/A | Z37: MM 27/01 : DESCARGADO EN RIQUEZA NATURAL 901 CAJAS DE BRASIL FIBRA EXTRA.
A38: 4 | B38: Descargado | C38: 312/ | D38: Paraguay MS | E38: 45315 | F38: =VLOOKUP($C38,Carpetas!$C$5:$M$2666,2,FALSE) -> PYB019 | G38: =VLOOKUP($C38,Carpetas!$C$5:$M$2666,10,FALSE) -> 148,29,76 | H38: =VLOOKUP($C38,Carpetas!$C$5:$M$2666,6,FALSE) -> 0 | J38: 45318 | K38: =VLOOKUP($C38,Carpetas!$C$5:$M$2666,5,FALSE) -> Salto | M38: 45320 | N38: =IF(E38<>"",M38-E38,"-") -> 5 | O38: 980 | P38: 980 | S38: PYMS006 | V38: AAJE676 | W38: AAJE638 | Y38: =VLOOKUP(X38,Choferes!$B$2:$C$500,2,FALSE) -> #N/A | Z38: SE DESCARGO EN RIQUEZA NATURAL 980 CAJAS DE PY EL DIA 29/1/2024
A39: 4 | B39: Descargado | C39: 101// | D39: Paraguay DF | E39: 45314 | F39: =VLOOKUP($C39,Carpetas!$C$5:$M$2666,2,FALSE) -> PYB015 | G39: =VLOOKUP($C39,Carpetas!$C$5:$M$2666,10,FALSE) -> 148,29,77 | H39: =VLOOKUP($C39,Carpetas!$C$5:$M$2666,6,FALSE) -> 0 | J39: =E39+5 -> 45319 | K39: =VLOOKUP($C39,Carpetas!$C$5:$M$2666,5,FALSE) -> Salto | M39: =J39+1 -> 45320 | N39: =IF(E39<>"",M39-E39,"-") -> 6 | O39: 980 | P39: 980 | S39: DF001 | V39: AAFL 470 | W39: BCC 343 | Y39: =VLOOKUP(X39,Choferes!$B$2:$C$500,2,FALSE) -> #N/A | Z39: MM 27/01 : DESCARGADO EN RIQUEZA NATURAL 980 CAJAS DE PARAGUAY,
A40: 3 | B40: Descargado | C40: AL003/2024 | D40: Nordeste | E40: 45310 | F40: =VLOOKUP($C40,Carpetas!$C$5:$M$2666,2,FALSE) -> BRA003 | G40: =VLOOKUP($C40,Carpetas!$C$5:$M$2666,10,FALSE) -> 0 | H40: =VLOOKUP($C40,Carpetas!$C$5:$M$2666,6,FALSE) -> Silvio | J40: 45317 | K40: =VLOOKUP($C40,Carpetas!$C$5:$M$2666,5,FALSE) -> Rio Branco | M40: 45321 | N40: =IF(E40<>"",M40-E40,"-") -> 11 | O40: 1104 | P40: 1104 | S40: 61014 | U40: 6693 | V40: RXP 2F83 | W40: MAQ 7E23 | Y40: =VLOOKUP(X40,Choferes!$B$2:$C$500,2,FALSE) -> #N/A | Z40: MM 30/01 : DESCARGADO EN RIQUEZA NATURAL 1104 CAJAS DE BRASIL CARTON.
...

Sheet Carpetas
B2: CARPETAS DE IMPORTACIÓN - CONTROL DE CARGAS y SALDOS
C4: Fatura | D4: Carpeta | E4: Export | F4: Producto | G4: Frontera | H4: Transp. | I4: Qtde | J4: Cargado | K4: Saldo | L4: Afidi | M4: DUA
B5: 44208 | C5: 2994/ | D5: BRA001 | E5: Agricola Famosa | G5: Rio Branco | H5: Silvio | I5: 1152 | J5: =SUMIF(Cargas!#REF!,C5,Cargas!#REF!) -> #REF! | K5: =IF(ABS(I5-J5)<20,0,I5-J5) -> #REF! | L5: 139.16.59 | M5: 6588
B6: 44208 | C6: 2995/ | D6: BRA001 | E6: Agricola Famosa | G6: Rio Branco | H6: Silvio | I6: 1152 | J6: =SUMIF(Cargas!#REF!,C6,Cargas!#REF!) -> #REF! | K6: =IF(ABS(I6-J6)<20,0,I6-J6) -> #REF! | L6: 139.16.58 | M6: 6588
B7: 44208 | C7: 3055/ | D7: BRA001 | E7: Agricola Famosa | G7: Rio Branco | H7: Silvio | I7: 1152 | J7: =SUMIF(Cargas!#REF!,C7,Cargas!#REF!) -> #REF! | K7: =IF(ABS(I7-J7)<20,0,I7-J7) -> #REF! | L7: 139.16.57 | M7: 6588
B8: 44209 | C8: 3115/ | D8: BRA002 | E8: Agricola Famosa | G8: Rio Branco | H8: Silvio | I8: 1152 | J8: =SUMIF(Cargas!#REF!,C8,Cargas!#REF!) -> #REF! | K8: =IF(ABS(I8-J8)<20,0,I8-J8) -> #REF! | L8: 139.20.23 | M8: 10198
B9: 44209 | C9: 3116/ | D9: BRA003 | E9: Agricola Famosa | G9: Rio Branco | H9: Miro | I9: 1152 | J9: =SUMIF(Cargas!#REF!,C9,Cargas!#REF!) -> #REF! | K9: =IF(ABS(I9-J9)<20,0,I9-J9) -> #REF! | L9: 139.20.24 | M9: 10227
B10: 44221 | C10: 3179/ | D10: BRA004 | E10: Agricola Famosa | G10: Rio Branco | H10: Silvio | I10: 1152 | J10: =SUMIF(Cargas!#REF!,C10,Cargas!#REF!) -> #REF! | K10: =IF(ABS(I10-J10)<20,0,I10-J10) -> #REF! | L10: 139.25.59 | M10: 15413
B11: 44221 | C11: 3331/ | D11: BRA004 | E11: Agricola Famosa | G11: Rio Branco | H11: Silvio | I11: 1152 | J11: =SUMIF(Cargas!#REF!,C11,Cargas!#REF!) -> #REF! | K11: =IF(ABS(I11-J11)<20,0,I11-J11) -> #REF! | L11: 139.25.60 | M11: 15413
B12: 44224 | C12: 3332/ | D12: BRA005 | E12: Agricola Famosa | G12: Rio Branco | H12: Silvio | I12: 1152 | J12: =SUMIF(Cargas!#REF!,C12,Cargas!#REF!) -> #REF! | K12: =IF(ABS(I12-J12)<20,0,I12-J12) -> #REF! | L12: 139.28.29 | M12: 19843
B13: 44231 | C13: 3384/ | D13: BRA005 | E13: Agricola Famosa | G13: Rio Branco | H13: Silvio | I13: 1152 | J13: =SUMIF(Cargas!#REF!,C13,Cargas!#REF!) -> #REF! | K13: =IF(ABS(I13-J13)<20,0,I13-J13) -> #REF! | L13: 139.28.29 | M13: 19843
B14: 44238 | C14: 3385/ | D14: BRA005 | E14: Agricola Famosa | G14: Rio Branco | H14: Silvio | I14: 1152 | J14: =SUMIF(Cargas!#REF!,C14,Cargas!#REF!) -> #REF! | K14: =IF(ABS(I14-J14)<20,0,I14-J14) -> #REF! | L14: 139.28.29 | M14: 19843
B15: 44232 | C15: 3494/ | D15: BRA006 | E15: Agricola Famosa | G15: Rio Branco | H15: Silvio | I15: 1152 | J15: 1152 | K15: =IF(ABS(I15-J15)<20,0,I15-J15) -> 0 | L15: 139.31.58 | M15: 23337
B16: 44232 | C16: 3495/ | D16: BRA006 | E16: Agricola Famosa | G16: Rio Branco | H16: Silvio | I16: 1152 | J16: 1152 | K16: =IF(ABS(I16-J16)<20,0,I16-J16) -> 0 | L16: 139.31.58 | M16: 23337
B17: 44233 | C17: 3556/ | D17: BRA006 | E17: Agricola Famosa | G17: Rio Branco | H17: Silvio | I17: 1152 | J17: 1152 | K17: =IF(ABS(I17-J17)<20,0,I17-J17) -> 0 | L17: 139.31.58 | M17: 23337
B18: 44238 | C18: 3557/ | D18: BRA007 | E18: Agricola Famosa | G18: Rio Branco | H18: Silvio | I18: 1152 | J18: 1152 | K18: =IF(ABS(I18-J18)<20,0,I18-J18) -> 0 | L18: 139.31.59 | M18: 25865
B19: 44239 | C19: 3558/ | D19: BRA007 | E19: Agricola Famosa | G19: Rio Branco | H19: Silvio | I19: 1152 | J19: 1152 | K19: =IF(ABS(I19-J19)<20,0,I19-J19) -> 0 | L19: 139.31.59 | M19: 25865
B20: 44240 | C20: 3653/ | D20: BRA008 | E20: Agricola Famosa | G20: Rio Branco | H20: Miro | I20: 1152 | J20: 1152 | K20: =IF(ABS(I20-J20)<20,0,I20-J20) -> 0 | L20: 139.31.60 | M20: 26759
B21: 44248 | C21: 3707/21 | D21: BRA009 | E21: Agricola Famosa | G21: Rio Branco | H21: Miro | I21: 1152 | J21: 1152 | K21: =IF(ABS(I21-J21)<20,0,I21-J21) -> 0 | L21: 139.42.43 | M21: 32433
B22: 44248 | C22: 3657/21 | D22: BRA010 | E22: Agricola Famosa | G22: Rio Branco | H22: Silvio | I22: 1152 | J22: 1152 | K22: =IF(ABS(I22-J22)<20,0,I22-J22) -> 0 | L22: 139.42.42 | M22: 30518
B23: 44248 | C23: 3696/21 | D23: BRA010 | E23: Agricola Famosa | G23: Rio Branco | H23: Silvio | I23: 1152 | J23: 1152 | K23: =IF(ABS(I23-J23)<20,0,I23-J23) -> 0 | L23: 139.42.42 | M23: 30518
B24: 44254 | C24: 3731/21 | D24: BRA011 | E24: Agricola Famosa | G24: Rio Branco | H24: Silvio | I24: 1152 | J24: 1152 | K24: =IF(ABS(I24-J24)<20,0,I24-J24) -> 0 | L24: 139.48.43 | M24: 35198
B25: 44254 | C25: 3762/21 | D25: BRA011 | E25: Agricola Famosa | G25: Rio Branco | H25: Silvio | I25: 1152 | J25: 1152 | K25: =IF(ABS(I25-J25)<20,0,I25-J25) -> 0 | L25: 139.48.43 | M25: 35198
B26: 44254 | C26: 3763/21 | D26: BRA011 | E26: Agricola Famosa | G26: Rio Branco | H26: Silvio | I26: 1152 | J26: 1152 | K26: =IF(ABS(I26-J26)<20,0,I26-J26) -> 0 | L26: 139.48.43 | M26: 35198
... B37: 44281 | C37: 3925/ | D37: BRA018 | E37: Agricola Famosa | G37: Rio Branco | H37: Miro | I37: 1152 | J37: 1152 | K37: =IF(ABS(I37-J37)<20,0,I37-J37) -> 0 | L37: 139.66.98 | M37: 54196
B38: 44281 | C38: 3957/ | D38: BRA019 | E38: Agricola Famosa | G38: Rio Branco | H38: silvio | I38: 1152 | J38: 1152 | K38: =IF(ABS(I38-J38)<20,0,I38-J38) -> 0 | M38: 55368
B39: 44281 | C39: 3958/ | D39: BRA019 | E39: Agricola Famosa | G39: Rio Branco | H39: Silvio | I39: 1152 | J39: 1152 | K39: =IF(ABS(I39-J39)<20,0,I39-J39) -> 0 | M39: 55368
B40: 44281 | C40: 3959/ | D40: BRA020 | E40: Agricola Famosa | G40: Rio Branco | H40: Miro | I40: 1152 | J40: 1152 | K40: =IF(ABS(I40-J40)<20,0,I40-J40) -> 0 | M40: 60105
B41: 44295 | C41: 3989/ | D41: BRA021 | E41: Agricola Famosa | G41: Rio Branco | H41: Silvio | I41: 1152 | J41: 1152 | K41: =IF(ABS(I41-J41)<20,0,I41-J41) -> 0 | L41: 139.76.37 | M41: 61348
B42: 44295 | C42: 3990/ | D42: BRA021 | E42: Agricola Famosa | G42: Rio Branco | H42: Silvio | I42: 1152 | J42: 1152 | K42: =IF(ABS(I42-J42)<20,0,I42-J42) -> 0 | L42: 139.76.37 | M42: 61348
B43: 44295 | C43: 3991/ | D43: BRA021 | E43: Agricola Famosa | G43: Rio Branco | H43: Silvio | I43: 1152 | J43: 1152 | K43: =IF(ABS(I43-J43)<20,0,I43-J43) -> 0 | L43: 139.76.37 | M43: 61348
B44: 44295 | C44: 4019/ | D44: BRA021 | E44: Agricola Famosa | G44: Rio Branco | H44: Silvio | I44: 1152 | J44: 1152 | K44: =IF(ABS(I44-J44)<20,0,I44-J44) -> 0 | L44: 139.76.37 | M44: 61348
B45: 44302 | C45: 4026/ | D45: BRA022 | E45: Agricola Famosa | G45: Rio Branco | H45: Silvio | I45: 1152 | J45: 1152 | K45: =IF(ABS(I45-J45)<20,0,I45-J45) -> 0 | L45: 139.81.67 | M45: 65972
B46: 44567 | C46: 3410/ | D46: BRA001 | E46: Agricola Famosa | G46: Rio Branco | H46: Silvio | I46: 1104 | J46: =SUMIF(Cargas!$C$5:$C$3470,C46,Cargas!$O$5:$O$3470) -> 0 | K46: =IF(ABS(I46-J46)<20,0,I46-J46) -> 1104 | L46: 141.95.81 | M46: xx
B47: 44302 | C47: 4051/ | D47: BRA022 | E47: Agricola Famosa | G47: Rio Branco | H47: Silvio | I47: 1152 | J47: 1152 | K47: =IF(ABS(I47-J47)<20,0,I47-J47) -> 0 | L47: 139.81.67 | M47: 65972
B48: 44302 | C48: 4052/ | D48: BRA022 | E48: Agricola Famosa | G48: Rio Branco | H48: Silvio | I48: 1152 | J48: 1152 | K48: =IF(ABS(I48-J48)<20,0,I48-J48) -> 0 | L48: 139.81.67 | M48: 69925
B49: 44307 | C49: 4053/ | D49: BRA023 | E49: Agricola Famosa | G49: Rio Branco | H49: Silvio | I49: 1152 | J49: 1152 | K49: =IF(ABS(I49-J49)<20,0,I49-J49) -> 0 | L49: 139.85.73 | M49: 69925
B50: 44307 | C50: 4054/ | D50: BRA023 | E50: Agricola Famosa | G50: Rio Branco | H50: Silvio | I50: 1152 | J50: 1152 | K50: =IF(ABS(I50-J50)<20,0,I50-J50) -> 0 | L50: 139.85.73 | M50: 69925
B51: 44307 | C51: 4055/ | D51: BRA023 | E51: Agricola Famosa | G51: Rio Branco | H51: Silvio | I51: 1152 | J51: 1152 | K51: =IF(ABS(I51-J51)<20,0,I51-J51) -> 0 | L51: 139.85.73 | M51: 69925
B52: 44307 | C52: 4069/ | D52: BRA023 | E52: Agricola Famosa | G52: Rio Branco | H52: Silvio | I52: 1152 | J52: 1152 | K52: =IF(ABS(I52-J52)<20,0,I52-J52) -> 0 | L52: 139.85.73 | M52: 69925
...

Sheet Choferes
B1: Chofer | C1: celular
B3: Adailton Chinkevicz | C3: +5542999594310
B4: Adair Rosseto | C4: +5542999841559
B5: Adão da Silveira | C5: +5549989007917
B6: Adilso Martello | C6: +5549999288403
B7: Adilson Barboza | C7: +5555999696955
B8: Adilson Beitum | C8: +554199367107
B9: Adilson Caceres | C9: +5555996177111
B10: Adilson Denis Duarte | C10: +5548992106401
B11: Adriano Becker de Souza | C11: +5555999703929
B12: Agnaldo Mariano Noelves | C12: +5527997171235
B13: Ailton Rodrigues Ibarra | C13: +5555984262559
... B361: UILIAN DE PAULA DOS SANTOS | C361: +55 53 8474-9701
B362: WESLEY SILVA MARTINS
B363: ALEX SANDRO BILHALVA
B364: Franco Camacho | C364: +598 91 694 331
B365: ANDERSON NEITZKE SOAREZ | C365: +55 53 8406-9723
B366: JOSE CLAUDIO FERNANDES ROCHA | C366: +55 73 8177-8043
B367: Gilberto Toledo | C367: +55 55 9999-0960
B368: LUCIANO FORTEZA | C368: +55 55 9979-8055
B369: Alan Adacheski | C369: +55 41 9687-3997
B370: WINSTON PORTO | C370: +55 53 9972-5431
B371: Anderson Braz | C371: +55 55 9674-9281
B372: GUILHERME MOTTA | C372: +55 53 8485-1806
B373: MARCOS ALVES COSTA | C373: +55 49 8411-6446
B374: OSNI RAPCINSKE | C374: +55 49 8816-0696
B375: Sidnei Surdi | C375: +55 49 9984-6132
... B387: Bruno Senosiain Carmona | C387: +55 53 99990-3654
Y1201: =PROCV('Choferes'!B3:C400

Sheet Rangos
B2: Listas para validación de datos
B4: Status List | D4: Transporte | E4: Cajas x Viaje | F4: INCOTERMS | H4: Fronteras | J4: Productores | K4: Iniciales
B5: Solicitado | J5: Ulgo | K5: HG
B6: Destruida | D6: CMCN | E6: 936 | F6: DAP | H6: Montevideo | J6: Exoticos PY
B7: Confirmado | D7: Amaro | E7: 1008 | F7: DAP | H7: Salto | J7: Claudia | K7: CH
B8: Cancelado | D8: Balbiani | E8: 1040 | F8: FCA | H8: Chuy | J8: Gilson | K8: GT
B9: Cargado | D9: Cigliuti | E9: 936 | F9: FCA | H9: Río Branco | J9: Jaime | K9: JM
B10: Frontera | D10: Cordenonsi | E10: 936 | F10: DAP | H10: Rivera | J10: Papa | K10: PA
B11: Liberado | D11: El Palomar | E11: 1000 | F11: DAP | H11: xx | J11: Boniato | K11: BO
B12: Arribado | D12: Pradera | E12: 918 | F12: FCA | J12: Sidnei | K12: SR
B13: Puerto | D13: Transzanini | E13: 918 | J13: Benini | K13: BN
B14: Descargado | D14: Gral | E14: 918 | F14: DAP | J14: Valdemar | K14: VH
D15: Aotrans | J15: Valdemar Ita | K15: VA
J17: Adriano | K17: AD
D18: Sergio Nava | E18: 918 | J18: Varios | K18: VA
D19: Marvel | J19: Nordeste | K19: ND
D20: K2 | E20: 918 | F20: DAP | J20: Corupá | K20: CP
D21: Costa Rica | E21: 918 | F21: DAP | J21: Jhony Viera | K21: JV
D22: Schwanck | E22: 918 | F22: DAP | J22: Muller | K22: MU
J23: Sergio | K23: SG
J24: Vitor | K24: VM
J25: Marconi Kons | K25: MK
J26: Ivo Zimerman | K26: IZ
J27: Banana MG | K27: MG
J28: A Confirmar
J29: Paraguay | K29: PY
J30: Paraguay EC | K30: PYE
J31: Paraguay OP | K31: PYO
J32: Paraguay MS | K32: PYM
J33: Paraguay GM | K33: GM
D34: Silvio | E34: 918 | F34: DAP | J34: Paraguay DF | K34: DF
J35: Jorge Marangoni | K35: JM
D36: Tottal Brasil | E36: 918 | F36: DAP | J36: Paraguay HF | K36: HF
J37: Paraguay SF | K37: SF
D38: Trans America | E38: 918 | F38: DAP | J38: Bolivia Tuli | K38: BT
J39: João Claudio Winter | K39: JW
J40: Osnildo Stein | K40: ST
J41: Zapellini | K41: ZP
J42: Fischer | K42: FH
J43: Tureck | K43: TK
...
